Workbook

Sheet Executive Summary
A1: HOTEL FINANCIAL MODEL - EXECUTIVE SUMMARY
A3: Property Overview
A4: Property Name: | B4: =Inputs!B4
A5: Hotel Type: | B5: =Inputs!B5
A6: Number of Rooms: | B6: =Inputs!B8
A7: Location: | B7: =Inputs!B6
A8: Brand Affiliation: | B8: =Inputs!B20
A10: Key Performance Metrics - Year 1
A11: Average Daily Rate (ADR): | B11: ='Pro Forma'!C21
A12: Occupancy Rate: | B12: ='Pro Forma'!C22
A13: RevPAR: | B13: ='Pro Forma'!C23
A14: Total Revenue: | B14: ='Pro Forma'!C42
A15: Total Operating Expenses: | B15: ='Pro Forma'!C71
A16: Gross Operating Profit (GOP): | B16: ='Pro Forma'!C73
A17: GOP Margin: | B17: ='Pro Forma'!C74
A19: Investment Returns
A20: Total Development Cost: | B20: =Inputs!B60
A21: Stabilized NOI (Year 2): | B21: ='Pro Forma'!D76
A22: Stabilized Yield on Cost: | B22: =B21/B20
A23: Estimated Exit Value (Year 10): | B23: ='Returns Analysis'!B15
A24: Levered IRR: | B24: ='Returns Analysis'!B20
A25: Equity Multiple: | B25: ='Returns Analysis'!B21

Sheet Inputs
A1: HOTEL FINANCIAL MODEL - INPUTS
A2: BLUE cells = USER INPUTS
A4: Property Name: | B4: Flagship Hotel & Resort
A5: Hotel Type: | B5: Upper Upscale
A6: Location: | B6: Downtown Metropolitan
A7: Opening Date: | B7: 46023
A8: Number of Rooms: | B8: 300
A9: Average Room Size (SF): | B9: 450
A11: REVENUE ASSUMPTIONS
A13: Rooms Revenue
A14: Year 1 Average Daily Rate (ADR): | B14: 225
A15: Stabilized Occupancy Rate: | B15: 0.7
A16: Ramp-Up Period (months): | B16: 18
A17: ADR Growth Rate (annual): | B17: 0.025
A19: Brand/Franchise Structure
A20: Brand Affiliation: | B20: Marriott Hotels
A21: Operating Structure: | B21: Franchise (Owner-Operated)
A22: Initial Franchise Fee: | B22: 75000
A23: Royalty Fee (% of rooms revenue): | B23: 0.05
A24: Marketing/Reservation Fee (% of rooms revenue): | B24: 0.04
A25: Technology/Distribution Fee (% of rooms revenue): | B25: 0.01
A27: Food & Beverage Revenue
A28: Restaurant/Outlet Revenue per Room per Day: | B28: 35
A29: Banquet/Catering Revenue per Group Room Night: | B29: 95
A30: Group Business % of Total Rooms: | B30: 0.35
A31: F&B Revenue Growth Rate: | B31: 0.03
A33: Other Operated Departments
A34: Meeting Room Rental Revenue per Room per Year: | B34: 1800
A35: Parking Revenue per Room per Year: | B35: 900
A36: Spa/Fitness Revenue per Room per Year: | B36: 400
A37: Other Revenue per Room per Year: | B37: 600
A39: OPERATING EXPENSES
A41: Rooms Department Expenses (% of rooms revenue): | B41: 0.25
A42: F&B Department Expenses (% of F&B revenue): | B42: 0.68
A43: Other Dept Expenses (% of other operated revenue): | B43: 0.35
A45: Undistributed Expenses (per room per year): | B45: 8500
A46: Property Operations & Maintenance (per room/year): | B46: 3200
A47: Utilities (per room per year): | B47: 2800
A48: Insurance (% of total revenue): | B48: 0.015
A49: Property Tax (% of total revenue): | B49: 0.035
...

Sheet Pro Forma
A1: HOTEL PRO FORMA - 10-YEAR PROJECTION
A3: Property: | B3: =Inputs!B4
A4: Rooms: | B4: =Inputs!B8
A6: Period | C6: Year 1 | D6: Year 2 | E6: Year 3 | F6: Year 4 | G6: Year 5 | H6: Year 6 | I6: Year 7 | J6: Year 8 | K6: Year 9 | L6: Year 10
A8: OPERATING STATISTICS
A10: Available Rooms: | B10: =Inputs!B8 | C10: =B10 | D10: =B10 | E10: =B10 | F10: =B10 | G10: =B10 | H10: =B10 | I10: =B10 | J10: =B10 | K10: =B10 | L10: =B10
A11: Available Room Nights: | B11: =B10*365 | C11: =B11 | D11: =C11 | E11: =D11 | F11: =E11 | G11: =F11 | H11: =G11 | I11: =H11 | J11: =I11 | ... L11: =K11
A12: Occupancy Rate (%): | B12: =Inputs!B15*12/(12+Inputs!B16/12) | C12: =Inputs!B15 | D12: =Inputs!B15 | E12: =Inputs!B15 | F12: =Inputs!B15 | G12: =Inputs!B15 | H12: =Inputs!B15 | I12: =Inputs!B15 | J12: =Inputs!B15 | K12: =Inputs!B15 | L12: =Inputs!B15
A13: Occupied Room Nights: | B13: =B11*B12 | C13: =C11*C12 | D13: =D11*D12 | E13: =E11*E12 | F13: =F11*F12 | G13: =G11*G12 | H13: =H11*H12 | I13: =I11*I12 | ... L13: =L11*L12
A14: Group Room Nights (%): | B14: =Inputs!B30 | C14: =Inputs!B30 | D14: =Inputs!B30 | E14: =Inputs!B30 | F14: =Inputs!B30 | G14: =Inputs!B30 | H14: =Inputs!B30 | I14: =Inputs!B30 | J14: =Inputs!B30 | K14: =Inputs!B30 | L14: =Inputs!B30
A15: Group Room Nights: | B15: =B13*B14 | C15: =C13*C14 | D15: =D13*D14 | E15: =E13*E14 | F15: =F13*F14 | G15: =G13*G14 | H15: =H13*H14 | I15: =I13*I14 | ... L15: =L13*L14
A17: REVENUE ($000s)
A19: Rooms Revenue
A20: ADR ($): | B20: =Inputs!B14 | C20: =B20*(1+Inputs!B17) | D20: =C20*(1+Inputs!B17) | E20: =D20*(1+Inputs!B17) | F20: =E20*(1+Inputs!B17) | G20: =F20*(1+Inputs!B17) | H20: =G20*(1+Inputs!B17) | I20: =H20*(1+Inputs!B17) | J20: =I20*(1+Inputs!B17) | K20: =J20*(1+Inputs!B17) | L20: =K20*(1+Inputs!B17)
A21: ADR (Actual): | B21: =B20 | C21: =C20 | D21: =D20 | E21: =E20 | F21: =F20 | G21: =G20 | H21: =H20 | I21: =I20 | ... L21: =L20
A22: Occupancy (Actual): | B22: =B12 | C22: =C12 | D22: =D12 | E22: =E12 | F22: =F12 | G22: =G12 | H22: =H12 | I22: =I12 | ... L22: =L12
A23: RevPAR ($): | B23: =B21*B22 | C23: =C21*C22 | D23: =D21*D22 | E23: =E21*E22 | F23: =F21*F22 | G23: =G21*G22 | H23: =H21*H22 | I23: =I21*I22 | ... L23: =L21*L22
A25: Total Rooms Revenue: | B25: =B13*B20/1000 | C25: =C13*C20/1000 | D25: =D13*D20/1000 | E25: =E13*E20/1000 | F25: =F13*F20/1000 | G25: =G13*G20/1000 | H25: =H13*H20/1000 | I25: =I13*I20/1000 | ... L25: =L13*L20/1000
A27: Food & Beverage Revenue
A28: Outlet Revenue: | B28: =B13*Inputs!B28*365/1000 | C28: =B28*(1+Inputs!B31) | D28: =C28*(1+Inputs!B31) | E28: =D28*(1+Inputs!B31) | F28: =E28*(1+Inputs!B31) | G28: =F28*(1+Inputs!B31) | H28: =G28*(1+Inputs!B31) | I28: =H28*(1+Inputs!B31) | J28: =I28*(1+Inputs!B31) | K28: =J28*(1+Inputs!B31) | L28: =K28*(1+Inputs!B31)
A29: Banquet/Catering Revenue: | B29: =B15*Inputs!B29/1000 | C29: =C15*Inputs!B29/1000*(1+Inputs!B31)^(1) | D29: =D15*Inputs!B29/1000*(1+Inputs!B31)^(2) | E29: =E15*Inputs!B29/1000*(1+Inputs!B31)^(3) | F29: =F15*Inputs!B29/1000*(1+Inputs!B31)^(4) | G29: =G15*Inputs!B29/1000*(1+Inputs!B31)^(5) | H29: =H15*Inputs!B29/1000*(1+Inputs!B31)^(6) | I29: =I15*Inputs!B29/1000*(1+Inputs!B31)^(7) | J29: =J15*Inputs!B29/1000*(1+Inputs!B31)^(8) | K29: =K15*Inputs!B29/1000*(1+Inputs!B31)^(9) | L29: =L15*Inputs!B29/1000*(1+Inputs!B31)^(10)
A30: Total F&B Revenue: | B30: =B28+B29 | C30: =C28+C29 | D30: =D28+D29 | E30: =E28+E29 | F30: =F28+F29 | G30: =G28+G29 | H30: =H28+H29 | I30: =I28+I29 | ... L30: =L28+L29
A32: Other Operated Departments
A33: Meeting Room Rental: | B33: =Inputs!B34*B10/1000 | C33: =Inputs!B34*C10/1000 | D33: =Inputs!B34*D10/1000 | E33: =Inputs!B34*E10/1000 | F33: =Inputs!B34*F10/1000 | G33: =Inputs!B34*G10/1000 | H33: =Inputs!B34*H10/1000 | I33: =Inputs!B34*I10/1000 | J33: =Inputs!B34*J10/1000 | K33: =Inputs!B34*K10/1000 | L33: =Inputs!B34*L10/1000
A34: Parking: | B34: =Inputs!B35*B10/1000 | C34: =Inputs!B35*C10/1000 | D34: =Inputs!B35*D10/1000 | E34: =Inputs!B35*E10/1000 | F34: =Inputs!B35*F10/1000 | G34: =Inputs!B35*G10/1000 | H34: =Inputs!B35*H10/1000 | I34: =Inputs!B35*I10/1000 | J34: =Inputs!B35*J10/1000 | K34: =Inputs!B35*K10/1000 | L34: =Inputs!B35*L10/1000
A35: Spa/Fitness: | B35: =Inputs!B36*B10/1000 | C35: =Inputs!B36*C10/1000 | D35: =Inputs!B36*D10/1000 | E35: =Inputs!B36*E10/1000 | F35: =Inputs!B36*F10/1000 | G35: =Inputs!B36*G10/1000 | H35: =Inputs!B36*H10/1000 | I35: =Inputs!B36*I10/1000 | J35: =Inputs!B36*J10/1000 | K35: =Inputs!B36*K10/1000 | L35: =Inputs!B36*L10/1000
A36: Other Revenue: | B36: =Inputs!B37*B10/1000 | C36: =Inputs!B37*C10/1000 | D36: =Inputs!B37*D10/1000 | E36: =Inputs!B37*E10/1000 | F36: =Inputs!B37*F10/1000 | G36: =Inputs!B37*G10/1000 | H36: =Inputs!B37*H10/1000 | I36: =Inputs!B37*I10/1000 | J36: =Inputs!B37*J10/1000 | K36: =Inputs!B37*K10/1000 | L36: =Inputs!B37*L10/1000
A38: Total Other Revenue: | B38: =B33+B34+B35+B36 | C38: =C33+C34+C35+C36 | D38: =D33+D34+D35+D36 | E38: =E33+E34+E35+E36 | F38: =F33+F34+F35+F36 | G38: =G33+G34+G35+G36 | H38: =H33+H34+H35+H36 | I38: =I33+I34+I35+I36 | ... L38: =L33+L34+L35+L36
A40: TOTAL OPERATING REVENUE
A42: Total Revenue: | B42: =B25+B30+B38 | C42: =C25+C30+C38 | D42: =D25+D30+D38 | E42: =E25+E30+E38 | F42: =F25+F30+F38 | G42: =G25+G30+G38 | H42: =H25+H30+H38 | I42: =I25+I30+I38 | ... L42: =L25+L30+L38
A44: OPERATING EXPENSES ($000s)
A46: Department Expenses
A47: Rooms Expense: | B47: =B25*Inputs!B41 | C47: =C25*Inputs!B41 | D47: =D25*Inputs!B41 | E47: =E25*Inputs!B41 | F47: =F25*Inputs!B41 | G47: =G25*Inputs!B41 | H47: =H25*Inputs!B41 | I47: =I25*Inputs!B41 | J47: =J25*Inputs!B41 | K47: =K25*Inputs!B41 | L47: =L25*Inputs!B41
A48: F&B Expense: | B48: =B30*Inputs!B42 | C48: =C30*Inputs!B42 | D48: =D30*Inputs!B42 | E48: =E30*Inputs!B42 | F48: =F30*Inputs!B42 | G48: =G30*Inputs!B42 | H48: =H30*Inputs!B42 | I48: =I30*Inputs!B42 | J48: =J30*Inputs!B42 | K48: =K30*Inputs!B42 | L48: =L30*Inputs!B42
A49: Other Department Expense: | B49: =B38*Inputs!B43 | C49: =C38*Inputs!B43 | D49: =D38*Inputs!B43 | E49: =E38*Inputs!B43 | F49: =F38*Inputs!B43 | G49: =G38*Inputs!B43 | H49: =H38*Inputs!B43 | I49: =I38*Inputs!B43 | J49: =J38*Inputs!B43 | K49: =K38*Inputs!B43 | L49: =L38*Inputs!B43
A51: Total Department Expense: | B51: =B47+B48+B49 | C51: =C47+C48+C49 | D51: =D47+D48+D49 | E51: =E47+E48+E49 | F51: =F47+F48+F49 | G51: =G47+G48+G49 | H51: =H47+H48+H49 | I51: =I47+I48+I49 | ... L51: =L47+L48+L49
A53: Undistributed Expenses
A54: Administrative & General: | B54: =Inputs!B45*B10/1000 | C54: =B54*(1+Inputs!B50) | D54: =C54*(1+Inputs!B50) | E54: =D54*(1+Inputs!B50) | F54: =E54*(1+Inputs!B50) | G54: =F54*(1+Inputs!B50) | H54: =G54*(1+Inputs!B50) | I54: =H54*(1+Inputs!B50) | J54: =I54*(1+Inputs!B50) | K54: =J54*(1+Inputs!B50) | L54: =K54*(1+Inputs!B50)
A55: Property Operations & Maintenance: | B55: =Inputs!B46*B10/1000 | C55: =B55*(1+Inputs!B50) | D55: =C55*(1+Inputs!B50) | E55: =D55*(1+Inputs!B50) | F55: =E55*(1+Inputs!B50) | G55: =F55*(1+Inputs!B50) | H55: =G55*(1+Inputs!B50) | I55: =H55*(1+Inputs!B50) | J55: =I55*(1+Inputs!B50) | K55: =J55*(1+Inputs!B50) | L55: =K55*(1+Inputs!B50)
A56: Utilities: | B56: =Inputs!B47*B10/1000 | C56: =B56*(1+Inputs!B50) | D56: =C56*(1+Inputs!B50) | E56: =D56*(1+Inputs!B50) | F56: =E56*(1+Inputs!B50) | G56: =F56*(1+Inputs!B50) | H56: =G56*(1+Inputs!B50) | I56: =H56*(1+Inputs!B50) | J56: =I56*(1+Inputs!B50) | K56: =J56*(1+Inputs!B50) | L56: =K56*(1+Inputs!B50)
...

Sheet Cash Flow Analysis
A1: CASH FLOW ANALYSIS
A3: Period | B3: Year 0 | C3: Year 1 | D3: Year 2 | E3: Year 3 | F3: Year 4 | G3: Year 5 | H3: Year 6 | I3: Year 7 | J3: Year 8 | K3: Year 9 | L3: Year 10
A5: SOURCES & USES ($000s)
A7: Sources:
A8: Equity Investment: | B8: =Inputs!B60*(1-Inputs!B64)
A9: Debt Financing: | B9: =Inputs!B60*Inputs!B64
A10: Total Sources: | B10: =B8+B9
A12: Uses:
A13: Total Development Cost: | B13: =Inputs!B60
A14: Total Uses: | B14: =B13
A16: OPERATING CASH FLOW ($000s)
A18: Net Operating Income (NOI): | C18: ='Pro Forma'!C76 | D18: ='Pro Forma'!D76 | E18: ='Pro Forma'!E76 | F18: ='Pro Forma'!F76 | G18: ='Pro Forma'!G76 | H18: ='Pro Forma'!H76 | I18: ='Pro Forma'!I76 | J18: ='Pro Forma'!J76 | ... L18: ='Pro Forma'!L76
A20: DEBT SERVICE ($000s)
A21: Annual Debt Service: | C21: =-PMT(Inputs!B65,Inputs!B67,B9) | D21: =-PMT(Inputs!B65,Inputs!B67,B9) | E21: =-PMT(Inputs!B65,Inputs!B67,B9) | F21: =-PMT(Inputs!B65,Inputs!B67,B9) | G21: =-PMT(Inputs!B65,Inputs!B67,B9) | H21: =-PMT(Inputs!B65,Inputs!B67,B9) | I21: =-PMT(Inputs!B65,Inputs!B67,B9) | J21: =-PMT(Inputs!B65,Inputs!B67,B9) | K21: =-PMT(Inputs!B65,Inputs!B67,B9) | L21: =-PMT(Inputs!B65,Inputs!B67,B9)
A23: CASH FLOW BEFORE TAX
A25: Cash Flow Before Tax: | C25: =C18-C21 | D25: =D18-D21 | E25: =E18-E21 | F25: =F18-F21 | G25: =G18-G21 | H25: =H18-H21 | I25: =I18-I21 | J25: =J18-J21 | ... L25: =L18-L21
A27: CAPITAL EXPENDITURES ($000s)
A28: FF&E Reserve (4% of revenue): | C28: ='Pro Forma'!C42*0.04 | D28: ='Pro Forma'!D42*0.04 | E28: ='Pro Forma'!E42*0.04 | F28: ='Pro Forma'!F42*0.04 | G28: ='Pro Forma'!G42*0.04 | H28: ='Pro Forma'!H42*0.04 | I28: ='Pro Forma'!I42*0.04 | J28: ='Pro Forma'!J42*0.04 | ... L28: ='Pro Forma'!L42*0.04
A30: NET OPERATING CASH FLOW
A32: Net Cash Flow: | B32: =-B8 | C32: =C25-C28 | D32: =D25-D28 | E32: =E25-E28 | F32: =F25-F28 | G32: =G25-G28 | H32: =H25-H28 | I32: =I25-I28 | J32: =J25-J28 | ... L32: =L25-L28

Sheet Returns Analysis
A1: RETURNS ANALYSIS
A3: EXIT ASSUMPTIONS
A5: Hold Period (years): | B5: =Inputs!B71
A6: Exit Year NOI: | B6: ='Pro Forma'!L76
A7: Exit Cap Rate: | B7: =Inputs!B72
A8: Estimated Value: | B8: =B6/B7
A9: Less: Selling Costs: | B9: =B8*Inputs!B73
A10: Less: Loan Balance: | B10: ='Cash Flow Analysis'!B9
A12: Net Sale Proceeds to Equity: | B12: =B8-B9-B10
A14: EXIT VALUE SUMMARY
A15: Gross Exit Value: | B15: =B8
A16: Exit Cap Rate: | B16: =B7
A18: RETURN METRICS
A20: Levered IRR: | B20: =IRR('Cash Flow Analysis'!B32:L32)
A21: Equity Multiple: | B21: =(SUM('Cash Flow Analysis'!C32:K32)+B12)/ABS('Cash Flow Analysis'!B32)
A23: Total Equity Invested: | B23: =ABS('Cash Flow Analysis'!B32)
A24: Total Cash Distributed: | B24: =SUM('Cash Flow Analysis'!C32:K32)+B12
A26: Investment Performance
A27: Year 1 Yield on Cost: | B27: ='Pro Forma'!C76/Inputs!B60
A28: Stabilized Yield on Cost (Year 2): | B28: ='Pro Forma'!D76/Inputs!B60
A29: Cash-on-Cash Return (Year 2): | B29: ='Cash Flow Analysis'!D25/'Cash Flow Analysis'!B8

Sheet Segment Benchmarks
A1: HOTEL SEGMENT BENCHMARKS - INDUSTRY DATA
A2: Source: STR, HVS, CBRE Hotels Research, 2024 Data
A4: Metric | B4: Luxury | C4: Upper Upscale | D4: Upscale | E4: Midscale | F4: Economy
A6: RATE & OCCUPANCY BENCHMARKS
A7: Typical ADR Range ($): | B7: $300-$500 | C7: $200-$300 | D7: $120-$200 | E7: $70-$120 | F7: $50-$90
A8: Typical Occupancy: | B8: 68-75% | C8: 68-72% | D8: 68-72% | E8: 58-65% | F8: 55-63%
A9: RevPAR Range ($): | B9: $200-$375 | C9: $135-$215 | D9: $80-$145 | E9: $40-$75 | F9: $30-$55
A11: REVENUE MIX
A12: Rooms % of Total Revenue: | B12: 55-65% | C12: 60-70% | D12: 65-75% | E12: 75-85% | F12: 85-95%
A13: F&B % of Total Revenue: | B13: 25-35% | C13: 20-30% | D13: 15-25% | E13: 8-15% | F13: 0-5%
A14: Other % of Total Revenue: | B14: 5-10% | C14: 5-10% | D14: 5-10% | E14: 5-10% | F14: 5-10%
A16: OPERATING MARGINS
A17: Rooms Dept OpEx (% of rooms revenue): | B17: 30-35% | C17: 25-30% | D17: 22-27% | E17: 20-25% | F17: 18-22%
A18: F&B Dept OpEx (% of F&B revenue): | B18: 65-75% | C18: 65-72% | D18: 65-70% | E18: 60-68% | F18: N/A
A19: GOP Margin: | B19: 35-45% | C19: 35-42% | D19: 30-40% | E19: 25-35% | F19: 20-30%
A20: Net Profit Margin: | B20: 25-35% | C20: 20-30% | D20: 15-25% | E20: 10-20% | F20: 5-15%
A22: DEVELOPMENT COSTS
A23: Construction Cost per Room: | B23: $500k-$1M+ | C23: $350k-$500k | D23: $250k-$350k | E23: $150k-$250k | F23: $80k-$150k
A24: FF&E per Room: | B24: $35k-$75k | C24: $25k-$40k | D24: $15k-$25k | E24: $10k-$15k | F24: $5k-$10k
A25: Typical Room Size (SF): | B25: 500-700 | C25: 450-550 | D25: 400-450 | E25: 300-400 | F25: 250-350
A27: FRANCHISE/BRAND FEES
A28: Typical Royalty Fee: | B28: 4-6% | C28: 4-6% | D28: 4-5% | E28: 4-5% | F28: 4-5%
A29: Marketing/Reservation Fee: | B29: 2-4% | C29: 2-4% | D29: 2-3% | E29: 2-3% | F29: 2-3%
A30: Total Brand Fees (% rooms revenue): | B30: 6-10% | C30: 6-10% | D30: 6-8% | E30: 6-8% | F30: 6-8%
A32: F&B OPERATIONS (Full-Service Hotels)
A33: Outlet Revenue per Room per Day: | B33: $50-$80 | C33: $35-$50 | D33: $25-$40 | E33: $15-$25 | F33: N/A
A34: Banquet Revenue per Group Room Night: | B34: $150-$200 | C34: $90-$120 | D34: $50-$80 | E34: $30-$50 | F34: N/A
A35: Meeting Space (SF per Room): | B35: 30-60 | C35: 25-40 | D35: 15-30 | E35: 5-15 | F35: 0-5
A37: KEY FINANCIAL RATIOS
A38: Labor Cost % of Revenue: | B38: 32-40% | C38: 30-36% | D38: 28-34% | E38: 25-30% | F38: 20-28%
A39: Flow-Through (incremental): | B39: 35-45% | C39: 40-50% | D39: 45-55% | E39: 50-60% | F39: 55-65%
A40: Typical Exit Cap Rate: | B40: 6.0-7.5% | C40: 6.5-7.5% | D40: 7.0-8.0% | E40: 7.5-8.5% | F40: 8.0-9.0%
A42: MAJOR BRANDS IN SEGMENT
A43: Example Brands: | B43: Ritz-Carlton Four Seasons St. Regis Waldorf Astoria | C43: Marriott Hilton Hyatt Regency Westin | D43: Courtyard Hilton Garden Inn Hyatt Place Aloft | E43: Hampton Inn Fairfield Inn Holiday Inn Express Comfort Inn | F43: Super 8 Days Inn Motel 6 Red Roof Inn
A45: NOTES:
A46: • All percentages and ranges based on 2024 industry data from STR, HVS, CBRE • ADR varies significantly by market (NYC vs. secondary markets) • Occupancy influenced by location, season, brand strength • GOP margins highest in upper segments due to pricing power • Labor costs are typically 50-65% of total operating expenses • F&B operations have lower margins but drive ancillary revenue • Development costs vary by market (urban vs. suburban) • Exit cap rates inversely correlated with property quality
