Workbook

Sheet Executive Summary
A1: HOUSE FLIPPING MODEL
A2: Executive Summary Dashboard
A4: PROPERTY INFORMATION | D4: KEY DEAL METRICS | G4: RETURN METRICS
A5: Property Address: | B5: =Inputs!B5 -> 123 Main Street, Anytown, USA | D5: Purchase Price: | E5: =Inputs!B13 -> 150000 | G5: Gross Profit: | H5: ='Deal Analysis'!E15 -> 0
A6: Property Type: | B6: =Inputs!B6 -> Single Family Home | D6: After Repair Value (ARV): | E6: ='Deal Analysis'!E6 -> From Inputs sheet | G6: ROI: | H6: ='Deal Analysis'!E16 -> 0
A7: Square Footage: | B7: =Inputs!B7 -> 1800 | D7: Total Renovation Cost: | E7: ='Renovation Budget'!C50 -> 0 | G7: 70% Rule Check: | H7: ='Deal Analysis'!E21 -> 0
A8: Bedrooms / Baths: | B8: =Inputs!B8&" / "&Inputs!B9 -> 3 / 2 | D8: All-In Cost: | E8: ='Deal Analysis'!E10 -> 0 | G8: Deal Quality: | H8: ='Deal Analysis'!E22 -> 0
A13: PROJECT TIMELINE
A14: Acquisition Period: | B14: =Inputs!B34 -> 200 | C14: days | D14: Renovation Period: | E14: =Inputs!B35 -> 0 | F14: days | G14: Marketing Period: | H14: =Inputs!B36 -> 0 | I14: days
A15: Total Hold Period: | B15: =Inputs!B34+Inputs!B35+Inputs!B36 -> 200 | C15: days

Sheet Inputs
A1: INPUTS & ASSUMPTIONS
A2: All BLUE cells are inputs - Change these to match your deal
A4: PROPERTY INFORMATION
A5: Property Address | B5: 123 Main Street, Anytown, USA
A6: Property Type | B6: Single Family Home
A7: Square Footage | B7: 1800
A8: Bedrooms | B8: 3
A9: Bathrooms | B9: 2
A10: Year Built | B10: 1975
A12: ACQUISITION COSTS
A13: Purchase Price | B13: 150000
A14: Closing Costs (% of Purchase) | B14: 0.025 | C14: =B13*B14 -> 3750
A15: Inspection Cost | B15: 500
A16: Due Diligence Costs | B16: 1000
A18: RENOVATION BUDGET ASSUMPTIONS
A19: Renovation Type | B19: Full Renovation | C19: Cosmetic / Full / Gut
A20: Estimated Total Renovation Cost | B20: 45000
A21: Contingency Reserve (% of Reno) | B21: 0.1
A23: AFTER REPAIR VALUE (ARV)
A24: Comp #1 Sale Price | B24: 285000
A25: Comp #2 Sale Price | B25: 295000
A26: Comp #3 Sale Price | B26: 290000
A27: Average Comp Value | B27: =AVERAGE(B23:B25) -> 290000
A28: Conservative Discount | B28: 0.02 | C28: Safety margin
A29: Your ARV Estimate | B29: =B26*(1-B27) -> -84099710000
A31: HOLDING COSTS
A32: Property Insurance (monthly) | B32: 150
A33: Property Taxes (monthly) | B33: 250
A34: Utilities (monthly) | B34: 200
A35: HOA Dues (if applicable, monthly) | B35: 0
A37: PROJECT TIMELINE
A38: Acquisition Period (days) | B38: 30 | C38: =B37/30 -> 0
A39: Renovation Period (days) | B39: 90
A40: Marketing & Sale Period (days) | B40: 60
A41: Total Hold Period (days) | B41: =B34+B35+B36 -> 200 | C41: =B37/30&" months" -> 0 months
A43: SELLING COSTS
A44: Real Estate Commission (%) | B44: 0.06
A45: Closing Costs (% of Sale Price) | B45: 0.015
A46: Staging & Photography | B46: 2000
A48: FINANCING ASSUMPTIONS
...

Sheet Deal Analysis
A1: DEAL ANALYSIS
A2: 70% Rule, MAO Calculation & Profitability Analysis
A4: AFTER REPAIR VALUE (ARV) ANALYSIS
D5: Value | E5: Note
A6: After Repair Value (ARV) | D6: =Inputs!B28 -> 0.02 | E6: From Inputs sheet
A8: TOTAL PROJECT COSTS
A9: Purchase Price | D9: =Inputs!B13 -> 150000
A10: Acquisition Closing Costs | D10: =Inputs!C14+Inputs!B15+Inputs!B16 -> 5250
A11: Renovation Costs (with contingency) | D11: =IF(D10=0,0,D10) -> 5250 | E11: Base + reserve
A12: Holding Costs (monthly × months) | D12: =(Inputs!B30+Inputs!B31+Inputs!B32+Inputs!B33)*(Inputs!B37/30) -> 0 | E12: Insurance, taxes, utilities
A13: All-In Cost | D13: =SUM(D7:D9) -> 150000
A14: Cash/Equity Required | D14: =D10 -> 5250 | E14: For cash deal
A16: SELLING ANALYSIS
A17: Total Selling Costs | D17: =D6*(Inputs!B40+Inputs!B41)+Inputs!B42 -> 5.2 | E17: Commission + closing + staging
A18: Net Sales Proceeds | D18: =D6-D13 -> -149999.98
A19: Gross Profit | D19: =D14-D10 -> 0
A20: Return on Investment (ROI) | D20: =Inputs!B13 -> 150000 | E20: Profit / Equity
A22: 70% RULE CHECK
A23: Maximum Allowable Offer (MAO) Formula: | D23: ARV × 70% - Repair Costs
A24: MAO Calculation | D24: =D6*Inputs!B52-D9 -> -150000 | E24: Max you should pay
A25: Your Purchase Price | D25: =D7 -> 0
A26: 70% Rule Result | D26: =IF(Inputs!B7=0,0,D9/Inputs!B7) -> 83.333333 | E26: Pass if under MAO
A27: Deal Quality Rating | D27: =IF(D16>=0.25,"EXCELLENT",IF(D16>=0.2,"GOOD",IF(D16>=0.15,"ACCEPTABLE","WEAK"))) -> WEAK | E27: Based on ROI
A29: DETAILED METRICS
A30: Purchase Price per SF | D30: =D7/Inputs!B7 -> 0
A31: ARV per SF | D31: =D6/Inputs!B7 -> 1.1111111e-05
A32: Renovation Cost per SF | D32: =D9/Inputs!B7 -> 83.333333
A33: Profit per SF | D33: =D15/Inputs!B7 -> 0
A34: Profit Margin (% of ARV) | D34: =D15/D6 -> 0
A35: Profit per Day Held | B35: =IF(D16="",0,D16) -> 0 | D35: =IFERROR(D16,0) -> 0
A36: Total Hold Period | D36: =Inputs!B37 -> 0 | E36: days
A38: PROFITABILITY BENCHMARKS
A39: Metric | B39: Your Deal | C39: Market Avg | D39: Status
A40: Gross Profit | B40: =D15 -> 0 | C40: 50000 | D40: =IF(B34>=C34,"Above ✓","Below ⚠") -> Above ✓
A41: ROI | B41: =D16 -> 0 | C41: 0.2 | D41: =IF(B35>=C35,"Above ✓","Below ⚠") -> Above ✓
A42: Profit Margin | B42: =D28 -> 0 | C42: 0.15 | D42: =IF(B36>=C36,"Above ✓","Below ⚠") -> Above ✓
A44: DEAL RECOMMENDATION
A45: =IF(AND(D21="PASS ✓",D16>=Inputs!B51),"PROCEED WITH DEAL - Meets 70% rule and ROI targets","CAUTION - Review assumptions carefully") -> CAUTION - Review assumptions carefully

Sheet Renovation Budget

Sheet ProForma

Sheet Financing Comparison

Sheet Sensitivity Analysis

Sheet Exit Strategies
