Workbook

Sheet Executive Summary
A1: SINGLE-FAMILY RENTAL ANALYSIS
A2: Buy & Hold Investment Model
A4: PROPERTY INFORMATION
A5: Address: | B5: ='Inputs & Assumptions'!B5 -> 123 Main Street, Anytown, USA
A6: Property Type: | B6: ='Inputs & Assumptions'!B6 -> Single-Family Residence
A7: Square Footage: | B7: ='Inputs & Assumptions'!B7 -> 1500
A8: Bedrooms / Bathrooms: | B8: ='Inputs & Assumptions'!B8&" / "&'Inputs & Assumptions'!B9 -> 3 / 2
A10: ACQUISITION SUMMARY | D10: RETURN METRICS
A11: Purchase Price: | B11: ='Inputs & Assumptions'!B13 -> 150000 | D11: Year 1 Cash Flow: | E11: ='10-Year Cash Flow'!N5*12 -> 0
A12: Renovation Cost: | B12: ='Inputs & Assumptions'!B20 -> 45000 | D12: Year 1 Cash-on-Cash: | E12: =E11/B13 -> 0
A13: All-In Cost: | B13: ='Acquisition Analysis'!B20 -> 204050 | D13: 10-Year IRR: | E13: ='10-Year Cash Flow'!B33 -> 95452.57
A14: After Repair Value (ARV): | B14: ='Inputs & Assumptions'!B28 -> 284200 | D14: Equity Multiple: | E14: ='10-Year Cash Flow'!B34 -> 0
A15: Initial Equity: | B15: =B14-B13 -> 80150 | D15: Total 10-Yr Profit: | E15: ='10-Year Cash Flow'!B35 -> 0
A17: YEAR 1 MONTHLY CASH FLOW | D17: KEY METRICS
A18: Gross Monthly Rent: | B18: ='Inputs & Assumptions'!B32 -> 2500 | D18: Metric | E18: Value | F18: Target | G18: Status
A19: Vacancy Loss (5%): | B19: =-B18*0.05 -> -125 | D19: Cap Rate (Cash) | E19: ='Acquisition Analysis'!B26 -> 13528 | F19: 7.0% | G19: =IF(E19>=F19,"✓ Pass","✗ Below") -> ✗ Below
A20: Effective Gross Income: | B20: =B18+B19 -> 2375 | D20: 1% Rule | E20: ='Acquisition Analysis'!B24 -> 0.016166667 | F20: 1.0% | G20: =IF(E20>=F20,"✓ Pass","✗ Below") -> ✗ Below
A21: Operating Expenses: | B21: ='Inputs & Assumptions'!B50 -> 13528 | D21: Cash-on-Cash | E21: =E12 -> 0 | F21: 10.0% | G21: =IF(E21>=F21,"✓ Pass","✗ Below") -> ✗ Below
A22: Net Operating Income: | B22: =B20-B21 -> -11153 | D22: DSCR | E22: ='Acquisition Analysis'!B30 -> 0 | F22: 1.25 | G22: =IF(E22>=F22,"✓ Pass","✗ Below") -> ✗ Below
A23: Debt Service: | B23: ='Inputs & Assumptions'!B59 -> 1490.3757
A24: Net Cash Flow: | B24: =B22-B23 -> -12643.376
A26: EXIT STRATEGY COMPARISON
A27: Strategy | B27: Timeline | C27: Cash Out | D27: Monthly Income | E27: Total Return | F27: IRR
A28: Flip (Traditional) | B28: 6 months | C28: ='Exit Strategies'!B5 -> 6 months | D28: $0 | E28: ='Exit Strategies'!B7 -> $0 | F28: ='Exit Strategies'!B8 -> 57414
A29: BRRRR (Refinance) | B29: 9 months | C29: ='Exit Strategies'!C5 -> 9 months + hold | D29: ='Exit Strategies'!C6 -> 55849.5 | E29: ='Exit Strategies'!C7 -> -313.95906 | F29: ='Exit Strategies'!C8 -> 35221.07
A30: Hold 10 Years | B30: 10 years | C30: ='Exit Strategies'!D5 -> 10 years | D30: ='Exit Strategies'!D6 -> 95452.57 | E30: ='Exit Strategies'!D7 -> 0 | F30: ='Exit Strategies'!D8 -> 65724.14
A31: Hold Forever | B31: Indefinite | C31: $0 | D31: ='10-Year Cash Flow'!N14 -> 0 | E31: Ongoing | F31: ='10-Year Cash Flow'!B32 -> -80531.449

Sheet Inputs & Assumptions
A1: INPUTS & ASSUMPTIONS
A2: Single-Family Rental Model - All user inputs are in BLUE
A4: PROPERTY INFORMATION
A5: Address: | B5: 123 Main Street, Anytown, USA
A6: Property Type: | B6: Single-Family Residence
A7: Square Footage: | B7: 1500
A8: Bedrooms: | B8: 3
A9: Bathrooms: | B9: 2
A10: Year Built: | B10: 1985
A12: ACQUISITION COSTS
A13: Purchase Price: | B13: 150000
A14: Closing Costs (% of purchase): | B14: 0.025
A15: Closing Costs ($): | B15: =B13*B14 -> 3750
A16: Inspection Cost: | B16: 500
A17: Other Due Diligence: | B17: 300
A19: RENOVATION BUDGET
A20: Estimated Renovation Cost: | B20: 45000
A21: Contingency Reserve (%): | B21: 0.1
A22: Total Renovation Budget: | B22: =B20*(1+B21) -> 49500
A24: AFTER REPAIR VALUE (ARV)
A25: Comp #1 Sale Price: | B25: 285000
A26: Comp #2 Sale Price: | B26: 290000
A27: Comp #3 Sale Price: | B27: 295000
A28: Average ARV (Conservative): | B28: =AVERAGE(B25:B27)*0.98 -> 284200
A30: RENTAL MARKET ANALYSIS
A31: Comp Rent #1: | B31: 2400
A32: Comp Rent #2: | B32: 2500
A33: Comp Rent #3: | B33: 2600
A34: Conservative Discount (%): | B34: 0.03
A35: Pro Forma Monthly Rent: | B35: =AVERAGE(B31:B33)*(1-B34) -> 2425
A37: OPERATING ASSUMPTIONS
A38: Vacancy Rate: | B38: 0.05
A39: Bad Debt / Credit Loss: | B39: 0.01
A41: Annual Property Taxes: | B41: 5200
A42: Annual Insurance: | B42: 1800
A43: Monthly HOA Dues: | B43: 0
A44: Property Management (% of rent): | B44: 0.08
A45: Monthly Repairs & Maintenance: | B45: 200
A46: Monthly CapEx Reserve: | B46: 150
A47: Monthly Utilities (if owner-paid): | B47: 0
...

Sheet Acquisition Analysis
A1: ACQUISITION ANALYSIS
A2: Deal Evaluation & Key Metrics
A4: AFTER REPAIR VALUE (ARV)
A5: After Repair Value: | B5: ='Inputs & Assumptions'!B28 -> 284200
A7: TOTAL PROJECT COSTS
A8: Purchase Price: | B8: ='Inputs & Assumptions'!B13 -> 150000
A9: Acquisition Closing Costs: | B9: ='Inputs & Assumptions'!B15 -> 3750
A10: Inspection: | B10: ='Inputs & Assumptions'!B16 -> 500
A11: Due Diligence: | B11: ='Inputs & Assumptions'!B17 -> 300
A12: Renovation Budget: | B12: ='Inputs & Assumptions'!B22 -> 49500
A14: Total Acquisition Costs: | B14: =SUM(B8:B12) -> 204050
A16: Down Payment (Cash Required): | B16: =B14-'Inputs & Assumptions'!B54 -> -9100
A17: Loan Amount: | B17: ='Inputs & Assumptions'!B54 -> 213150
A19: Equity in Property: | B19: =B5-B17 -> 71050
A20: All-In Cost: | B20: =B14 -> 204050
A22: RENTAL ANALYSIS (YEAR 1)
A23: Monthly Rent: | B23: ='Inputs & Assumptions'!B35 -> 2425
A24: 1% Rule Test: | B24: =B23/'Inputs & Assumptions'!B13 -> 0.016166667 | C24: =IF(B24>=0.01,"✓ Pass","✗ Fail") -> ✓ Pass
A25: Annual Gross Rent: | B25: =B23*12 -> 29100
A26: Annual Operating Expenses: | B26: ='Inputs & Assumptions'!B50 -> 13528
A27: Net Operating Income (NOI): | B27: =B25-B26 -> 15572
A28: Cap Rate (All-Cash): | B28: =B27/B20 -> 0.076314629
A29: Cap Rate (Market): | B29: =B27/B5 -> 0.0547924
A31: DEBT SERVICE COVERAGE
A32: Monthly Debt Service: | B32: ='Inputs & Assumptions'!B59 -> 1490.3757
A33: Annual Debt Service: | B33: =B32*12 -> 17884.509
A34: DSCR: | B34: =B27/B33 -> 0.87069767 | C34: =IF(B34>=1.25,"✓ Strong","⚠ Acceptable") -> ⚠ Acceptable
A36: CASH FLOW & RETURNS
A37: Net Operating Income: | B37: =B27 -> 15572
A38: Annual Debt Service: | B38: =B33 -> 17884.509
A39: Annual Cash Flow: | B39: =B37-B38 -> -2312.5087
A40: Monthly Cash Flow: | B40: =B39/12 -> -192.70906
A42: Cash-on-Cash Return: | B42: =B39/B16 -> 0.25412184
A44: 70% RULE CHECK (FLIP ALTERNATIVE)
A45: ARV × 70%: | B45: =B5*0.7 -> 198940
A46: Less: Renovation Cost: | B46: =-'Inputs & Assumptions'!B22 -> -49500
A47: Maximum Allowable Offer: | B47: =B45+B46 -> 149440
A48: Your Purchase Price: | B48: ='Inputs & Assumptions'!B13 -> 150000
A49: 70% Rule Status: | B49: =IF(B48<=B47,"✓ Pass - Good Flip Deal","✗ Fail - Hold Better") -> ✗ Fail - Hold Better
A51: DETAILED METRICS
...

Sheet 10-Year Cash Flow
A1: 10-YEAR CASH FLOW PROJECTION
A2: Rental Income & Expense Projections with Annual Growth
A4: Year | B4: Gross Rent | C4: Vacancy Loss | D4: Effective Income | E4: Operating Expenses | F4: NOI | G4: Debt Service | H4: Cash Flow Before Tax | I4: Cumulative CF | J4: Property Value
A5: 0 | B5: 0 | C5: 0 | D5: 0 | E5: 0 | F5: 0 | G5: 0 | H5: =-'Acquisition Analysis'!B16 -> 9100 | I5: =H5 -> 9100 | J5: ='Inputs & Assumptions'!B28 -> 284200
A6: 1 | B6: ='Inputs & Assumptions'!B35*12 -> 29100 | C6: =-B6*'Inputs & Assumptions'!$B$38 -> -1455 | D6: =B6+C6 -> 27645 | E6: ='Inputs & Assumptions'!B50 -> 13528 | F6: =D6-E6 -> 14117 | G6: ='Inputs & Assumptions'!$B$59*12 -> 17884.509 | H6: =F6-G6 -> -3767.5087 | I6: =I5+H6 -> 5332.4913 | J6: =J5*(1+'Inputs & Assumptions'!$B$65) -> 295568
A7: 2 | B7: =B6*(1+'Inputs & Assumptions'!$B$63) -> 29973 | C7: =-B7*'Inputs & Assumptions'!$B$38 -> -1498.65 | D7: =B7+C7 -> 28474.35 | E7: =E6*(1+'Inputs & Assumptions'!$B$64) -> 14001.48 | F7: =D7-E7 -> 14472.87 | G7: ='Inputs & Assumptions'!$B$59*12 -> 17884.509 | H7: =F7-G7 -> -3411.6387 | I7: =I6+H7 -> 1920.8526 | J7: =J6*(1+'Inputs & Assumptions'!$B$65) -> 307390.72
A8: 3 | B8: =B7*(1+'Inputs & Assumptions'!$B$63) -> 30872.19 | C8: =-B8*'Inputs & Assumptions'!$B$38 -> -1543.6095 | D8: =B8+C8 -> 29328.581 | E8: =E7*(1+'Inputs & Assumptions'!$B$64) -> 14491.532 | F8: =D8-E8 -> 14837.049 | G8: ='Inputs & Assumptions'!$B$59*12 -> 17884.509 | H8: =F8-G8 -> -3047.46 | I8: =I7+H8 -> -1126.6074 | J8: =J7*(1+'Inputs & Assumptions'!$B$65) -> 319686.35
A9: 4 | B9: =B8*(1+'Inputs & Assumptions'!$B$63) -> 31798.356 | C9: =-B9*'Inputs & Assumptions'!$B$38 -> -1589.9178 | D9: =B9+C9 -> 30208.438 | E9: =E8*(1+'Inputs & Assumptions'!$B$64) -> 14998.735 | F9: =D9-E9 -> 15209.703 | G9: ='Inputs & Assumptions'!$B$59*12 -> 17884.509 | H9: =F9-G9 -> -2674.8062 | I9: =I8+H9 -> -3801.4136 | J9: =J8*(1+'Inputs & Assumptions'!$B$65) -> 332473.8
A10: 5 | B10: =B9*(1+'Inputs & Assumptions'!$B$63) -> 32752.306 | C10: =-B10*'Inputs & Assumptions'!$B$38 -> -1637.6153 | D10: =B10+C10 -> 31114.691 | E10: =E9*(1+'Inputs & Assumptions'!$B$64) -> 15523.691 | F10: =D10-E10 -> 15591 | G10: ='Inputs & Assumptions'!$B$59*12 -> 17884.509 | H10: =F10-G10 -> -2293.5088 | I10: =I9+H10 -> -6094.9224 | J10: =J9*(1+'Inputs & Assumptions'!$B$65) -> 345772.75
A11: 6 | B11: =B10*(1+'Inputs & Assumptions'!$B$63) -> 33734.876 | C11: =-B11*'Inputs & Assumptions'!$B$38 -> -1686.7438 | D11: =B11+C11 -> 32048.132 | E11: =E10*(1+'Inputs & Assumptions'!$B$64) -> 16067.02 | F11: =D11-E11 -> 15981.111 | G11: ='Inputs & Assumptions'!$B$59*12 -> 17884.509 | H11: =F11-G11 -> -1903.3973 | I11: =I10+H11 -> -7998.3197 | J11: =J10*(1+'Inputs & Assumptions'!$B$65) -> 359603.67
A12: 7 | B12: =B11*(1+'Inputs & Assumptions'!$B$63) -> 34746.922 | C12: =-B12*'Inputs & Assumptions'!$B$38 -> -1737.3461 | D12: =B12+C12 -> 33009.576 | E12: =E11*(1+'Inputs & Assumptions'!$B$64) -> 16629.366 | F12: =D12-E12 -> 16380.21 | G12: ='Inputs & Assumptions'!$B$59*12 -> 17884.509 | H12: =F12-G12 -> -1504.299 | I12: =I11+H12 -> -9502.6187 | J12: =J11*(1+'Inputs & Assumptions'!$B$65) -> 373987.81
A13: 8 | B13: =B12*(1+'Inputs & Assumptions'!$B$63) -> 35789.329 | C13: =-B13*'Inputs & Assumptions'!$B$38 -> -1789.4665 | D13: =B13+C13 -> 33999.863 | E13: =E12*(1+'Inputs & Assumptions'!$B$64) -> 17211.394 | F13: =D13-E13 -> 16788.469 | G13: ='Inputs & Assumptions'!$B$59*12 -> 17884.509 | H13: =F13-G13 -> -1096.0396 | I13: =I12+H13 -> -10598.658 | J13: =J12*(1+'Inputs & Assumptions'!$B$65) -> 388947.32
A14: 9 | B14: =B13*(1+'Inputs & Assumptions'!$B$63) -> 36863.009 | C14: =-B14*'Inputs & Assumptions'!$B$38 -> -1843.1505 | D14: =B14+C14 -> 35019.859 | E14: =E13*(1+'Inputs & Assumptions'!$B$64) -> 17813.793 | F14: =D14-E14 -> 17206.066 | G14: ='Inputs & Assumptions'!$B$59*12 -> 17884.509 | H14: =F14-G14 -> -678.44245 | I14: =I13+H14 -> -11277.101 | J14: =J13*(1+'Inputs & Assumptions'!$B$65) -> 404505.22
A15: 10 | B15: =B14*(1+'Inputs & Assumptions'!$B$63) -> 37968.9 | C15: =-B15*'Inputs & Assumptions'!$B$38 -> -1898.445 | D15: =B15+C15 -> 36070.455 | E15: =E14*(1+'Inputs & Assumptions'!$B$64) -> 18437.275 | F15: =D15-E15 -> 17633.179 | G15: ='Inputs & Assumptions'!$B$59*12 -> 17884.509 | H15: =F15-G15 -> -251.32943 | I15: =I14+H15 -> -11528.43 | J15: =J14*(1+'Inputs & Assumptions'!$B$65) -> 420685.43
A17: EXIT ANALYSIS (Year 10)
A18: Property Value: | B18: =J15 -> 420685.43
A19: Sales Commission (6%): | B19: =-B18*'Inputs & Assumptions'!B69 -> -25241.126
A20: Closing Costs (1.5%): | B20: =-B18*'Inputs & Assumptions'!B70 -> -6310.2814
A21: Net Sales Proceeds: | B21: =SUM(B18:B20) -> 389134.02
A22: Loan Payoff: | B22: =-'Inputs & Assumptions'!B54 -> -213150 | C22: (Simplified - assumes no principal paydown)
A23: Cash to Seller: | B23: =B21+B22 -> 175984.02
A25: TAX CALCULATION
A26: Original Basis: | B26: ='Acquisition Analysis'!B20 -> 204050
A27: Accumulated Depreciation: | B27: =-'Inputs & Assumptions'!B79*10 -> -82676.364
A28: Adjusted Basis: | B28: =B26+B27 -> 121373.64
A29: Capital Gain: | B29: =B18-B28 -> 299311.79
A30: Capital Gains Tax (20%): | B30: =-B29*'Inputs & Assumptions'!B71 -> -59862.358
A31: Depreciation Recapture (25%): | B31: =B27*'Inputs & Assumptions'!B72 -> -20669.091
A32: Total Tax: | B32: =B30+B31 -> -80531.449
A33: After-Tax Proceeds: | B33: =B23+B32 -> 95452.57
A35: KEY RETURN METRICS
A36: Total Cash Invested: | B36: =-'Acquisition Analysis'!B16 -> 9100
A37: Total Cash Flow (10 Years): | B37: =SUM(H6:H15) -> -20628.43
A38: After-Tax Exit Proceeds: | B38: =B33 -> 95452.57
A39: Total Return: | B39: =B37+B38-B36 -> 65724.14

Sheet BRRRR Scenario
A1: BRRRR REFINANCE STRATEGY
A2: Buy, Rehab, Rent, Refinance, Repeat
A4: INITIAL ACQUISITION (Hard Money)
A5: Purchase Price: | B5: ='Inputs & Assumptions'!B13 -> 150000
A6: Renovation Budget: | B6: ='Inputs & Assumptions'!B22 -> 49500
A7: Acquisition Costs: | B7: ='Inputs & Assumptions'!B15+'Inputs & Assumptions'!B16+'Inputs & Assumptions'!B17 -> 4550
A8: Total Project Cost: | B8: =SUM(B5:B7) -> 204050
A10: Hard Money Loan (75% LTC): | B10: =B8*0.75 -> 153037.5
A11: Hard Money Rate: | B11: 0.1
A12: Points (3%): | B12: =B10*0.03 -> 4591.125
A13: Hold Period (Months): | B13: 9
A14: Interest Cost: | B14: =B10*B11*B13/12 -> 11477.812
A15: Total Hard Money Cost: | B15: =B12+B14 -> 16068.938
A17: Cash Required: | B17: =B8-B10+B15 -> 67081.438
A20: AFTER RENOVATION (Month 9)
A21: After Repair Value (ARV): | B21: ='Inputs & Assumptions'!B28 -> 284200
A22: Stabilized Monthly Rent: | B22: ='Inputs & Assumptions'!B35 -> 2425
A23: Monthly NOI: | B23: =B22*0.95-'Inputs & Assumptions'!B49 -> 1176.4167
A25: REFINANCE
A26: Refinance LTV: | B26: 0.75
A27: New Loan Amount: | B27: =B21*B26 -> 213150
A28: Refinance Rate: | B28: ='Inputs & Assumptions'!B55 -> 0.075
A29: Refinance Term (Years): | B29: 30
A30: New Monthly Payment: | B30: =PMT(B28/12,B29*12,-B27) -> 1490.3757
A32: Refinance Closing Costs: | B32: =B27*0.02 -> 4263
A33: Pay Off Hard Money Loan: | B33: =-B10 -> -153037.5
A34: Cash Out to Investor: | B34: =B27+B33-B32 -> 55849.5
A37: BRRRR RESULTS
A38: Total Cash Invested: | B38: =B17 -> 67081.438
A39: Cash Returned via Refinance: | B39: =B34 -> 55849.5
A40: Net Cash Left in Deal: | B40: =B38-B39 -> 11231.938
A42: Property Value: | B42: =B21 -> 284200
A43: New Loan Balance: | B43: =B27 -> 213150
A44: Equity Position: | B44: =B42-B43 -> 71050
A45: Equity %: | B45: =B44/B42 -> 0.25
A47: Post-Refinance Monthly Cash Flow: | B47: =B23-B30 -> -313.95906
A48: Cash-on-Cash Return: | B48: =IF(B40<=0,999%,B47*12/B40) -> -0.33542821 | C48: Infinite if all cash out!
A51: STRATEGY COMPARISON
A52: Metric | B52: Traditional Purchase | C52: BRRRR Strategy
A53: Cash Required | B53: ='Acquisition Analysis'!B16 -> -9100 | C53: =B17 -> 67081.438
...

Sheet Exit Strategies
A1: EXIT STRATEGY COMPARISON
A2: Four Different Paths to Profit
A4: Metric | B4: Flip (6mo) | C4: BRRRR (Refi) | D4: Hold 10 Years | E4: Hold Forever
A5: Timeline | B5: 6 months | C5: 9 months + hold | D5: 10 years | E5: Indefinite
A6: Cash Out at Exit | B6: ='Inputs & Assumptions'!B28*0.92-'Acquisition Analysis'!B14 -> 57414 | C6: ='BRRRR Scenario'!B34 -> 55849.5 | D6: ='10-Year Cash Flow'!B33 -> 95452.57 | E6: $0
A7: Monthly Income | B7: $0 | C7: ='BRRRR Scenario'!B47 -> -313.95906 | D7: ='10-Year Cash Flow'!G60/12 -> 0 | E7: ='10-Year Cash Flow'!G59 -> 0
A8: Total Return | B8: =B6 -> 57414 | C8: =C6+'10-Year Cash Flow'!B37 -> 35221.07 | D8: ='10-Year Cash Flow'!B39 -> 65724.14 | E8: Ongoing
A9: IRR | B9: =(B6/'Acquisition Analysis'!B16)^(12/6)-1 -> 38.806393 | C9: 17% | D9: ='10-Year Cash Flow'!B41 -> 0 | E9: 12%+
A10: Capital Efficiency | B10: Low | C10: High | D10: Medium | E10: Low
A11: Complexity | B11: Low | C11: Medium | D11: Medium | E11: High
A13: BEST FOR:
A14: Flip: | B14: ✓ Need capital quickly
B15: ✓ Strong buyer market
B16: ✓ Simple exit strategy
A18: BRRRR: | C18: ✓ Want to scale portfolio
C19: ✓ Recycle capital fast
C20: ✓ Build rental portfolio
A22: Hold 10 Years: | D22: ✓ High IRR target
D23: ✓ Tax-efficient exit
D24: ✓ Strong appreciation
A26: Hold Forever: | E26: ✓ Passive income goal
E27: ✓ Don't need capital
E28: ✓ Legacy building

Sheet Sensitivity Analysis
A1: SENSITIVITY ANALYSIS
A2: Test Key Variables to Understand Risk & Upside
A4: SENSITIVITY TO MONTHLY RENT
A5: Base Monthly Rent: | B5: ='Inputs & Assumptions'!B35 -> 2425
A7: Change | B7: -10% | C7: -5% | D7: Base | E7: +5% | F7: +10%
A8: Monthly Rent | B8: =B5*0.9 -> 2182.5 | C8: =B5*0.95 -> 2303.75 | D8: =B5 -> 2425 | E8: =B5*1.05 -> 2546.25 | F8: =B5*1.1 -> 2667.5
A9: Annual NOI | B9: =B8*12*0.95-'Inputs & Assumptions'!B50 -> 11352.5 | C9: =C8*12*0.95-'Inputs & Assumptions'!B50 -> 12734.75 | D9: =D8*12*0.95-'Inputs & Assumptions'!B50 -> 14117 | E9: =E8*12*0.95-'Inputs & Assumptions'!B50 -> 15499.25 | F9: =F8*12*0.95-'Inputs & Assumptions'!B50 -> 16881.5
A10: Monthly Cash Flow | B10: =(B9-'Inputs & Assumptions'!B59*12)/12 -> -544.33406 | C10: =(C9-'Inputs & Assumptions'!B59*12)/12 -> -429.14656 | D10: =(D9-'Inputs & Assumptions'!B59*12)/12 -> -313.95906 | E10: =(E9-'Inputs & Assumptions'!B59*12)/12 -> -198.77156 | F10: =(F9-'Inputs & Assumptions'!B59*12)/12 -> -83.584058
A11: Cash-on-Cash Return | B11: =B10*12/'Acquisition Analysis'!B16 -> 0.71780315 | C11: =C10*12/'Acquisition Analysis'!B16 -> 0.56590755 | D11: =D10*12/'Acquisition Analysis'!B16 -> 0.41401195 | E11: =E10*12/'Acquisition Analysis'!B16 -> 0.26211634 | F11: =F10*12/'Acquisition Analysis'!B16 -> 0.11022074
A14: SENSITIVITY TO PROPERTY APPRECIATION
A15: Base Annual Appreciation: | B15: ='Inputs & Assumptions'!B65 -> 0.04
A17: Appreciation | B17: 2.0% | C17: 3.0% | D17: 4.0% | E17: 5.0% | F17: 6.0%
A18: Year 10 Value | B18: ='Inputs & Assumptions'!B28*(1+0.02)^10 -> 346438.21 | C18: ='Inputs & Assumptions'!B28*(1+0.03)^10 -> 381941.04 | D18: ='Inputs & Assumptions'!B28*(1+0.04)^10 -> 420685.43 | E18: ='Inputs & Assumptions'!B28*(1+0.05)^10 -> 462931.85 | F18: ='Inputs & Assumptions'!B28*(1+0.06)^10 -> 508958.92
A19: Total Equity | B19: =B18-'Inputs & Assumptions'!B54 -> 133288.21 | C19: =C18-'Inputs & Assumptions'!B54 -> 168791.04 | D19: =D18-'Inputs & Assumptions'!B54 -> 207535.43 | E19: =E18-'Inputs & Assumptions'!B54 -> 249781.85 | F19: =F18-'Inputs & Assumptions'!B54 -> 295808.92
A20: Equity Multiple | B20: =B19/'Acquisition Analysis'!B16 -> -14.647057 | C20: =C19/'Acquisition Analysis'!B16 -> -18.548465 | D20: =D19/'Acquisition Analysis'!B16 -> -22.806091 | E20: =E19/'Acquisition Analysis'!B16 -> -27.448555 | F20: =F19/'Acquisition Analysis'!B16 -> -32.506474
A23: SENSITIVITY TO INTEREST RATES
A24: Base Interest Rate: | B24: ='Inputs & Assumptions'!B55 -> 0.075
A26: Interest Rate | B26: 6.5% | C26: 7.0% | D26: 7.5% | E26: 8.0% | F26: 8.5%
A27: Monthly Payment | B27: =PMT(0.065/12,30*12,-'Inputs & Assumptions'!B54) -> 1347.253 | C27: =PMT(0.07/12,30*12,-'Inputs & Assumptions'!B54) -> 1418.0923 | D27: =PMT(0.075/12,30*12,-'Inputs & Assumptions'!B54) -> 1490.3757 | E27: =PMT(0.08/12,30*12,-'Inputs & Assumptions'!B54) -> 1564.0192 | F27: =PMT(0.085/12,30*12,-'Inputs & Assumptions'!B54) -> 1638.9391
A28: Monthly Cash Flow | B28: ='Acquisition Analysis'!B27/12-B27 -> -49.586325 | C28: ='Acquisition Analysis'!B27/12-C27 -> -120.4256 | D28: ='Acquisition Analysis'!B27/12-D27 -> -192.70906 | E28: ='Acquisition Analysis'!B27/12-E27 -> -266.35252 | F28: ='Acquisition Analysis'!B27/12-F27 -> -341.27242
A29: Cash-on-Cash Return | B29: =B28*12/'Acquisition Analysis'!B16 -> 0.065388561 | C29: =C28*12/'Acquisition Analysis'!B16 -> 0.15880299 | D29: =D28*12/'Acquisition Analysis'!B16 -> 0.25412184 | E29: =E28*12/'Acquisition Analysis'!B16 -> 0.3512341 | F29: =F28*12/'Acquisition Analysis'!B16 -> 0.45002957
A32: WORST CASE SCENARIO
A33: Assumptions:
A34: • Rent: -10% below market
A35: • Vacancy: 15% (vs 5% base)
A36: • Expenses: +25% above base
A37: • Appreciation: 2% (vs 4% base)
A39: Monthly Rent (Low): | B39: ='Inputs & Assumptions'!B35*0.9 -> 2182.5
A40: Effective Income (85%): | B40: =B39*0.85*12 -> 22261.5
A41: Operating Expenses (+25%): | B41: ='Inputs & Assumptions'!B50*1.25 -> 16910
A42: NOI (Worst Case): | B42: =B40-B41 -> 5351.5
A43: Annual Debt Service: | B43: ='Inputs & Assumptions'!B59*12 -> 17884.509
A44: Cash Flow (Worst Case): | B44: =B42-B43 -> -12533.009
A45: Monthly Cash Flow: | B45: =B44/12 -> -1044.4174
A48: BREAK-EVEN ANALYSIS
A49: Monthly Expenses + Debt: | B49: ='Inputs & Assumptions'!B49+'Inputs & Assumptions'!B59 -> 2617.7091
A50: Required Gross Rent: | B50: =B49/0.95 -> 2755.4832
A51: Actual Gross Rent: | B51: ='Inputs & Assumptions'!B35 -> 2425
A52: Cushion Above Break-Even: | B52: =B51-B50 -> -330.48322
A53: Cushion %: | B53: =B52/B51 -> -0.13628174

Sheet Tax Benefits
A1: TAX BENEFITS ANALYSIS
A2: Depreciation & Tax Deductions
A4: DEPRECIATION SCHEDULE
A5: Property Value: | B5: ='Inputs & Assumptions'!B28 -> 284200
A6: Land Value (20%): | B6: =B5*'Inputs & Assumptions'!B76 -> 56840
A7: Building Value (Depreciable): | B7: =B5-B6 -> 227360
A8: Depreciation Period: | B8: ='Inputs & Assumptions'!B78 -> 27.5
A9: Annual Depreciation: | B9: =B7/B8 -> 8267.6364
A12: 10-YEAR DEPRECIATION TABLE
A13: Year | B13: Depreciation | C13: Accumulated | D13: Remaining Basis
A14: 1 | B14: =$B$9 -> 8267.6364 | C14: =B14 -> 8267.6364 | D14: =$B$7-C14 -> 219092.36
A15: 2 | B15: =$B$9 -> 8267.6364 | C15: =C14+B15 -> 16535.273 | D15: =$B$7-C15 -> 210824.73
A16: 3 | B16: =$B$9 -> 8267.6364 | C16: =C15+B16 -> 24802.909 | D16: =$B$7-C16 -> 202557.09
A17: 4 | B17: =$B$9 -> 8267.6364 | C17: =C16+B17 -> 33070.545 | D17: =$B$7-C17 -> 194289.45
A18: 5 | B18: =$B$9 -> 8267.6364 | C18: =C17+B18 -> 41338.182 | D18: =$B$7-C18 -> 186021.82
A19: 6 | B19: =$B$9 -> 8267.6364 | C19: =C18+B19 -> 49605.818 | D19: =$B$7-C19 -> 177754.18
A20: 7 | B20: =$B$9 -> 8267.6364 | C20: =C19+B20 -> 57873.455 | D20: =$B$7-C20 -> 169486.55
A21: 8 | B21: =$B$9 -> 8267.6364 | C21: =C20+B21 -> 66141.091 | D21: =$B$7-C21 -> 161218.91
A22: 9 | B22: =$B$9 -> 8267.6364 | C22: =C21+B22 -> 74408.727 | D22: =$B$7-C22 -> 152951.27
A23: 10 | B23: =$B$9 -> 8267.6364 | C23: =C22+B23 -> 82676.364 | D23: =$B$7-C23 -> 144683.64
A25: TAX SAVINGS ANALYSIS (YEAR 1)
A26: Net Operating Income: | B26: ='Acquisition Analysis'!B27 -> 15572
A27: Interest Expense: | B27: =-'Inputs & Assumptions'!B54*'Inputs & Assumptions'!B55 -> -15986.25
A28: Depreciation: | B28: =-B9 -> -8267.6364
A29: Other Deductions: | B29: 0
A31: Taxable Income: | B31: =SUM(B26:B29) -> -8681.8864
A33: Tax Bracket: | B33: ='Inputs & Assumptions'!B80 -> 0.35
A34: Tax Liability (Savings): | B34: =B31*B33 -> -3038.6602
A36: Pre-Tax Cash Flow: | B36: ='Acquisition Analysis'!B39 -> -2312.5087
A37: Tax Savings: | B37: =-B34 -> 3038.6602
A38: After-Tax Cash Flow: | B38: =B36+B37 -> 726.15153
A41: 1031 EXCHANGE STRATEGY
A42: Sale Price (Year 10): | B42: ='10-Year Cash Flow'!B18 -> 420685.43
A43: Adjusted Basis: | B43: ='10-Year Cash Flow'!B28 -> 121373.64
A44: Capital Gain: | B44: =B42-B43 -> 299311.79
A46: Tax WITHOUT 1031: | B46: ='10-Year Cash Flow'!B32 -> -80531.449
A47: Tax WITH 1031: | B47: $0
A48: Tax Savings via 1031: | B48: =B46-B47 -> -80531.449
A50: 1031 Requirements:
A51: ✓ Identify replacement property within 45 days
...

Sheet Portfolio Scaling
A1: PORTFOLIO SCALING SCENARIOS
A2: Building a Multi-Property Portfolio
A4: SCENARIO 1: CONSERVATIVE SCALE (1 Property/Year)
A5: Year | B5: Properties | C5: Total Rent | D5: Total CF/Year | E5: Portfolio Value | F5: Total Equity
A6: 0 | B6: 0 | C6: 0 | D6: 0 | E6: 0 | F6: 0
A7: 1 | B7: 1 | C7: ='Inputs & Assumptions'!$B$35*B7*12*(1+'Inputs & Assumptions'!$B$63)^(A7-1) -> 29100 | D7: ='Acquisition Analysis'!$B$39*B7*(1+'Inputs & Assumptions'!$B$63)^(A7-1) -> -2312.5087 | E7: ='Inputs & Assumptions'!$B$28*B7*(1+'Inputs & Assumptions'!$B$65)^(A7-1) -> 284200 | F7: =(E7-'Inputs & Assumptions'!$B$54*B7) -> 71050
A8: 2 | B8: 2 | C8: ='Inputs & Assumptions'!$B$35*B8*12*(1+'Inputs & Assumptions'!$B$63)^(A8-1) -> 59946 | D8: ='Acquisition Analysis'!$B$39*B8*(1+'Inputs & Assumptions'!$B$63)^(A8-1) -> -4763.7679 | E8: ='Inputs & Assumptions'!$B$28*B8*(1+'Inputs & Assumptions'!$B$65)^(A8-1) -> 591136 | F8: =(E8-'Inputs & Assumptions'!$B$54*B8) -> 164836
A9: 3 | B9: 3 | C9: ='Inputs & Assumptions'!$B$35*B9*12*(1+'Inputs & Assumptions'!$B$63)^(A9-1) -> 92616.57 | D9: ='Acquisition Analysis'!$B$39*B9*(1+'Inputs & Assumptions'!$B$63)^(A9-1) -> -7360.0214 | E9: ='Inputs & Assumptions'!$B$28*B9*(1+'Inputs & Assumptions'!$B$65)^(A9-1) -> 922172.16 | F9: =(E9-'Inputs & Assumptions'!$B$54*B9) -> 282722.16
A10: 4 | B10: 4 | C10: ='Inputs & Assumptions'!$B$35*B10*12*(1+'Inputs & Assumptions'!$B$63)^(A10-1) -> 127193.42 | D10: ='Acquisition Analysis'!$B$39*B10*(1+'Inputs & Assumptions'!$B$63)^(A10-1) -> -10107.763 | E10: ='Inputs & Assumptions'!$B$28*B10*(1+'Inputs & Assumptions'!$B$65)^(A10-1) -> 1278745.4 | F10: =(E10-'Inputs & Assumptions'!$B$54*B10) -> 426145.4
A11: 5 | B11: 5 | C11: ='Inputs & Assumptions'!$B$35*B11*12*(1+'Inputs & Assumptions'!$B$63)^(A11-1) -> 163761.53 | D11: ='Acquisition Analysis'!$B$39*B11*(1+'Inputs & Assumptions'!$B$63)^(A11-1) -> -13013.745 | E11: ='Inputs & Assumptions'!$B$28*B11*(1+'Inputs & Assumptions'!$B$65)^(A11-1) -> 1662369 | F11: =(E11-'Inputs & Assumptions'!$B$54*B11) -> 596619.01
A12: 6 | B12: 6 | C12: ='Inputs & Assumptions'!$B$35*B12*12*(1+'Inputs & Assumptions'!$B$63)^(A12-1) -> 202409.25 | D12: ='Acquisition Analysis'!$B$39*B12*(1+'Inputs & Assumptions'!$B$63)^(A12-1) -> -16084.988 | E12: ='Inputs & Assumptions'!$B$28*B12*(1+'Inputs & Assumptions'!$B$65)^(A12-1) -> 2074636.5 | F12: =(E12-'Inputs & Assumptions'!$B$54*B12) -> 795736.53
A13: 7 | B13: 7 | C13: ='Inputs & Assumptions'!$B$35*B13*12*(1+'Inputs & Assumptions'!$B$63)^(A13-1) -> 243228.45 | D13: ='Acquisition Analysis'!$B$39*B13*(1+'Inputs & Assumptions'!$B$63)^(A13-1) -> -19328.794 | E13: ='Inputs & Assumptions'!$B$28*B13*(1+'Inputs & Assumptions'!$B$65)^(A13-1) -> 2517225.7 | F13: =(E13-'Inputs & Assumptions'!$B$54*B13) -> 1025175.7
A14: 8 | B14: 8 | C14: ='Inputs & Assumptions'!$B$35*B14*12*(1+'Inputs & Assumptions'!$B$63)^(A14-1) -> 286314.64 | D14: ='Acquisition Analysis'!$B$39*B14*(1+'Inputs & Assumptions'!$B$63)^(A14-1) -> -22752.752 | E14: ='Inputs & Assumptions'!$B$28*B14*(1+'Inputs & Assumptions'!$B$65)^(A14-1) -> 2991902.5 | F14: =(E14-'Inputs & Assumptions'!$B$54*B14) -> 1286702.5
A15: 9 | B15: 9 | C15: ='Inputs & Assumptions'!$B$35*B15*12*(1+'Inputs & Assumptions'!$B$63)^(A15-1) -> 331767.08 | D15: ='Acquisition Analysis'!$B$39*B15*(1+'Inputs & Assumptions'!$B$63)^(A15-1) -> -26364.752 | E15: ='Inputs & Assumptions'!$B$28*B15*(1+'Inputs & Assumptions'!$B$65)^(A15-1) -> 3500525.9 | F15: =(E15-'Inputs & Assumptions'!$B$54*B15) -> 1582175.9
A16: 10 | B16: 10 | C16: ='Inputs & Assumptions'!$B$35*B16*12*(1+'Inputs & Assumptions'!$B$63)^(A16-1) -> 379689 | D16: ='Acquisition Analysis'!$B$39*B16*(1+'Inputs & Assumptions'!$B$63)^(A16-1) -> -30172.993 | E16: ='Inputs & Assumptions'!$B$28*B16*(1+'Inputs & Assumptions'!$B$65)^(A16-1) -> 4045052.2 | F16: =(E16-'Inputs & Assumptions'!$B$54*B16) -> 1913552.2
A18: KEY METRICS (Year 10):
A19: Total Properties: | B19: =B16 -> 10
A20: Monthly Cash Flow: | B20: =D16/12 -> -2514.4161
A21: Annual Cash Flow: | B21: =D16 -> -30172.993
A22: Portfolio Value: | B22: =E16 -> 4045052.2
A23: Total Equity: | B23: =F16 -> 1913552.2
A24: Total Debt: | B24: =E16-F16 -> 2131500
A27: SCENARIO 2: BRRRR VELOCITY (Recycle Capital)
A28: Starting Capital: | B28: ='Acquisition Analysis'!B16 -> -9100
A29: Capital Recycled per Deal: | B29: ='BRRRR Scenario'!B34 -> 55849.5
A30: Months per Deal: | B30: 9
A31: Deals per Year: | B31: =12/B30 -> 1.3333333
A33: Properties after 10 Years: | B33: =B31*10 -> 13.333333
A34: Monthly Cash Flow (10 Years): | B34: ='BRRRR Scenario'!B47*B33 -> -4186.1208
A35: Annual Cash Flow: | B35: =B34*12 -> -50233.449
A36: Portfolio Value: | B36: ='Inputs & Assumptions'!B28*B33*(1+'Inputs & Assumptions'!B65)^10 -> 5609139
A37: Total Equity: | B37: =(B36-'BRRRR Scenario'!B27*B33) -> 2767139
A40: STRATEGY COMPARISON
A41: Metric | B41: Conservative | C41: BRRRR Velocity
A42: Properties (10 Years) | B42: =B16 -> 10 | C42: =B33 -> 13.333333
A43: Monthly Cash Flow | B43: =D16/12 -> -2514.4161 | C43: =B34 -> -4186.1208
A44: Annual Cash Flow | B44: =D16 -> -30172.993 | C44: =B35 -> -50233.449
A45: Portfolio Value | B45: =E16 -> 4045052.2 | C45: =B36 -> 5609139
A46: Total Equity | B46: =F16 -> 1913552.2 | C46: =B37 -> 2767139
A47: Starting Capital | B47: ='Acquisition Analysis'!B16 -> -9100 | C47: ='Acquisition Analysis'!B16 -> -9100
