Workbook

Sheet Executive Summary
B2: QUALITY OF EARNINGS ANALYSIS
B4: TRANSACTION OVERVIEW
B5: Target Company: | C5: Enter Company Name
B6: Analysis Date: | C6: =TODAY()
B7: Analysis Period: | C7: Last 3 Years + TTM
B8: Prepared By: | C8: Enter Name
B9: Transaction Type: | C9: PE Acquisition
B11: KEY FINDINGS SUMMARY
B12: Metric | C12: Year 1 | D12: Year 2 | E12: Year 3 | F12: TTM | G12: Change | H12: Comment
B13: Revenue ($mm) | C13: ="Reported Financials"!C12/1000 | D13: ="Reported Financials"!D12/1000 | E13: ="Reported Financials"!E12/1000 | F13: ="Reported Financials"!F12/1000 | G13: =F13-C13
B14: Reported EBITDA ($mm) | C14: ="Reported Financials"!C29/1000 | D14: ="Reported Financials"!D29/1000 | E14: ="Reported Financials"!E29/1000 | F14: ="Reported Financials"!F29/1000 | G14: =F14-C14
B15: Adjusted EBITDA ($mm) | C15: ="EBITDA Bridge"!C55/1000 | D15: ="EBITDA Bridge"!D55/1000 | E15: ="EBITDA Bridge"!E55/1000 | F15: ="EBITDA Bridge"!F55/1000 | G15: =F15-C15
B16: Reported EBITDA Margin % | C16: ="Reported Financials"!C30 | D16: ="Reported Financials"!D30 | E16: ="Reported Financials"!E30 | F16: ="Reported Financials"!F30 | G16: =F16-C16
B17: Adjusted EBITDA Margin % | C17: ="EBITDA Bridge"!C56 | D17: ="EBITDA Bridge"!D56 | E17: ="EBITDA Bridge"!E56 | F17: ="EBITDA Bridge"!F56 | G17: =F17-C17
B18: Adjustment Impact ($mm) | C18: ="EBITDA Bridge"!C53/1000 | D18: ="EBITDA Bridge"!D53/1000 | E18: ="EBITDA Bridge"!E53/1000 | F18: ="EBITDA Bridge"!F53/1000 | G18: =F18-C18
B19: Adjustment % of Reported | C19: ="EBITDA Bridge"!C58 | D19: ="EBITDA Bridge"!D58 | E19: ="EBITDA Bridge"!E58 | F19: ="EBITDA Bridge"!F58 | G19: =F19-C19
B22: EBITDA ADJUSTMENTS SUMMARY
B23: Adjustment Category | C23: Year 1 | D23: Year 2 | E23: Year 3 | F23: TTM | G23: Total | H23: % of Reported
B24: Non-Recurring Items | C24: ="EBITDA Bridge"!C15/1000 | D24: ="EBITDA Bridge"!D15/1000 | E24: ="EBITDA Bridge"!E15/1000 | F24: ="EBITDA Bridge"!F15/1000 | G24: =SUM(C24:E24) | H24: =IF(SUM(C14:E14)=0,0,G24/SUM(C14:E14))
B25: Owner Compensation | C25: ="EBITDA Bridge"!C23/1000 | D25: ="EBITDA Bridge"!D23/1000 | E25: ="EBITDA Bridge"!E23/1000 | F25: ="EBITDA Bridge"!F23/1000 | G25: =SUM(C25:E25) | H25: =IF(SUM(C14:E14)=0,0,G25/SUM(C14:E14))
B26: Owner Discretionary | C26: =0 | D26: =0 | E26: =0 | F26: =0 | G26: =SUM(C26:E26) | H26: =IF(SUM(C14:E14)=0,0,G26/SUM(C14:E14))
B27: Normalization Adjustments | C27: ="EBITDA Bridge"!C31/1000 | D27: ="EBITDA Bridge"!D31/1000 | E27: ="EBITDA Bridge"!E31/1000 | F27: ="EBITDA Bridge"!F31/1000 | G27: =SUM(C27:E27) | H27: =IF(SUM(C14:E14)=0,0,G27/SUM(C14:E14))
B28: Accounting Adjustments | C28: ="EBITDA Bridge"!C38/1000 | D28: ="EBITDA Bridge"!D38/1000 | E28: ="EBITDA Bridge"!E38/1000 | F28: ="EBITDA Bridge"!F38/1000 | G28: =SUM(C28:E28) | H28: =IF(SUM(C14:E14)=0,0,G28/SUM(C14:E14))
B29: Pro Forma Adjustments | C29: ="EBITDA Bridge"!C45/1000 | D29: ="EBITDA Bridge"!D45/1000 | E29: ="EBITDA Bridge"!E45/1000 | F29: ="EBITDA Bridge"!F45/1000 | G29: =SUM(C29:E29) | H29: =IF(SUM(C14:E14)=0,0,G29/SUM(C14:E14))
B30: TOTAL ADJUSTMENTS | C30: ="EBITDA Bridge"!C53/1000 | D30: ="EBITDA Bridge"!D53/1000 | E30: ="EBITDA Bridge"!E53/1000 | F30: ="EBITDA Bridge"!F53/1000 | G30: =SUM(C30:E30) | H30: =IF(SUM(C14:E14)=0,0,G30/SUM(C14:E14))
B32: EARNINGS QUALITY ASSESSMENT
B33: Revenue Quality | C33: High | D33: Strong customer base, diversified revenue streams
B34: Customer Concentration | C34: Medium | D34: Top 3 customers = 45% of revenue
B35: Revenue Recognition | C35: High | D35: Conservative, GAAP compliant
B36: Cost Structure | C36: High | D36: Predictable, well-documented
B37: Working Capital | C37: Medium | D37: Some seasonal fluctuation
B38: Overall Earnings Quality | C38: HIGH | D38: Strong sustainable earnings
B40: RED FLAGS & KEY RISKS
B41: Risk Category | C41: Severity | D41: Description | E41: Impact ($mm) | F41: Mitigation

Sheet Reported Financials
B2: HISTORICAL FINANCIAL STATEMENTS
B4: All figures in $thousands
B5: Analysis Period | C5: Year 1 | D5: Year 2 | E5: Year 3 | F5: TTM | G5: CAGR
C6: 2022 | D6: 2023 | E6: 2024 | F6: Q3-2025
B8: INCOME STATEMENT
B9: Revenue | C9: 0 | D9: 0 | E9: 0 | F9: 0
B10: Product Revenue | C10: 0 | D10: 0 | E10: 0 | F10: 0
B11: Service Revenue | C11: 0 | D11: 0 | E11: 0 | F11: 0
B12: Total Revenue | C12: =C10+C11 | D12: =D10+D11 | E12: =E10+E11 | F12: =F10+F11 | G12: =IF(AND(C12<>0,F12<>0),(POWER(F12/C12,1/3)-1),0)
B14: Cost of Goods Sold | C14: 0 | D14: 0 | E14: 0 | F14: 0
B15: Direct Materials | C15: 0 | D15: 0 | E15: 0 | F15: 0
B16: Direct Labor | C16: 0 | D16: 0 | E16: 0 | F16: 0
B17: Manufacturing Overhead | C17: 0 | D17: 0 | E17: 0 | F17: 0
B18: Total COGS | C18: =SUM(C14:C17) | D18: =SUM(D14:D17) | E18: =SUM(E14:E17) | F18: =SUM(F14:F17)
B20: Gross Profit | C20: =C12-C18 | D20: =D12-D18 | E20: =E12-E18 | F20: =F12-F18
B21: Gross Margin % | C21: =IF(C12=0,0,C20/C12) | D21: =IF(D12=0,0,D20/D12) | E21: =IF(E12=0,0,E20/E12) | F21: =IF(F12=0,0,F20/F12)
B23: Operating Expenses
B24: Sales & Marketing | C24: 0 | D24: 0 | E24: 0 | F24: 0
B25: Research & Development | C25: 0 | D25: 0 | E25: 0 | F25: 0
B26: General & Administrative | C26: 0 | D26: 0 | E26: 0 | F26: 0
B27: Total Operating Expenses | C27: =SUM(C24:C26) | D27: =SUM(D24:D26) | E27: =SUM(E24:E26) | F27: =SUM(F24:F26)
B29: EBITDA (As Reported) | C29: =C20-C27 | D29: =D20-D27 | E29: =E20-E27 | F29: =F20-F27
B30: EBITDA Margin % | C30: =IF(C12=0,0,C29/C12) | D30: =IF(D12=0,0,D29/D12) | E30: =IF(E12=0,0,E29/E12) | F30: =IF(F12=0,0,F29/F12)
B32: Depreciation & Amortization | C32: 0 | D32: 0 | E32: 0 | F32: 0
B33: EBIT | C33: =C29-C32 | D33: =D29-D32 | E33: =E29-E32 | F33: =F29-F32
B34: Interest Expense | C34: 0 | D34: 0 | E34: 0 | F34: 0
B35: Interest Income | C35: 0 | D35: 0 | E35: 0 | F35: 0
B36: Other Income/(Expense) | C36: 0 | D36: 0 | E36: 0 | F36: 0
B38: Earnings Before Tax | C38: =C33-C34+C35+C36 | D38: =D33-D34+D35+D36 | E38: =E33-E34+E35+E36 | F38: =F33-F34+F35+F36
B39: Income Tax Expense | C39: 0 | D39: 0 | E39: 0 | F39: 0
B40: Net Income | C40: =C38-C39 | D40: =D38-D39 | E40: =E38-E39 | F40: =F38-F39
B41: CASH FLOW METRICS
B42: Operating Cash Flow
B43: Capital Expenditures
B44: Free Cash Flow | C44: =C42-C43 | D44: =D42-D43 | E44: =E42-E43 | F44: =F42-F43
B45: FCF Conversion (FCF/EBITDA) | C45: =IF(C29=0,0,C44/C29) | D45: =IF(D29=0,0,D44/D29) | E45: =IF(E29=0,0,E44/E29) | F45: =IF(F29=0,0,F44/F29)

Sheet EBITDA Bridge
B2: EBITDA RECONCILIATION & BRIDGE
B4: All figures in $thousands
B5: Description | C5: Year 1 | D5: Year 2 | E5: Year 3 | F5: TTM | G5: 3-Yr Avg
B6: REPORTED EBITDA | C6: ="Reported Financials"!C29 | D6: ="Reported Financials"!D29 | E6: ="Reported Financials"!E29 | F6: ="Reported Financials"!F29 | G6: =AVERAGE(C6:E6)
B8: ADD-BACKS (Increase EBITDA)
B9: Non-Recurring Expenses
B10: Litigation settlement | C10: 0 | D10: 0 | E10: 0 | F10: 0
B11: One-time professional fees | C11: 0 | D11: 0 | E11: 0 | F11: 0
B12: Restructuring costs | C12: 0 | D12: 0 | E12: 0 | F12: 0
B13: COVID-related expenses | C13: 0 | D13: 0 | E13: 0 | F13: 0
B14: Other non-recurring | C14: 0 | D14: 0 | E14: 0 | F14: 0
B15: Total Non-Recurring | C15: =SUM(C10:C14) | D15: =SUM(D10:D14) | E15: =SUM(E10:E14) | F15: =SUM(F10:F14) | G15: =AVERAGE(C15:E15)
B17: Owner-Related Adjustments
B18: Excess owner compensation | C18: 0 | D18: 0 | E18: 0 | F18: 0
B19: Personal vehicle expenses | C19: 0 | D19: 0 | E19: 0 | F19: 0
B20: Personal travel & entertainment | C20: 0 | D20: 0 | E20: 0 | F20: 0
B21: Family member salaries (non-working) | C21: 0 | D21: 0 | E21: 0 | F21: 0
B22: Country club dues | C22: 0 | D22: 0 | E22: 0 | F22: 0
B23: Total Owner-Related | C23: =SUM(C18:C22) | D23: =SUM(D18:D22) | E23: =SUM(E18:E22) | F23: =SUM(F18:F22) | G23: =AVERAGE(C23:E23)
B25: Normalization Adjustments
B26: Replacement management salary | C26: 0 | D26: 0 | E26: 0 | F26: 0
B27: Normalized rent expense | C27: 0 | D27: 0 | E27: 0 | F27: 0
B28: Normalized insurance | C28: 0 | D28: 0 | E28: 0 | F28: 0
B29: Deferred maintenance catch-up | C29: 0 | D29: 0 | E29: 0 | F29: 0
B30: Bad debt normalization | C30: 0 | D30: 0 | E30: 0 | F30: 0
B31: Total Normalization | C31: =SUM(C26:C30) | D31: =SUM(D26:D30) | E31: =SUM(E26:E30) | F31: =SUM(F26:F30) | G31: =AVERAGE(C31:E31)
B33: Accounting Adjustments
B34: Revenue recognition timing | C34: 0 | D34: 0 | E34: 0 | F34: 0
B35: Cash to accrual adjustments | C35: 0 | D35: 0 | E35: 0 | F35: 0
B36: Expense classification | C36: 0 | D36: 0 | E36: 0 | F36: 0
B37: Inventory valuation | C37: 0 | D37: 0 | E37: 0 | F37: 0
B38: Total Accounting | C38: =SUM(C34:C37) | D38: =SUM(D34:D37) | E38: =SUM(E34:E37) | F38: =SUM(F34:F37) | G38: =AVERAGE(C38:E38)
B40: Pro Forma Adjustments
B41: Annualized new customer contracts | C41: 0 | D41: 0 | E41: 0 | F41: 0
B42: Cost savings initiatives | C42: 0 | D42: 0 | E42: 0 | F42: 0
B43: Pricing adjustments implemented | C43: 0 | D43: 0 | E43: 0 | F43: 0
B44: New facility costs | C44: 0 | D44: 0 | E44: 0 | F44: 0
B45: Total Pro Forma | C45: =SUM(C41:C44) | D45: =SUM(D41:D44) | E45: =SUM(E41:E44) | F45: =SUM(F41:F44) | G45: =AVERAGE(C45:E45)
B47: LESS: DEDUCTIONS (Decrease EBITDA)
B48: Non-recurring revenue | C48: 0 | D48: 0 | E48: 0 | F48: 0
...

Sheet Adjustment Details
B2: DETAILED ADJUSTMENT DOCUMENTATION
B4: INSTRUCTIONS: Document each adjustment with supporting evidence and rationale
B6: ID | C6: Category | D6: Description | E6: Amount ($000s) | F6: Period | G6: Justification | H6: Source Document | I6: Approved By
B7: ADJ-001 | C7: Non-Recurring | D7: Litigation settlement | E7: 250 | F7: Year 2 | G7: One-time legal settlement for patent dispute. Not expected to recur. | H7: Legal invoice dated 3/15/2023 | I7: CFO
B8: ADJ-002 | C8: Owner Comp | D8: Excess owner compensation | E8: 150 | F8: TTM | G8: Owner salary $400K vs market rate $250K for CEO role. Adjustment = $150K. | H8: Payroll records; industry salary survey | I8: Management
B9: ADJ-003 | C9: Non-Recurring | D9: One-time consulting fees | E9: 75 | F9: Year 3 | G9: M&A advisory fees for potential acquisition that did not proceed. | H9: Consulting agreement + invoices | I9: CFO
B32: ADJUSTMENT CATEGORY SUMMARY
B33: Category | C33: Count | D33: Total Amount | E33: % of Total | F33: Avg per Item
B34: Non-Recurring
B35: Owner Compensation
B36: Owner Discretionary
B37: Normalization
B38: Accounting
B39: Pro Forma
B40: Deductions
B41: TOTAL

Sheet Revenue Analysis
B2: REVENUE QUALITY ANALYSIS
B4: REVENUE BY PRODUCT LINE
B5: Product Line | C5: Year 1 | D5: Year 2 | E5: Year 3 | F5: TTM | G5: Growth Rate
B6: Product A | G6: =IF(C6=0,0,(F6-C6)/C6/3)
B7: Product B | G7: =IF(C7=0,0,(F7-C7)/C7/3)
B8: Product C | G8: =IF(C8=0,0,(F8-C8)/C8/3)
B9: Service Revenue | G9: =IF(C9=0,0,(F9-C9)/C9/3)
B10: Recurring Revenue | G10: =IF(C10=0,0,(F10-C10)/C10/3)
B11: One-Time Revenue | G11: =IF(C11=0,0,(F11-C11)/C11/3)
B12: Total Revenue | C12: =SUM(C6:C11) | D12: =SUM(D6:D11) | E12: =SUM(E6:E11) | F12: =SUM(F6:F11) | G12: =IF(C12=0,0,(F12-C12)/C12/3)
B15: REVENUE MIX ANALYSIS
B16: Category | C16: Year 1 | D16: Year 2 | E16: Year 3 | F16: TTM
B17: Recurring Revenue % | C17: =IF(C12=0,0,C10/C12) | D17: =IF(D12=0,0,D10/D12) | E17: =IF(E12=0,0,E10/E12) | F17: =IF(F12=0,0,F10/F12)
B18: One-Time Revenue % | C18: =IF(C12=0,0,C11/C12) | D18: =IF(D12=0,0,D11/D12) | E18: =IF(E12=0,0,E11/E12) | F18: =IF(F12=0,0,F11/F12)
B19: Top Product % of Total | C19: =IF(C12=0,0,MAX(C6:C9)/C12) | D19: =IF(D12=0,0,MAX(D6:D9)/D12) | E19: =IF(E12=0,0,MAX(E6:E9)/E12) | F19: =IF(F12=0,0,MAX(F6:F9)/F12)
B20: Contract-Based Revenue %
B21: Spot Sales %
B24: REVENUE QUALITY METRICS
B25: Revenue Growth Rate (CAGR) | C25: =0 | D25: =IF(C12=0,0,(D12-C12)/C12) | E25: =IF(D12=0,0,(E12-D12)/D12) | F25: =IF(E12=0,0,(F12-E12)/E12)
B26: Organic Growth Rate
B27: Acquisition Growth
B28: Revenue Volatility (Std Dev)
B29: Revenue Predictability Score
B32: REVENUE RECOGNITION REVIEW
B33: Revenue Recognition Policy | C33: GAAP Compliant
B34: Deferred Revenue Balance | C34: =INPUT
B35: Unbilled Revenue | C35: =INPUT
B36: Contract Liabilities | C36: =INPUT
B37: ASC 606 Compliance | C37: Yes/No
B38: Revenue Timing Issues | C38: None Identified

Sheet Customer Concentration
B2: CUSTOMER CONCENTRATION ANALYSIS
B4: TOP 10 CUSTOMERS
B5: Rank | C5: Customer | D5: Revenue ($000s) | E5: % of Total | F5: Years as Customer | G5: Contract Status | H5: Risk Level
B6: 1 | C6: Customer 1 | D6: 0 | E6: =IF(SUM($D$6:$D$15)=0,0,D6/SUM($D$6:$D$15)) | G6: Multi-year contract | H6: Low
B7: 2 | C7: Customer 2 | D7: 0 | E7: =IF(SUM($D$6:$D$15)=0,0,D7/SUM($D$6:$D$15)) | G7: Multi-year contract | H7: Low
B8: 3 | C8: Customer 3 | D8: 0 | E8: =IF(SUM($D$6:$D$15)=0,0,D8/SUM($D$6:$D$15)) | G8: Multi-year contract | H8: Low
B9: 4 | C9: Customer 4 | D9: 0 | E9: =IF(SUM($D$6:$D$15)=0,0,D9/SUM($D$6:$D$15)) | G9: Multi-year contract | H9: Low
B10: 5 | C10: Customer 5 | D10: 0 | E10: =IF(SUM($D$6:$D$15)=0,0,D10/SUM($D$6:$D$15)) | G10: Multi-year contract | H10: Low
B11: 6 | C11: Customer 6 | D11: 0 | E11: =IF(SUM($D$6:$D$15)=0,0,D11/SUM($D$6:$D$15)) | G11: Multi-year contract | H11: Low
B12: 7 | C12: Customer 7 | D12: 0 | E12: =IF(SUM($D$6:$D$15)=0,0,D12/SUM($D$6:$D$15)) | G12: Multi-year contract | H12: Low
B13: 8 | C13: Customer 8 | D13: 0 | E13: =IF(SUM($D$6:$D$15)=0,0,D13/SUM($D$6:$D$15)) | G13: Multi-year contract | H13: Low
B14: 9 | C14: Customer 9 | D14: 0 | E14: =IF(SUM($D$6:$D$15)=0,0,D14/SUM($D$6:$D$15)) | G14: Multi-year contract | H14: Low
B15: 10 | C15: Customer 10 | D15: 0 | E15: =IF(SUM($D$6:$D$15)=0,0,D15/SUM($D$6:$D$15)) | G15: Multi-year contract | H15: Low
B17: CONCENTRATION METRICS
B18: Top 1 Customer % of Revenue | C18: =E6
B19: Top 3 Customers % of Revenue | C19: =SUM(E6:E8)
B20: Top 5 Customers % of Revenue | C20: =SUM(E6:E10)
B21: Top 10 Customers % of Revenue | C21: =SUM(E6:E15)
B22: Herfindahl-Hirschman Index (HHI) | C22: =SUMPRODUCT(E6:E15,E6:E15)*10000
B23: Customer Concentration Risk
B26: CUSTOMER RISK ASSESSMENT
B27: Risk Factor | C27: Score (1-5) | D27: Weight | E27: Weighted Score | F27: Comments
B28: Customer concentration level | C28: 3 | D28: 0.2 | E28: =C28*D28
B29: Contract length & stability | C29: 3 | D29: 0.2 | E29: =C29*D29
B30: Payment terms & history | C30: 3 | D30: 0.2 | E30: =C30*D30
B31: Industry concentration | C31: 3 | D31: 0.2 | E31: =C31*D31
B32: Geographic concentration | C32: 3 | D32: 0.2 | E32: =C32*D32
B33: TOTAL RISK SCORE | E33: =SUM(E28:E32)

Sheet Working Capital
B2: WORKING CAPITAL ANALYSIS
B4: HISTORICAL NET WORKING CAPITAL
B5: Component | C5: Year 1 | D5: Year 2 | E5: Year 3 | F5: TTM | G5: % of Revenue
B6: Current Assets
B7: Cash & Cash Equivalents | G7: =IF("Reported Financials"!F12=0,0,F7/"Reported Financials"!F12)
B8: Accounts Receivable | G8: =IF("Reported Financials"!F12=0,0,F8/"Reported Financials"!F12)
B9: Inventory | G9: =IF("Reported Financials"!F12=0,0,F9/"Reported Financials"!F12)
B10: Prepaid Expenses | G10: =IF("Reported Financials"!F12=0,0,F10/"Reported Financials"!F12)
B11: Other Current Assets | G11: =IF("Reported Financials"!F12=0,0,F11/"Reported Financials"!F12)
B12: Total Current Assets | C12: =SUM(C7:C11) | D12: =SUM(D7:D11) | E12: =SUM(E7:E11) | F12: =SUM(F7:F11) | G12: =IF("Reported Financials"!F12=0,0,F12/"Reported Financials"!F12)
B14: Current Liabilities
B15: Accounts Payable | G15: =IF("Reported Financials"!F12=0,0,F15/"Reported Financials"!F12)
B16: Accrued Expenses | G16: =IF("Reported Financials"!F12=0,0,F16/"Reported Financials"!F12)
B17: Deferred Revenue | G17: =IF("Reported Financials"!F12=0,0,F17/"Reported Financials"!F12)
B18: Other Current Liabilities | G18: =IF("Reported Financials"!F12=0,0,F18/"Reported Financials"!F12)
B19: Total Current Liabilities | C19: =SUM(C15:C18) | D19: =SUM(D15:D18) | E19: =SUM(E15:E18) | F19: =SUM(F15:F18) | G19: =IF("Reported Financials"!F12=0,0,F19/"Reported Financials"!F12)
B21: Net Working Capital (NWC) | C21: =C12-C19 | D21: =D12-D19 | E21: =E12-E19 | F21: =F12-F19 | G21: =IF("Reported Financials"!F12=0,0,F21/"Reported Financials"!F12)
B22: NWC excluding Cash | C22: =C21-C7 | D22: =D21-D7 | E22: =E21-E7 | F22: =F21-F7 | G22: =IF("Reported Financials"!F12=0,0,F22/"Reported Financials"!F12)
B23: NWC as % of Revenue | C23: =IF("Reported Financials"!C12=0,0,C22/"Reported Financials"!C12) | D23: =IF("Reported Financials"!D12=0,0,D22/"Reported Financials"!D12) | E23: =IF("Reported Financials"!E12=0,0,E22/"Reported Financials"!E12) | F23: =IF("Reported Financials"!F12=0,0,F22/"Reported Financials"!F12) | G23: =IF("Reported Financials"!F12=0,0,F23/"Reported Financials"!F12)
B24: WORKING CAPITAL DAYS ANALYSIS
B25: Metric | C25: Year 1 | D25: Year 2 | E25: Year 3 | F25: TTM
B26: Days Sales Outstanding (DSO) | C26: =IF("Reported Financials"!C12=0,0,(C8/"Reported Financials"!C12)*365) | D26: =IF("Reported Financials"!D12=0,0,(D8/"Reported Financials"!D12)*365) | E26: =IF("Reported Financials"!E12=0,0,(E8/"Reported Financials"!E12)*365) | F26: =IF("Reported Financials"!F12=0,0,(F8/"Reported Financials"!F12)*365)
B27: Days Inventory Outstanding (DIO) | C27: =IF("Reported Financials"!C18=0,0,(C9/"Reported Financials"!C18)*365) | D27: =IF("Reported Financials"!D18=0,0,(D9/"Reported Financials"!D18)*365) | E27: =IF("Reported Financials"!E18=0,0,(E9/"Reported Financials"!E18)*365) | F27: =IF("Reported Financials"!F18=0,0,(F9/"Reported Financials"!F18)*365)
B28: Days Payable Outstanding (DPO) | C28: =IF("Reported Financials"!C18=0,0,(C15/"Reported Financials"!C18)*365) | D28: =IF("Reported Financials"!D18=0,0,(D15/"Reported Financials"!D18)*365) | E28: =IF("Reported Financials"!E18=0,0,(E15/"Reported Financials"!E18)*365) | F28: =IF("Reported Financials"!F18=0,0,(F15/"Reported Financials"!F18)*365)
B29: Cash Conversion Cycle (CCC) | C29: =C26+C27-C28 | D29: =D26+D27-D28 | E29: =E26+E27-E28 | F29: =F26+F27-F28
B31: NET WORKING CAPITAL TARGET
B32: Calculation Method | C32: Trailing 12-Month Average
B33: Historical NWC Average | C33: =AVERAGE(C22:F22)
B34: Seasonal Adjustment | C34: =INPUT
B35: Growth Adjustment | C35: =INPUT
B36: Target NWC for Transaction | C36: =FORMULA
B37: Target NWC as % of Revenue | C37: =C33+C34+C35
C38: =IF("Reported Financials"!F12=0,0,C37/"Reported Financials"!F12)

Sheet Proof of Cash
B2: PROOF OF CASH ANALYSIS
B4: PURPOSE: Reconcile reported earnings to actual cash transactions
B6: CASH RECONCILIATION - TTM
B7: Beginning Cash Balance (per books) | C7: 0
B9: Add: Cash Receipts
B10: Cash from customers | C10: 0
B11: Interest received | C11: 0
B12: Other cash receipts | C12: 0
B13: Total Cash Receipts | C13: =SUM(C10:C12)
B15: Less: Cash Disbursements
B16: Payments to suppliers | C16: 0
B17: Employee compensation | C17: 0
B18: Operating expenses paid | C18: 0
B19: Interest paid | C19: 0
B20: Taxes paid | C20: 0
B21: Other cash payments | C21: 0
B22: Total Cash Disbursements | C22: =SUM(C16:C21)
B24: Net Cash from Operations | C24: =C13-C22
B26: Ending Cash Balance (per books) | C26: =C7+C24
B27: Ending Cash Balance (per bank) | C27: 0
B28: Difference (Reconciliation) | C28: =C26-C27
B30: REVENUE TO CASH COLLECTIONS
B31: Reported Revenue
B32: Add: Beginning AR Balance | C32: 0
B33: Less: Ending AR Balance | C33: 0
B34: Cash Collections (calculated)
B35: Cash Collections (per bank) | C35: =C32+C33-C34
B36: Variance
B37: Variance % | C37: =C35-C36
C38: =IF(C36=0,0,C37/C36)
B39: EBITDA TO OPERATING CASH FLOW
B40: Adjusted EBITDA
B42: Less: Cash Taxes Paid | C42: 0
B43: Add/Less: Change in NWC | C43: 0
B44: Less: CapEx (maintenance) | C44: 0
B46: Free Cash Flow
B47: FCF / EBITDA Conversion %
C48: ="EBITDA Bridge"!F55-C44-C45-C46
B49: Operating Cash Flow (per stmt) | C49: =IF("EBITDA Bridge"!F55=0,0,C48/"EBITDA Bridge"!F55)
B50: Calculated Operating Cash Flow
...

Sheet Integration with Models
B2: INTEGRATION WITH FINANCIAL MODELS
B4: INSTRUCTIONS: Link QoE findings to DCF, LBO, and Merger models
B6: KEY QOE OUTPUTS FOR MODEL INTEGRATION
B7: QoE Output | C7: Value | D7: Link to QoE | E7: Usage in Models
B8: Adjusted EBITDA (TTM) | C8: =EBITDA Bridge!F56 | D8: =EBITDA Bridge!F56 | E8: Use in all models
B9: Adjusted EBITDA Margin % | C9: =EBITDA Bridge!F57 | D9: =EBITDA Bridge!F57 | E9: For margin assumptions
B10: Revenue (TTM) | C10: =Reported Financials!F12 | D10: =Reported Financials!F12 | E10: Base for projections
B11: Revenue Growth Rate | C11: =Revenue Analysis!C25 | D11: =Revenue Analysis!C25 | E11: Growth assumptions
B12: Target Net Working Capital | C12: =Working Capital!C40 | D12: =Working Capital!C40 | E12: For NWC peg
B13: Customer Concentration Risk | C13: =Customer Concentration!C23 | D13: =Customer Concentration!C23 | E13: Risk adjustment
B14: FCF Conversion Rate | C14: =Proof of Cash!C48 | D14: =Proof of Cash!C48 | E14: Cash generation
B16: DCF MODEL ADJUSTMENTS
B17: Finding | C17: Impact | D17: DCF Adjustment | E17: Value Impact ($mm)
B18: Adjusted EBITDA vs Reported | C18: Higher sustainable earnings | D18: Increase base EBITDA | E18: 0
B19: Revenue growth quality | C19: Predictable growth | D19: Adjust growth rate | E19: 0
B20: Customer concentration | C20: Revenue risk | D20: Increase discount rate | E20: 0
B21: Working capital needs | C21: Cash requirements | D21: Update NWC assumptions | E21: 0
B23: LBO MODEL ADJUSTMENTS
B24: Finding | C24: Impact | D24: LBO Adjustment | E24: IRR Impact
B25: Adjusted EBITDA | C25: Entry multiple basis | D25: Update entry EBITDA | E25: 0
B26: FCF conversion | C26: Debt paydown capacity | D26: Adjust cash sweep | E26: 0
B27: CapEx requirements | C27: Cash available | D27: Update CapEx assumptions | E27: 0
B28: Working capital target | C28: Sources & Uses | D28: Update NWC in S&U | E28: 0
B30: MERGER MODEL ADJUSTMENTS
B31: Finding | C31: Impact | D31: Merger Adjustment | E31: EPS Impact
B32: Adjusted EBITDA | C32: Pro forma earnings | D32: Update target EBITDA | E32: 0
B33: Revenue synergies | C33: Combined revenue | D33: Adjust synergy estimates | E33: 0
B34: Cost structure | C34: Cost synergies | D34: Update cost savings | E34: 0
B35: Working capital | C35: Combined balance sheet | D35: Adjust NWC target | E35: 0

Sheet Key Findings
B2: QUALITY OF EARNINGS - KEY FINDINGS & RECOMMENDATIONS
B4: EXECUTIVE SUMMARY
B5: Overall Assessment: [HIGH / MEDIUM / LOW] Quality of Earnings
B7: Key Takeaways:
B8: • Adjusted EBITDA is $XX million higher/lower than reported
B9: • Revenue quality is strong with diversified customer base
B10: • Cash generation is consistent with reported earnings
B11: • Working capital requirements are well-documented
B13: Recommendation: [PROCEED / PROCEED WITH CAUTION / DO NOT PROCEED]
B16: POSITIVE FINDINGS
B17: ✓ Strong historical revenue growth (X% CAGR)
B18: ✓ High quality recurring revenue (X% of total)
... B34: RECOMMENDATIONS
B35: Area | C35: Recommendation | D35: Priority
B36: Valuation | C36: Use Adjusted EBITDA of $XX million for valuation | D36: High
B37: Purchase Price | C37: Adjust offer price down by X% due to findings | D37: High
B38: Deal Structure | C38: Include working capital peg mechanism | D38: High
B39: Due Diligence | C39: Deep dive on top 3 customers | D39: Medium
B40: Integration | C40: Budget $XX for deferred maintenance in Year 1 | D40: Medium
B41: Monitoring | C41: Track customer concentration post-close | D41: Low
