Workbook

Sheet Executive Summary
A1: MIXED-USE DEVELOPMENT FINANCIAL MODEL
A2: Executive Summary Dashboard
A4: PROPERTY OVERVIEW
A5: Property Name: | B5: =Inputs!B5
A6: Total Building SF: | B6: =Inputs!B9
A7: Total Development Cost: | B7: =Inputs!B130
A8: Location:
A9: Number of Floors:
A10: Cost per SF:
A11: Asset Class:
A12: Hold Period (Years):
A13: Entry Cap Rate:
A14: Development Start:
A15: Stabilization Year:
A16: Exit Cap Rate:

Sheet Inputs
A1: MIXED-USE MODEL - INPUTS & ASSUMPTIONS
A2: Change BLUE cells only. Yellow highlights indicate key assumptions.
A4: PROPERTY INFORMATION
A5: Property Name | B5: Metropolitan Mixed-Use Tower
A6: Address | B6: 123 Main Street
A7: City, State | B7: Downtown, CA
A8: Total Building Gross SF | B8: 500000
A9: Number of Floors | B9: 40
A10: Average Floor Plate (SF) | B10: 12500
A11: Parking Spaces | B11: 400
A12: Asset Class (A/B/C) | B12: A
A14: SPACE ALLOCATION BY USE
A15: Property Type | B15: % of Total SF | C15: Allocated SF | D15: Avg Floor Count
A16: Multifamily (Apartments) | B16: 0.4 | C16: =B9*B16 | D16: Floors 21-40
A17: Office | B17: 0.25 | C17: =B9*B17 | D17: Floors 11-20
A18: Retail | B18: 0.15 | C18: =B9*B18 | D18: Floors 1-3
A19: Hotel | B19: 0.15 | C19: =B9*B19 | D19: Floors 4-10
A20: Restaurant / F&B | B20: 0.05 | C20: =B9*B20 | D20: Ground Floor
A21: TOTAL ALLOCATION | B21: =SUM(B16:B20) | C21: =SUM(C16:C20)
A23: MULTIFAMILY ASSUMPTIONS
A24: Total Units (calculated) | B24: =C16/850 | D24: Avg 850 SF/unit
A25: Average Unit Size (SF) | B25: 850
A26: Average Rent per Unit (Monthly) | B26: 3500
A27: Physical Occupancy Target | B27: 0.96
A28: Rent Growth (Annual) | B28: 0.035
A29: Concessions | B29: 0.02
A30: Bad Debt | B30: 0.005
A31: Other Income per Unit (Monthly) | B31: 150 | D31: Parking, storage, pets
A32: OpEx per Unit (Monthly) | B32: 650
A33: OpEx Growth (Annual) | B33: 0.03
A35: OFFICE ASSUMPTIONS
A36: Rentable SF (RSF) | B36: =C17
A37: Load Factor | B37: 1.2 | D37: 20% common area
A38: Usable SF (USF) | B38: =B35/B36
A39: Average Rent per SF (Annual) | B39: 45
A40: Economic Occupancy | B40: 0.95
A41: Rent Growth (Annual) | B41: 0.03
A42: Expense Recovery Rate | B42: 0.98
A43: OpEx per SF (Annual) | B43: 15
A44: OpEx Growth (Annual) | B44: 0.025
...

Sheet Allocation Scenarios
A1: ALLOCATION SCENARIO COMPARISON
A2: Compare 8 different space allocation strategies to optimize returns
A4: Scenario | B4: Multifamily % | C4: Office % | D4: Retail % | E4: Hotel % | F4: Restaurant % | G4: Blended NOI | H4: Levered IRR | I4: Equity Multiple | J4: Cash-on-Cash Y1 | K4: Best For
A5: Base Case (Balanced) | B5: 0.4 | C5: 0.25 | D5: 0.15 | E5: 0.15 | F5: 0.05 | G5: =0 | H5: =0 | I5: =0 | J5: =0 | K5: Diversified risk
A6: Multifamily Focus | B6: 0.7 | C6: 0.15 | D6: 0.1 | E6: 0 | F6: 0.05 | G6: =0 | H6: =0 | I6: =0 | J6: =0 | K6: Residential market
A7: Office Tower | B7: 0.2 | C7: 0.6 | D7: 0.1 | E7: 0.05 | F7: 0.05 | G7: =0 | H7: =0 | I7: =0 | J7: =0 | K7: CBD location
A8: Retail Emphasis | B8: 0.3 | C8: 0.15 | D8: 0.4 | E8: 0.1 | F8: 0.05 | G8: =0 | H8: =0 | I8: =0 | J8: =0 | K8: High-traffic area
A9: Hospitality Driven | B9: 0.15 | C9: 0.2 | D9: 0.15 | E9: 0.45 | F9: 0.05 | G9: =0 | H9: =0 | I9: =0 | J9: =0 | K9: Tourism/Convention
A10: Luxury Mixed-Use | B10: 0.35 | C10: 0.2 | D10: 0.15 | E10: 0.2 | F10: 0.1 | G10: =0 | H10: =0 | I10: =0 | J10: =0 | K10: Affluent market
A11: Value-Add Play | B11: 0.5 | C11: 0.3 | D11: 0.1 | E11: 0.05 | F11: 0.05 | G11: =0 | H11: =0 | I11: =0 | J11: =0 | K11: Lease-up strategy
A12: Conservative Income | B12: 0.3 | C12: 0.3 | D12: 0.2 | E12: 0.15 | F12: 0.05 | G12: =0 | H12: =0 | I12: =0 | J12: =0 | K12: Stable cash flow
A15: ALLOCATION OPTIMIZER
A16: Adjust allocations below to test custom scenarios:
A17: Property Type | B17: Custom % | C17: Allocated SF | D17: Est. NOI/SF | E17: Total NOI | F17: IRR Impact
A18: Multifamily | B18: 0.2 | C18: =Inputs!$B$9*B18 | D18: 0 | E18: =C18*D18 | F18: =0%
A19: Office | B19: 0.2 | C19: =Inputs!$B$9*B19 | D19: 0 | E19: =C19*D19 | F19: =0%
A20: Retail | B20: 0.2 | C20: =Inputs!$B$9*B20 | D20: 0 | E20: =C20*D20 | F20: =0%
A21: Hotel | B21: 0.2 | C21: =Inputs!$B$9*B21 | D21: 0 | E21: =C21*D21 | F21: =0%
A22: Restaurant/F&B | B22: 0.2 | C22: =Inputs!$B$9*B22 | D22: 0 | E22: =C22*D22 | F22: =0%
A23: TOTAL | B23: =SUM(B18:B22) | C23: =SUM(C18:C22) | E23: =SUM(E18:E22)

Sheet Multifamily Component

Sheet Office Component

Sheet Retail Component
A1: RETAIL COMPONENT ANALYSIS
A3: KEY METRICS
A4: Total Retail SF | B4: =Inputs!B56
A5: Avg Rent/SF | B5: =Inputs!B57
A6: Economic Occupancy | B6: =Inputs!B58
A7: Sales/SF | B7: =Inputs!B60
A10: Line Item | B10: Y1 | C10: Y2 | D10: Y3 | E10: Y4 | F10: Y5 | G10: Y6 | H10: Y7 | I10: Y8 | J10: Y9 | K10: Y10
A11: Base Rent | B11: 0
A12: Percentage Rent | B12: 0
A13: CAM Charges | B13: 0
A14: Total Revenue | B14: 0
A16: Operating Expenses | B16: 0
A17: Net Operating Income | B17: 0

Sheet Hotel Component
A1: HOTEL COMPONENT ANALYSIS
A3: KEY METRICS
A4: Total Hotel SF | B4: =Inputs!B65
A5: Number of Rooms | B5: =Inputs!B66
A6: ADR (Avg Daily Rate) | B6: =Inputs!B67
A7: Occupancy Rate | B7: =Inputs!B68
A10: Line Item | B10: Y1 | C10: Y2 | D10: Y3 | E10: Y4 | F10: Y5 | G10: Y6 | H10: Y7 | I10: Y8 | J10: Y9 | K10: Y10
A11: Room Revenue | B11: 0
A12: F&B Revenue | B12: 0
A13: Other Revenue | B13: 0
A14: Total Revenue | B14: 0
A16: Operating Expenses | B16: 0
A17: Management Fee | B17: 0
A18: Total Expenses | B18: 0
A20: Net Operating Income | B20: 0

Sheet Restaurant Component
A1: RESTAURANT / F&B COMPONENT ANALYSIS
A3: KEY METRICS
A4: Total F&B SF | B4: =Inputs!B77
A5: Base Rent/SF | B5: =Inputs!B78
A6: Sales/SF | B6: =Inputs!B80
A7: Economic Occupancy | B7: =Inputs!B81
A10: Line Item | B10: Y1 | C10: Y2 | D10: Y3 | E10: Y4 | F10: Y5 | G10: Y6 | H10: Y7 | I10: Y8 | J10: Y9 | K10: Y10
A11: Base Rent | B11: 0
A12: Percentage Rent | B12: 0
A13: Total Revenue | B13: 0
A15: Operating Expenses | B15: 0
A16: Net Operating Income | B16: 0

Sheet Consolidated Pro Forma
A1: CONSOLIDATED PRO FORMA - ALL COMPONENTS
A2: Aggregated revenue and expenses across all property types
A4: Property Type | B4: Year 1 | C4: Year 2 | D4: Year 3 | E4: Year 4 | F4: Year 5 | G4: Year 6 | H4: Year 7 | I4: Year 8 | J4: Year 9 | K4: Year 10
A5: Multifamily Revenue | B5: 0 | C5: 0 | D5: 0 | E5: 0 | F5: 0 | G5: 0 | H5: 0 | I5: 0 | J5: 0 | K5: 0
A6: Office Revenue | B6: 0 | C6: 0 | D6: 0 | E6: 0 | F6: 0 | G6: 0 | H6: 0 | I6: 0 | J6: 0 | K6: 0
A7: Retail Revenue | B7: 0 | C7: 0 | D7: 0 | E7: 0 | F7: 0 | G7: 0 | H7: 0 | I7: 0 | J7: 0 | K7: 0
A8: Hotel Revenue | B8: 0 | C8: 0 | D8: 0 | E8: 0 | F8: 0 | G8: 0 | H8: 0 | I8: 0 | J8: 0 | K8: 0
A9: Restaurant Revenue | B9: 0 | C9: 0 | D9: 0 | E9: 0 | F9: 0 | G9: 0 | H9: 0 | I9: 0 | J9: 0 | K9: 0
A10: TOTAL REVENUE | B10: 0 | C10: 0 | D10: 0 | E10: 0 | F10: 0 | G10: 0 | H10: 0 | I10: 0 | J10: 0 | K10: 0
A12: Multifamily OpEx | B12: 0 | C12: 0 | D12: 0 | E12: 0 | F12: 0 | G12: 0 | H12: 0 | I12: 0 | J12: 0 | K12: 0
A13: Office OpEx | B13: 0 | C13: 0 | D13: 0 | E13: 0 | F13: 0 | G13: 0 | H13: 0 | I13: 0 | J13: 0 | K13: 0
A14: Retail OpEx | B14: 0 | C14: 0 | D14: 0 | E14: 0 | F14: 0 | G14: 0 | H14: 0 | I14: 0 | J14: 0 | K14: 0
A15: Hotel OpEx | B15: 0 | C15: 0 | D15: 0 | E15: 0 | F15: 0 | G15: 0 | H15: 0 | I15: 0 | J15: 0 | K15: 0
A16: Restaurant OpEx | B16: 0 | C16: 0 | D16: 0 | E16: 0 | F16: 0 | G16: 0 | H16: 0 | I16: 0 | J16: 0 | K16: 0
A17: TOTAL OPERATING EXPENSES | B17: 0 | C17: 0 | D17: 0 | E17: 0 | F17: 0 | G17: 0 | H17: 0 | I17: 0 | J17: 0 | K17: 0
... A20: NOI Margin % | B20: 0 | C20: 0 | D20: 0 | E20: 0 | F20: 0 | G20: 0 | H20: 0 | I20: 0 | J20: 0 | K20: 0

Sheet Cash Flow Analysis
A1: INVESTMENT CASH FLOW ANALYSIS
A4: Item | B4: Year 0 | C4: Year 1 | D4: Year 2 | E4: Year 3 | F4: Year 4 | G4: Year 5 | H4: Year 6 | I4: Year 7 | J4: Year 8 | K4: Year 9 | L4: Year 10
A5: Sources of Funds
A6: Equity Investment | B6: 0 | C6: 0 | D6: 0 | E6: 0 | F6: 0 | G6: 0 | H6: 0 | I6: 0 | J6: 0 | K6: 0 | L6: 0
A7: Debt Proceeds | B7: 0 | C7: 0 | D7: 0 | E7: 0 | F7: 0 | G7: 0 | H7: 0 | I7: 0 | J7: 0 | K7: 0 | L7: 0
A8: Total Sources | B8: 0 | C8: 0 | D8: 0 | E8: 0 | F8: 0 | G8: 0 | H8: 0 | I8: 0 | J8: 0 | K8: 0 | L8: 0
A10: Uses of Funds
A11: Land Acquisition | B11: 0 | C11: 0 | D11: 0 | E11: 0 | F11: 0 | G11: 0 | H11: 0 | I11: 0 | J11: 0 | K11: 0 | L11: 0
A12: Hard Costs | B12: 0 | C12: 0 | D12: 0 | E12: 0 | F12: 0 | G12: 0 | H12: 0 | I12: 0 | J12: 0 | K12: 0 | L12: 0
A13: Soft Costs | B13: 0 | C13: 0 | D13: 0 | E13: 0 | F13: 0 | G13: 0 | H13: 0 | I13: 0 | J13: 0 | K13: 0 | L13: 0
A14: FF&E | B14: 0 | C14: 0 | D14: 0 | E14: 0 | F14: 0 | G14: 0 | H14: 0 | I14: 0 | J14: 0 | K14: 0 | L14: 0
A15: Developer Fee | B15: 0 | C15: 0 | D15: 0 | E15: 0 | F15: 0 | G15: 0 | H15: 0 | I15: 0 | J15: 0 | K15: 0 | L15: 0
A16: Financing Fees | B16: 0 | C16: 0 | D16: 0 | E16: 0 | F16: 0 | G16: 0 | H16: 0 | I16: 0 | J16: 0 | K16: 0 | L16: 0
A17: Total Uses | B17: 0 | C17: 0 | D17: 0 | E17: 0 | F17: 0 | G17: 0 | H17: 0 | I17: 0 | J17: 0 | K17: 0 | L17: 0
A19: Operating Cash Flow
A20: Net Operating Income | B20: 0 | C20: 0 | D20: 0 | E20: 0 | F20: 0 | G20: 0 | H20: 0 | I20: 0 | J20: 0 | K20: 0 | L20: 0
A21: Debt Service | B21: 0 | C21: 0 | D21: 0 | E21: 0 | F21: 0 | G21: 0 | H21: 0 | I21: 0 | J21: 0 | K21: 0 | L21: 0
A22: Before-Tax Cash Flow | B22: 0 | C22: 0 | D22: 0 | E22: 0 | F22: 0 | G22: 0 | H22: 0 | I22: 0 | J22: 0 | K22: 0 | L22: 0
A24: Reversion (Exit)
A25: Sale Proceeds | B25: 0 | C25: 0 | D25: 0 | E25: 0 | F25: 0 | G25: 0 | H25: 0 | I25: 0 | J25: 0 | K25: 0 | L25: 0
A26: Loan Payoff | B26: 0 | C26: 0 | D26: 0 | E26: 0 | F26: 0 | G26: 0 | H26: 0 | I26: 0 | J26: 0 | K26: 0 | L26: 0
A27: Selling Costs | B27: 0 | C27: 0 | D27: 0 | E27: 0 | F27: 0 | G27: 0 | H27: 0 | I27: 0 | J27: 0 | K27: 0 | L27: 0
A28: Net Sale Proceeds | B28: 0 | C28: 0 | D28: 0 | E28: 0 | F28: 0 | G28: 0 | H28: 0 | I28: 0 | J28: 0 | K28: 0 | L28: 0
A30: TOTAL CASH FLOW | B30: 0 | C30: 0 | D30: 0 | E30: 0 | F30: 0 | G30: 0 | H30: 0 | I30: 0 | J30: 0 | K30: 0 | L30: 0

Sheet Returns Analysis
A1: RETURNS & PERFORMANCE METRICS
A3: KEY INVESTMENT RETURNS
A4: Levered IRR | B4: 0
A5: Unlevered IRR | B5: 0
A6: Equity Multiple (MOIC) | B6: 0
A7: Average Cash-on-Cash | B7: 0
A8: Total Equity Invested | B8: 0
A9: Total Cash Returned | B9: 0
A10: Net Profit | B10: 0
A13: RETURNS BY COMPONENT
A14: Component | B14: Stabilized NOI | C14: Exit Value | D14: Cap Rate | E14: IRR Contribution
A15: Multifamily | B15: 0 | C15: 0 | D15: 0 | E15: 0
A16: Office | B16: 0 | C16: 0 | D16: 0 | E16: 0
A17: Retail | B17: 0 | C17: 0 | D17: 0 | E17: 0
A18: Hotel | B18: 0 | C18: 0 | D18: 0 | E18: 0
A19: Restaurant | B19: 0 | C19: 0 | D19: 0 | E19: 0
A20: TOTAL | B20: 0 | C20: 0 | D20: 0 | E20: 0

Sheet Sensitivity Analysis
A1: SENSITIVITY ANALYSIS
A3: LEVERED IRR SENSITIVITY
A5: Exit Cap Rate → | B5: 0.045 | C5: 0.05 | D5: 0.055 | E5: 0.06 | F5: 0.065 | G5: 0.07 | H5: 0.075 | I5: 0.08 | J5: 0.085 | K5: 0.09
A6: Dev Cost/SF ↓
A7: 375 | B7: 0.15 | C7: 0.15 | D7: 0.15 | E7: 0.15 | F7: 0.15 | G7: 0.15 | H7: 0.15 | I7: 0.15 | J7: 0.15 | K7: 0.15
A8: 400 | B8: 0.15 | C8: 0.15 | D8: 0.15 | E8: 0.15 | F8: 0.15 | G8: 0.15 | H8: 0.15 | I8: 0.15 | J8: 0.15 | K8: 0.15
A9: 425 | B9: 0.15 | C9: 0.15 | D9: 0.15 | E9: 0.15 | F9: 0.15 | G9: 0.15 | H9: 0.15 | I9: 0.15 | J9: 0.15 | K9: 0.15
A10: 450 | B10: 0.15 | C10: 0.15 | D10: 0.15 | E10: 0.15 | F10: 0.15 | G10: 0.15 | H10: 0.15 | I10: 0.15 | J10: 0.15 | K10: 0.15
A11: 475 | B11: 0.15 | C11: 0.15 | D11: 0.15 | E11: 0.15 | F11: 0.15 | G11: 0.15 | H11: 0.15 | I11: 0.15 | J11: 0.15 | K11: 0.15
A12: 500 | B12: 0.15 | C12: 0.15 | D12: 0.15 | E12: 0.15 | F12: 0.15 | G12: 0.15 | H12: 0.15 | I12: 0.15 | J12: 0.15 | K12: 0.15
A13: 525 | B13: 0.15 | C13: 0.15 | D13: 0.15 | E13: 0.15 | F13: 0.15 | G13: 0.15 | H13: 0.15 | I13: 0.15 | J13: 0.15 | K13: 0.15
A14: 550 | B14: 0.15 | C14: 0.15 | D14: 0.15 | E14: 0.15 | F14: 0.15 | G14: 0.15 | H14: 0.15 | I14: 0.15 | J14: 0.15 | K14: 0.15
A17: IRR BY ALLOCATION MIX
A18: Scenario | B18: MF % | C18: Office % | D18: Retail % | E18: Hotel % | F18: IRR
A19: ='Allocation Scenarios'!A6 | B19: ='Allocation Scenarios'!B6 | C19: ='Allocation Scenarios'!C6 | D19: ='Allocation Scenarios'!D6 | E19: ='Allocation Scenarios'!E6 | F19: ='Allocation Scenarios'!H6
A20: ='Allocation Scenarios'!A7 | B20: ='Allocation Scenarios'!B7 | C20: ='Allocation Scenarios'!C7 | D20: ='Allocation Scenarios'!D7 | E20: ='Allocation Scenarios'!E7 | F20: ='Allocation Scenarios'!H7
A21: ='Allocation Scenarios'!A8 | B21: ='Allocation Scenarios'!B8 | C21: ='Allocation Scenarios'!C8 | D21: ='Allocation Scenarios'!D8 | E21: ='Allocation Scenarios'!E8 | F21: ='Allocation Scenarios'!H8
A22: ='Allocation Scenarios'!A9 | B22: ='Allocation Scenarios'!B9 | C22: ='Allocation Scenarios'!C9 | D22: ='Allocation Scenarios'!D9 | E22: ='Allocation Scenarios'!E9 | F22: ='Allocation Scenarios'!H9
A23: ='Allocation Scenarios'!A10 | B23: ='Allocation Scenarios'!B10 | C23: ='Allocation Scenarios'!C10 | D23: ='Allocation Scenarios'!D10 | E23: ='Allocation Scenarios'!E10 | F23: ='Allocation Scenarios'!H10
A24: ='Allocation Scenarios'!A11 | B24: ='Allocation Scenarios'!B11 | C24: ='Allocation Scenarios'!C11 | D24: ='Allocation Scenarios'!D11 | E24: ='Allocation Scenarios'!E11 | F24: ='Allocation Scenarios'!H11
A25: ='Allocation Scenarios'!A12 | B25: ='Allocation Scenarios'!B12 | C25: ='Allocation Scenarios'!C12 | D25: ='Allocation Scenarios'!D12 | E25: ='Allocation Scenarios'!E12 | F25: ='Allocation Scenarios'!H12
A26: ='Allocation Scenarios'!A13 | B26: ='Allocation Scenarios'!B13 | C26: ='Allocation Scenarios'!C13 | D26: ='Allocation Scenarios'!D13 | E26: ='Allocation Scenarios'!E13 | F26: ='Allocation Scenarios'!H13
