Workbook

Sheet Executive Summary
A1: DUPLEX SUBDIVISION ANALYSIS
A3: PROPERTY INFORMATION
A4: Address: | B4: =Inputs!B3
A5: Property Type: | B5: Duplex (2 Units)
A6: Total Square Feet: | B6: =Inputs!B6
A7: Unit 1 Size: | B7: =Inputs!B7
A8: Unit 2 Size: | B8: =Inputs!B8
A9: Year Built: | B9: =Inputs!B9
A10: Current Status: | B10: =Inputs!B10
A12: KEY DEAL METRICS
A13: Purchase Price: | B13: =Inputs!B13
A14: Down Payment (%): | B14: =Inputs!B14
A15: Cash Required: | B15: =Inputs!B13*Inputs!B14
A16: Loan Amount: | B16: =Inputs!B13*(1-Inputs!B14)
A18: Total Renovation Cost: | B18: ="Subdivision!D46
A19: Subdivision/Legal Costs: | B19: =Subdivision!D28
A20: Total Project Cost: | B20: =B17+B18
A21: All-In Cost Per Unit: | B21: =(B19)/2
A23: EXIT STRATEGY COMPARISON
A24: Strategy | B24: Gross Proceeds | C24: Net Profit | D24: ROI | E24: Timeline
A25: Option A: Subdivide & Sell 2 Units | B25: =Subdivision!E52 | C25: =Subdivision!E55 | D25: =Subdivision!E57 | E25: 9-15 months
A26: Option B: Sell As Duplex (Baseline) | B26: =Subdivision!G52 | C26: =Subdivision!G55 | D26: =Subdivision!G57 | E26: 6 months
A27: Option C: BRRRR (Refinance & Hold) | B27: =Subdivision!I52 | C27: =Subdivision!I55 | D27: =Subdivision!I57 | E27: 12+ months

Sheet Inputs
A1: INPUTS & ASSUMPTIONS
A3: PROPERTY INFORMATION
A4: Address: | B4: 2470-2472 NE 182nd Ter, North Miami Beach, FL 33160
A5: City: | B5: North Miami Beach
A6: State: | B6: FL
A7: Total Square Feet: | B7: 1778
A8: Unit 1 Square Feet: | B8: 889
A9: Unit 2 Square Feet: | B9: 889
A10: Year Built: | B10: 1967
A11: Current Status: | B11: Renovated, Occupied
A13: ACQUISITION DETAILS
A14: Purchase Price: | B14: 735000
A15: Down Payment %: | B15: 0.03
A16: Closing Costs %: | B16: 0.025
A17: Loan Interest Rate: | B17: 0.08
A18: Loan Term (Years): | B18: 30
A19: Loan Points: | B19: 0.02
A21: CURRENT RENTAL INCOME (Baseline)
A22: Unit 1 Current Rent (Monthly): | B22: 2400
A23: Unit 2 Current Rent (Monthly): | B23: 2075
A24: Annual Gross Rent: | B24: 53700
A25: Market Rent Potential (Annual): | B25: 60000
A26: Economic Occupancy: | B26: 0.95
A28: RENOVATION/IMPROVEMENT COSTS (Per Unit)
A29: Kitchen Updates: | B29: 5000
A30: Bathroom Updates: | B30: 3000
A31: Flooring: | B31: 2500
A32: Paint (Interior): | B32: 1500
A33: Paint (Exterior): | B33: 1000
A34: Landscaping/Curb Appeal: | B34: 2000
A35: Appliances: | B35: 2500
A36: Plumbing/Electrical: | B36: 1500
A37: Contingency % (of reno): | B37: 0.1
A39: SUBDIVISION/CONDO CONVERSION COSTS
A40: Survey & Engineering: | B40: 5000
A41: Legal Fees (Condo Docs): | B41: 8000
A42: HOA Formation & Filing: | B42: 3000
A43: Permit & Application Fees: | B43: 2000
A44: Utility Separation (if needed): | B44: 5000
A45: Title Work (per unit): | B45: 1500
...

Sheet Subdivision
A1: SUBDIVISION vs DUPLEX SALE ANALYSIS
A3: ACQUISITION COST BREAKDOWN
C4: Purchase Price: | D4: =Inputs!B13
C5: Down Payment: | D5: =Inputs!B13*Inputs!B14
C6: Loan Amount: | D6: =D4-D5
C7: Closing Costs: | D7: =Inputs!B13*Inputs!B15
C8: Loan Points: | D8: =D6*Inputs!B18
C9: Total Cash at Closing: | D9: =D5+D7+D8
A11: RENOVATION COSTS
B12: Category | C12: Unit 1 | D12: Unit 2 | E12: Total
B13: Kitchen Updates | C13: =Inputs!B33 | D13: =Inputs!B33 | E13: =C13+D13
B14: Bathroom Updates | C14: =Inputs!B34 | D14: =Inputs!B34 | E14: =C14+D14
B15: Flooring | C15: =Inputs!B35 | D15: =Inputs!B35 | E15: =C15+D15
B16: Paint (Interior) | C16: =Inputs!B36 | D16: =Inputs!B36 | E16: =C16+D16
B17: Paint (Exterior) | C17: =Inputs!B37/2 | D17: =Inputs!B37/2 | E17: =C17+D17
B18: Landscaping | C18: =Inputs!B38/2 | D18: =Inputs!B38/2 | E18: =C18+D18
B19: Appliances | C19: =Inputs!B39 | D19: =Inputs!B39 | E19: =C19+D19
B20: Plumbing/Electrical | C20: =Inputs!B40 | D20: =Inputs!B40 | E20: =C20+D20
B21: SUBTOTAL | C21: =SUM(C13:C20) | D21: =SUM(D13:D20) | E21: =C21+D21
B22: Contingency (10%) | C22: =C21*Inputs!B41 | D22: =D21*Inputs!B41 | E22: =C22+D22
B23: TOTAL RENOVATION | C23: =C21+C22 | D23: =D21+D22 | E23: =C23+D23
A25: SUBDIVISION/CONDO CONVERSION COSTS
C26: Survey & Engineering: | D26: =Inputs!B44
C27: Legal Fees (Condo Docs): | D27: =Inputs!B45
C28: HOA Formation & Filing: | D28: =Inputs!B46
C29: Permit & Application Fees: | D29: =Inputs!B47
C30: Utility Separation: | D30: =Inputs!B48
C31: Title Work (2 units): | D31: =Inputs!B49*2
C32: Contingency: | D32: =Inputs!B50
C33: TOTAL SUBDIVISION COSTS | D33: =SUM(D26:D32)
A35: EXIT STRATEGY COMPARISON
C36: Metric | E36: Option A: Subdivide | G36: Option B: Sell Duplex | I36: Option C: BRRRR
C37: REVENUE
C38: Gross Sales Proceeds | E38: =Inputs!B53+Inputs!B54 | G38: =Inputs!B55 | I38: =Inputs!B55
C39: Less: RE Commission (6%) | E39: =-E39*Inputs!B56 | G39: =-E39*Inputs!B56 | I39: 0
C40: Less: Closing Costs | E40: =-E40*Inputs!B57 | G40: =-E40*Inputs!B57 | I40: =-E40*Inputs!B57
C41: Less: Staging/Marketing | E41: =-Inputs!B58*2 | G41: =-Inputs!B58 | I41: 0
C42: Net Sale Proceeds | E42: =E{r-4}+E{r-3}+E{r-2}+E{r-1} | G42: =G{r-4}+G{r-3}+G{r-2}+G{r-1} | I42: =I{r-4}+I{r-3}+I{r-2}+I{r-1}
C44: TOTAL COSTS
C45: Cash at Closing | E45: =D9 | G45: =D9 | I45: =D9
...

Sheet Cash Flow
A1: CASH FLOW ANALYSIS
A3: Month-by-Month Cash Flow Projection
A4: Month | B4: Rental Income | C4: Loan Payment | D4: Operating Exp | E4: Reno Costs | F4: Net Cash Flow | G4: Cumulative
A5: 1 | B5: =(Inputs!B23+Inputs!B24)*Inputs!B27 | C5: =-PMT(Inputs!B16/12,Inputs!B17*12,Subdivision!D6) | D5: =-B5*0.30 | E5: 0 | F5: =B5+C5+D5+E5 | G5: =F5
A6: 2 | B6: =(Inputs!B23+Inputs!B24)*Inputs!B27 | C6: =-PMT(Inputs!B16/12,Inputs!B17*12,Subdivision!D6) | D6: =-B6*0.30 | E6: =-Subdivision!E23/3 | F6: =B6+C6+D6+E6 | G6: =G5+F6
A7: 3 | B7: =(Inputs!B23+Inputs!B24)*Inputs!B27 | C7: =-PMT(Inputs!B16/12,Inputs!B17*12,Subdivision!D6) | D7: =-B7*0.30 | E7: =-Subdivision!E23/3 | F7: =B7+C7+D7+E7 | G7: =G6+F7
A8: 4 | B8: =(Inputs!B23+Inputs!B24)*Inputs!B27 | C8: =-PMT(Inputs!B16/12,Inputs!B17*12,Subdivision!D6) | D8: =-B8*0.30 | E8: =-Subdivision!E23/3 | F8: =B8+C8+D8+E8 | G8: =G7+F8
A9: 5 | B9: =(Inputs!B23+Inputs!B24)*Inputs!B27 | C9: =-PMT(Inputs!B16/12,Inputs!B17*12,Subdivision!D6) | D9: =-B9*0.30 | E9: 0 | F9: =B9+C9+D9+E9 | G9: =G8+F9
A10: 6 | B10: =(Inputs!B23+Inputs!B24)*Inputs!B27 | C10: =-PMT(Inputs!B16/12,Inputs!B17*12,Subdivision!D6) | D10: =-B10*0.30 | E10: 0 | F10: =B10+C10+D10+E10 | G10: =G9+F10
A11: 7 | B11: =(Inputs!B23+Inputs!B24)*Inputs!B27 | C11: =-PMT(Inputs!B16/12,Inputs!B17*12,Subdivision!D6) | D11: =-B11*0.30 | E11: 0 | F11: =B11+C11+D11+E11 | G11: =G10+F11
A12: 8 | B12: =(Inputs!B23+Inputs!B24)*Inputs!B27 | C12: =-PMT(Inputs!B16/12,Inputs!B17*12,Subdivision!D6) | D12: =-B12*0.30 | E12: 0 | F12: =B12+C12+D12+E12 | G12: =G11+F12
A13: 9 | B13: =(Inputs!B23+Inputs!B24)*Inputs!B27 | C13: =-PMT(Inputs!B16/12,Inputs!B17*12,Subdivision!D6) | D13: =-B13*0.30 | E13: 0 | F13: =B13+C13+D13+E13 | G13: =G12+F13
A14: 10 | B14: =(Inputs!B23+Inputs!B24)*Inputs!B27 | C14: =-PMT(Inputs!B16/12,Inputs!B17*12,Subdivision!D6) | D14: =-B14*0.30 | E14: 0 | F14: =B14+C14+D14+E14 | G14: =G13+F14
A15: 11 | B15: =(Inputs!B23+Inputs!B24)*Inputs!B27 | C15: =-PMT(Inputs!B16/12,Inputs!B17*12,Subdivision!D6) | D15: =-B15*0.30 | E15: 0 | F15: =B15+C15+D15+E15 | G15: =G14+F15
A16: 12 | B16: =(Inputs!B23+Inputs!B24)*Inputs!B27 | C16: =-PMT(Inputs!B16/12,Inputs!B17*12,Subdivision!D6) | D16: =-B16*0.30 | E16: 0 | F16: =B16+C16+D16+E16 | G16: =G15+F16
A17: TOTAL | B17: =SUM(B5:B16) | C17: =SUM(C5:C16) | D17: =SUM(D5:D16) | E17: =SUM(E5:E16) | F17: =SUM(F5:F16) | G17: =F17
