Workbook

Sheet Property Setup
A1: MULTI-UNIT SUBDIVISION/CONVERSION ANALYSIS
A2: Property Configuration & Unit Details
A4: PROPERTY INFORMATION
A5: Field | B5: Value | C5: Notes
A6: Property Address | C6: Full street address
A7: City, State, ZIP | C7: Location details
A8: Property Type | B8: Duplex | C8: Duplex/Triplex/Quadplex/5-Unit/6-Unit/7-Unit/8-Unit/9-Unit/10-Unit
A9: Number of Units | B9: 2 | C9: 2-10 units supported
A10: Total Building SF | B10: 0 | C10: Total square footage
A11: Lot Size (SF) | B11: 0 | C11: Land area in square feet
A12: Year Built | B12: 0 | C12: Construction year
A13: Zoning | C13: Current zoning designation
A14: Conversion Allowed? | B14: Unknown | C14: Yes/No/Unknown - CHECK WITH COUNTY!
A16: INDIVIDUAL UNIT DETAILS
A17: Unit # | B17: Beds | C17: Baths | D17: SF | E17: Current Rent | F17: Market Rent | G17: Condition | H17: Occupied? | I17: Lease End | J17: Notes
A18: Unit 1 | G18: Fair | H18: No
A19: Unit 2 | G19: Fair | H19: No
A20: Unit 3 | G20: Fair | H20: No
A21: Unit 4 | G21: Fair | H21: No
A22: Unit 5 | G22: Fair | H22: No
A23: Unit 6 | G23: Fair | H23: No
A24: Unit 7 | G24: Fair | H24: No
A25: Unit 8 | G25: Fair | H25: No
A26: Unit 9 | G26: Fair | H26: No
A27: Unit 10 | G27: Fair | H27: No
A28: TOTALS | D28: =SUM(D18:D27) -> 0 | E28: =SUM(E18:E27) -> 0 | F28: =SUM(F18:F27) -> 0

Sheet Acquisition
A1: ACQUISITION ANALYSIS
A2: Purchase Price & Financing Scenarios
A4: PURCHASE DETAILS
A5: Purchase Price | B5: 0 | C5: $
A6: Closing Costs % | B6: 0.025 | C6: %
A7: Closing Costs $ | B7: =B5*B6 -> 0 | C7: $
A8: Inspection/Due Diligence | B8: 2000 | C8: $
A9: Total Acquisition Cost | B9: =B5+B7+B8 -> 2000 | C9: $
A11: FINANCING OPTIONS COMPARISON
B12: Option 1: 3% Down | C12: Option 2: 3.5% FHA | D12: Option 3: 20% Down | E12: Option 4: Hard Money
A13: Down Payment % | B13: 0.03 | C13: 0.035 | D13: 0.2 | E13: 0.25
A14: Interest Rate | B14: 0.075 | C14: 0.0675 | D14: 0.07 | E14: 0.12
A15: Loan Term (Years) | B15: 30 | C15: 30 | D15: 30 | E15: 12
A16: Down Payment $ | B16: =$B$5*B13 -> 0 | C16: =$B$5*C13 -> 0 | D16: =$B$5*D13 -> 0 | E16: =$B$5*E13 -> 0
A17: Loan Amount | B17: =$B$5-B16 -> 0 | C17: =$B$5-C16 -> 0 | D17: =$B$5-D16 -> 0 | E17: =$B$5-E16 -> 0
A18: Monthly Payment | B18: =PMT(B14/12,B15*12,B17) -> 0 | C18: =PMT(C14/12,C15*12,C17) -> 0 | D18: =PMT(D14/12,D15*12,D17) -> 0 | E18: =PMT(E14/12,E15*12,E17) -> 0
A20: CASH REQUIRED AT CLOSING
A21: Down Payment | B21: =B16 -> 0 | C21: =C16 -> 0 | D21: =D16 -> 0 | E21: =E16 -> 0
A22: Closing Costs | B22: =$B$7 -> 0 | C22: =$B$7 -> 0 | D22: =$B$7 -> 0 | E22: =$B$7 -> 0
A23: Due Diligence | B23: =$B$8 -> 2000 | C23: =$B$8 -> 2000 | D23: =$B$8 -> 2000 | E23: =$B$8 -> 2000
A24: Total Cash Needed | B24: =B21+B22+B23 -> 2000 | C24: =C21+C22+C23 -> 2000 | D24: =D21+D22+D23 -> 2000 | E24: =E21+E22+E23 -> 2000

Sheet Renovation Budget
A1: RENOVATION BUDGET
A2: Unit-by-Unit Renovation Costs
A4: Enter renovation costs for each unit being renovated. Leave blank for units not being touched.
A6: RENOVATION CATEGORY | B6: Unit 1 | C6: Unit 2 | D6: Unit 3 | E6: Unit 4 | F6: Unit 5 | G6: Unit 6 | H6: Unit 7 | I6: Unit 8 | J6: Unit 9 | K6: Unit 10 | L6: TOTAL
A7: Kitchen Updates | B7: 0 | C7: 0 | D7: 0 | E7: 0 | F7: 0 | G7: 0 | H7: 0 | I7: 0 | J7: 0 | K7: 0 | L7: =SUM(B7:K7) -> 0
A8: Bathroom Updates | B8: 0 | C8: 0 | D8: 0 | E8: 0 | F8: 0 | G8: 0 | H8: 0 | I8: 0 | J8: 0 | K8: 0 | L8: =SUM(B8:K8) -> 0
A9: Flooring | B9: 0 | C9: 0 | D9: 0 | E9: 0 | F9: 0 | G9: 0 | H9: 0 | I9: 0 | J9: 0 | K9: 0 | L9: =SUM(B9:K9) -> 0
A10: Interior Paint | B10: 0 | C10: 0 | D10: 0 | E10: 0 | F10: 0 | G10: 0 | H10: 0 | I10: 0 | J10: 0 | K10: 0 | L10: =SUM(B10:K10) -> 0
A11: Exterior Paint | B11: 0 | C11: 0 | D11: 0 | E11: 0 | F11: 0 | G11: 0 | H11: 0 | I11: 0 | J11: 0 | K11: 0 | L11: =SUM(B11:K11) -> 0
A12: Appliances | B12: 0 | C12: 0 | D12: 0 | E12: 0 | F12: 0 | G12: 0 | H12: 0 | I12: 0 | J12: 0 | K12: 0 | L12: =SUM(B12:K12) -> 0
A13: Plumbing Repairs | B13: 0 | C13: 0 | D13: 0 | E13: 0 | F13: 0 | G13: 0 | H13: 0 | I13: 0 | J13: 0 | K13: 0 | L13: =SUM(B13:K13) -> 0
A14: Electrical Updates | B14: 0 | C14: 0 | D14: 0 | E14: 0 | F14: 0 | G14: 0 | H14: 0 | I14: 0 | J14: 0 | K14: 0 | L14: =SUM(B14:K14) -> 0
A15: HVAC | B15: 0 | C15: 0 | D15: 0 | E15: 0 | F15: 0 | G15: 0 | H15: 0 | I15: 0 | J15: 0 | K15: 0 | L15: =SUM(B15:K15) -> 0
A16: Windows/Doors | B16: 0 | C16: 0 | D16: 0 | E16: 0 | F16: 0 | G16: 0 | H16: 0 | I16: 0 | J16: 0 | K16: 0 | L16: =SUM(B16:K16) -> 0
A17: Landscaping | B17: 0 | C17: 0 | D17: 0 | E17: 0 | F17: 0 | G17: 0 | H17: 0 | I17: 0 | J17: 0 | K17: 0 | L17: =SUM(B17:K17) -> 0
A18: Roof Repairs | B18: 0 | C18: 0 | D18: 0 | E18: 0 | F18: 0 | G18: 0 | H18: 0 | I18: 0 | J18: 0 | K18: 0 | L18: =SUM(B18:K18) -> 0
A19: Other | B19: 0 | C19: 0 | D19: 0 | E19: 0 | F19: 0 | G19: 0 | H19: 0 | I19: 0 | J19: 0 | K19: 0 | L19: =SUM(B19:K19) -> 0
A20: SUBTOTAL | B20: =SUM(B7:B19) -> 0 | C20: =SUM(C7:C19) -> 0 | D20: =SUM(D7:D19) -> 0 | E20: =SUM(E7:E19) -> 0 | F20: =SUM(F7:F19) -> 0 | G20: =SUM(G7:G19) -> 0 | H20: =SUM(H7:H19) -> 0 | I20: =SUM(I7:I19) -> 0 | ... L20: =SUM(L7:L19) -> 0
A21: Contingency (10%) | B21: =B20*0.1 -> 0 | C21: =C20*0.1 -> 0 | D21: =D20*0.1 -> 0 | E21: =E20*0.1 -> 0 | F21: =F20*0.1 -> 0 | G21: =G20*0.1 -> 0 | H21: =H20*0.1 -> 0 | I21: =I20*0.1 -> 0 | ... L21: =L20*0.1 -> 0
A22: TOTAL PER UNIT | B22: =B20+B21 -> 0 | C22: =C20+C21 -> 0 | D22: =D20+D21 -> 0 | E22: =E20+E21 -> 0 | F22: =F20+F21 -> 0 | G22: =G20+G21 -> 0 | H22: =H20+H21 -> 0 | I22: =I20+I21 -> 0 | ... L22: =L20+L21 -> 0
A24: SUMMARY
A25: Total Renovation Budget | B25: =L22 -> 0 | C25: $
A26: Average Cost Per Unit | B26: =IFERROR(L22/'Property Setup'!B8,0) -> 0 | C26: $
A27: Cost Per Square Foot | B27: =IFERROR(B25/'Property Setup'!D28,0) -> 0 | C27: $/SF

Sheet Conversion Costs
A1: CONVERSION COSTS
A2: Legal & Subdivision Expenses
A4: CONVERSION TYPE SELECTION
A5: Conversion Type | B5: Condo Conversion | C5: Select: Condo/Townhome/Co-op/Subdivision/None
A6: Number of Units | B6: ='Property Setup'!B8 -> Duplex | C6: From Property Setup sheet
A8: ITEMIZED CONVERSION COSTS
A9: Item | B9: Cost | C9: Notes
A10: Survey & Engineering | B10: 0 | C10: Boundary survey, plat preparation
A11: Real Estate Attorney | B11: 0 | C11: Legal docs, condo/co-op formation
A12: HOA/Co-op Formation | B12: 0 | C12: Articles, bylaws, CC&Rs
A13: Title Work (Per Unit) | B13: 0 | C13: Separate titles for each unit
A14: County/City Fees & Permits | B14: 0 | C14: Application, recording, permits
A15: Utility Separation | B15: 0 | C15: If meters need to be separated
A16: Environmental Inspections | B16: 0 | C16: Phase I, Phase II if needed
A17: Architectural Plans | B17: 0 | C17: If required by county
A18: Insurance (During Conversion) | B18: 0 | C18: Builder's risk, liability
A19: Other | B19: 0 | C19: Miscellaneous costs
A20: SUBTOTAL | B20: =SUM(B10:B19) -> 0
A21: Contingency (10%) | B21: =B20*0.1 -> 0
A22: TOTAL CONVERSION COST | B22: =B20+B21 -> 0
A24: CONVERSION COST PER UNIT | B24: =IFERROR(B22/B6,0) -> 0
A26: ESTIMATED TIMELINE
A27: County Approval Process | B27: 6-12 months | C27: Typical range
A28: Legal Document Preparation | B28: 2-4 months | C28: Overlaps with county
A29: Total Estimated Duration | B29: 9-14 months | C29: From start to sellable units

Sheet Exit Strategies
A1: EXIT STRATEGY COMPARISON
A2: Compare 5 Exit Options to Find the Best Strategy
A4: Strategy 1: Subdivide/Convert & Sell
B5: Amount | C5: Formula/Notes
A6: Individual Unit Sale Prices (Total) | B6: 0 | C6: Sum of all unit sales
A7: Selling Costs (7.5%) | B7: =B6*0.075 -> 0 | C7: Commission + closing
A8: Net Proceeds from Sales | B8: =B6-B7 -> 0
A9: Less: Remaining Loan Balance | B9: =Acquisition!B17 -> 0 | C9: From acquisition
A10: Less: Renovation Cost | B10: ='Renovation Budget'!L22 -> 0 | C10: Total renovation
A11: Less: Conversion Cost | B11: ='Conversion Costs'!B22 -> 0 | C11: Legal/subdivision
A12: Net Profit | B12: =B8-B9-B10-B11 -> 0
A14: Total Project Cost | B14: =Acquisition!B24+'Renovation Budget'!L22+'Conversion Costs'!B22 -> 2000
A15: Return on Investment (ROI) | B15: =B12/B14 -> 0 | C15: Net profit / Total invested
A16: Cash-on-Cash Return | B16: =B12/(Acquisition!B24) -> 0 | C16: Net profit / Cash invested
A18: Strategy 2: Sell As-Is
B19: Amount | C19: Formula/Notes
A20: As-Is Sale Price | B20: 0 | C20: What investors will pay
A21: Selling Costs (7.5%) | B21: =B20*0.075 -> 0 | C21: Commission + closing
A22: Net Proceeds from Sale | B22: =B20-B21 -> 0
A23: Less: Remaining Loan Balance | B23: =Acquisition!B17 -> 0 | C23: Pay off loan
A24: Less: Renovation Cost | B24: ='Renovation Budget'!L22 -> 0 | C24: If any renovation done
A25: Net Profit | B25: =B22-B23-B24 -> 0
A27: Total Project Cost | B27: =Acquisition!B24+'Renovation Budget'!L22 -> 2000
A28: Return on Investment (ROI) | B28: =B25/B27 -> 0 | C28: Net profit / Total invested
A29: Cash-on-Cash Return | B29: =B25/(Acquisition!B24) -> 0 | C29: Net profit / Cash invested
A31: Strategy 3: BRRRR (Refinance & Hold)
B32: Amount | C32: Formula/Notes
A33: Stabilized Property Value | B33: 0 | C33: ARV after renovation
A34: Refinance Amount (75% LTV) | B34: =B33*0.75 -> 0 | C34: Typical max for refi
A35: Less: Original Loan Balance | B35: =Acquisition!B17 -> 0 | C35: Pay off original
A36: Cash-Out Proceeds | B36: =B34-B35 -> 0 | C36: Cash returned
A37: Less: Total Cash Invested | B37: =Acquisition!B24+'Renovation Budget'!L22 -> 2000 | C37: Original investment
A38: Net Position | B38: =B36-B37 -> -2000 | C38: Positive = money returned
A40: Annual Rental Income | B40: 0 | C40: All units at market rent
A41: Annual Operating Expenses | B41: =B40*0.5 -> 0 | C41: 50% of rent rule
A42: Annual Debt Service (New Loan) | B42: =PMT(0.07/12,30*12,B34)*-12 -> 0 | C42: New loan payment
A43: Annual Cash Flow | B43: =B40-B41-B42 -> 0 | C43: NOI - debt service
A44: Cash-on-Cash Return | B44: =B43/(Acquisition!B24+'Renovation Budget'!L22-B36) -> 0 | C44: Annual CF / Cash left in
A46: Strategy 4: Hybrid (Sell Some, Hold Some)
B47: Amount | C47: Formula/Notes
...

Sheet Cash Flow
A1: CASH FLOW PROJECTION
A2: 18-Month Cash Requirements Timeline
A4: PROJECT TIMELINE
A5: CASH FLOW ITEM | B5: Month 1 | C5: Month 2 | D5: Month 3 | E5: Month 4 | F5: Month 5 | G5: Month 6 | H5: Month 7 | I5: Month 8 | J5: Month 9 | K5: Month 10 | L5: Month 11 | M5: Month 12 | N5: Month 13 | O5: Month 14 | P5: Month 15 | Q5: Month 16 | R5: Month 17 | S5: Month 18
A6: CASH OUTFLOWS
A7: Purchase Price
A8: Closing Costs
A9: Renovation Costs
A10: Conversion Costs
A11: Mortgage Payment
A12: Property Taxes
A13: Insurance
A14: Utilities (Vacant)
A15: Total Outflows
A17: CASH INFLOWS
A18: Unit Sales
... A24: Cumulative Cash Position

Sheet Instructions
A1: HOW TO USE THIS TEMPLATE
A3: QUICK START GUIDE
A5: This template analyzes 2-10 unit properties with multiple exit strategies including:
A6: • Condo/townhome conversion and individual sales
A7: • As-is sale to investors
A8: • BRRRR (Buy, Renovate, Rent, Refinance, Repeat)
A9: • Hybrid strategy (sell some units, hold others)
A10: • Wholesale assignment
A12: STEP-BY-STEP WORKFLOW:
A14: 1. PROPERTY SETUP (10 minutes)
A15: • Enter property address and details
A16: • Complete unit information (beds, baths, SF, rent)
... A73: Remember: This template helps you analyze deals - but buying right is 90% of success!
