Workbook

Sheet Instructions
B2: ENHANCED DCF MODEL - INSTRUCTIONS
B4: Welcome to Your Comprehensive DCF Valuation Model!
B6: COLOR CODING SYSTEM (Follow This Throughout)
B7: 🔵 BLUE TEXT + YELLOW FILL = INPUT CELLS (Enter your data here)
B8: ⚫ BLACK TEXT = FORMULAS (Automatically calculated - do not edit)
B9: 🟢 GREEN TEXT = LINKS (References to other worksheets)
B12: QUICK START GUIDE (15 Minutes to First Valuation)
B13: 1. DCF Sheet → Fill company info (cells D8-D11) including name, ticker, stock price, and year end
B14: 2. DCF Sheet → Enter balance sheet items (cells D19-D22) for cash, debt, preferred stock, minority interest
B15: 3. WACC Sheet → Enter cost of capital inputs (cells F6-F9, F15) including risk-free rate, ERP, beta, cost of debt
B16: 4. DCF Sheet → Adjust revenue growth rates and EBITDA margins (rows 61-68) for 5-year projections
B17: 5. DCF Sheet → Set terminal value method and rate (cells G7-G9) - choose Growth or Multiple method
... B59: Version 1.0 Enhanced - Comprehensive DCF Valuation Model

Sheet Executive Summary
B2: EXECUTIVE SUMMARY
B3: =DCF!D8
B4: As of: November 01, 2025
B6: KEY VALUATION METRICS
B7: Current Share Price | C7: =DCF!D10
B8: DCF Implied Price | C8: =DCF!D32
B9: Upside / (Downside) | C9: =C8/C7-1
B10: Recommendation | C10: =IF(C9>0.15,"STRONG BUY",IF(C9>0.05,"BUY",IF(C9>-0.05,"HOLD",IF(C9>-0.15,"SELL","STRONG SELL"))))
B12: VALUATION SUMMARY
B13: Method | C13: Equity Value ($mm) | D13: Price per Share
B14: DCF Analysis | C14: =DCF!D29 | D14: =DCF!D32
B15: Trading Comps (Median) | C15: =TradingComps!C28 | D15: =C16/DCF!D48
B16: Precedent Transactions (Median) | C16: =PrecedentTxns!C28 | D16: =C17/DCF!D48
B18: KEY FINANCIAL METRICS
B19: Metric | C19: LTM | D19: Year 5
B20: Revenue ($mm) | C20: =DCF!D63 | D20: =DCF!I63
B21: EBITDA ($mm) | C21: =DCF!D67 | D21: =DCF!I67
B22: EBITDA Margin | C22: =DCF!D68 | D22: =DCF!I68
B23: Free Cash Flow ($mm) | C23: =DCF!D95 | D23: =DCF!I95
B25: CREDIT METRICS
B26: Net Debt / EBITDA | C26: =CreditAnalysis!D10
B27: EBITDA / Interest | C27: =CreditAnalysis!D13

Sheet DCF
C2: DISCOUNTED CASH FLOW ANALYSIS
C3: ($ in Millions Except Per Share Data)
C6: COMPANY INFORMATION | F6: TERMINAL VALUE ASSUMPTIONS
C7: Company Name: | D7: Example Corp | F7: Terminal Growth Rate: | G7: 0.025
C8: Ticker Symbol: | D8: EXMP | F8: Terminal EBITDA Multiple: | G8: 10
C9: Current Share Price: | D9: 100 | F9: Terminal Value Method: | G9: Growth
C10: Fiscal Year End: | D10: 12/31/2024
C11: Effective Tax Rate: | D11: 0.25
C13: BALANCE SHEET ITEMS
C14: Cash & Equivalents: | D14: 500
C15: Total Debt: | D15: 1000
C16: Preferred Stock: | D16: 0
C17: Minority Interest: | D17: 0
C25: BRIDGE TO EQUITY VALUE
C26: Enterprise Value (PV of FCF + Terminal) | D26: =SUM(D100:I100)+D102
C27: (+) Cash & Equivalents | D27: =D19
C28: (-) Total Debt | D28: =-D20
C29: Equity Value | D29: =SUM(D26:D28)
C31: Implied Price per Share: | D31: =D29/D48
C32: Current Share Price: | D32: =D10
C33: Upside / (Downside): | D33: =D32/D33-1
C36: COST OF CAPITAL
C37: WACC: | D37: =WACC!F35
C38: Tax Rate: | D38: =D13
C41: KEY ASSUMPTIONS
C42: Projection Years: | D42: 5
C43: Base Year Revenue ($mm): | D43: 5000
C45: Diluted Shares Outstanding (mm): | D45: 100
C58: FINANCIAL PROJECTIONS
C59: Item | D59: LTM | E59: Year 1 | F59: Year 2 | G59: Year 3 | H59: Year 4 | I59: Year 5
C60: Revenue Growth % | E60: 0.1 | F60: 0.09 | G60: 0.08 | H60: 0.07 | I60: 0.06
C61: Revenue | D61: =D45 | E61: =D63*(1+E61) | F61: =E63*(1+F61) | G61: =F63*(1+G61) | H61: =G63*(1+H61) | I61: =H63*(1+I61)
C62: EBITDA Margin % | D62: 0.2 | E62: 0.21 | F62: 0.22 | G62: 0.23 | H62: 0.24 | I62: 0.25
C63: EBITDA | D63: =D63*D64 | E63: =E63*E64 | F63: =F63*F64 | G63: =G63*G64 | H63: =H63*H64 | I63: =I63*I64
C64: D&A % of Revenue | D64: 0.03 | E64: 0.03 | F64: 0.03 | G64: 0.03 | H64: 0.03 | I64: 0.03
C65: Depreciation & Amortization | D65: =D63*D68 | E65: =E63*E68 | F65: =F63*F68 | G65: =G63*G68 | H65: =H63*H68 | I65: =I63*I68
C66: EBIT | D66: =D67-D69 | E66: =E67-E69 | F66: =F67-F69 | G66: =G67-G69 | H66: =H67-H69 | I66: =I67-I69
C67: Less: Taxes | D67: =-D70*$D$13 | E67: =-E70*$D$13 | F67: =-F70*$D$13 | G67: =-G70*$D$13 | H67: =-H70*$D$13 | I67: =-I70*$D$13
C68: NOPAT (After-Tax Operating Profit) | D68: =D70+D71 | E68: =E70+E71 | F68: =F70+F71 | G68: =G70+G71 | H68: =H70+H71 | I68: =I70+I71
C69: Add: D&A | D69: =D69 | E69: =E69 | F69: =F69 | G69: =G69 | H69: =H69 | I69: =I69
...

Sheet Sensitivity
C2: SENSITIVITY ANALYSIS
C5: SENSITIVITY TABLE 1: WACC vs Terminal Growth Rate
C6: Implied Share Price
D7: 0.015 | E7: 0.02 | F7: 0.025 | G7: 0.03 | H7: 0.035 | I7: 0.04 | J7: 0.045
C8: 0.07 | D8: =(((DCF!I84*(1+0.015))/(0.07-0.015))/((1+0.07)^5)+SUM(DCF!E92:DCF!I92)+DCF!D19-DCF!D20)/DCF!D48 | E8: =(((DCF!I84*(1+0.02))/(0.07-0.02))/((1+0.07)^5)+SUM(DCF!E92:DCF!I92)+DCF!D19-DCF!D20)/DCF!D48 | F8: =(((DCF!I84*(1+0.025))/(0.07-0.025))/((1+0.07)^5)+SUM(DCF!E92:DCF!I92)+DCF!D19-DCF!D20)/DCF!D48 | G8: =(((DCF!I84*(1+0.03))/(0.07-0.03))/((1+0.07)^5)+SUM(DCF!E92:DCF!I92)+DCF!D19-DCF!D20)/DCF!D48 | H8: =(((DCF!I84*(1+0.035))/(0.07-0.035))/((1+0.07)^5)+SUM(DCF!E92:DCF!I92)+DCF!D19-DCF!D20)/DCF!D48 | I8: =(((DCF!I84*(1+0.04))/(0.07-0.04))/((1+0.07)^5)+SUM(DCF!E92:DCF!I92)+DCF!D19-DCF!D20)/DCF!D48 | J8: =(((DCF!I84*(1+0.045))/(0.07-0.045))/((1+0.07)^5)+SUM(DCF!E92:DCF!I92)+DCF!D19-DCF!D20)/DCF!D48
C9: 0.075 | D9: =(((DCF!I84*(1+0.015))/(0.075-0.015))/((1+0.075)^5)+SUM(DCF!E92:DCF!I92)+DCF!D19-DCF!D20)/DCF!D48 | E9: =(((DCF!I84*(1+0.02))/(0.075-0.02))/((1+0.075)^5)+SUM(DCF!E92:DCF!I92)+DCF!D19-DCF!D20)/DCF!D48 | F9: =(((DCF!I84*(1+0.025))/(0.075-0.025))/((1+0.075)^5)+SUM(DCF!E92:DCF!I92)+DCF!D19-DCF!D20)/DCF!D48 | G9: =(((DCF!I84*(1+0.03))/(0.075-0.03))/((1+0.075)^5)+SUM(DCF!E92:DCF!I92)+DCF!D19-DCF!D20)/DCF!D48 | H9: =(((DCF!I84*(1+0.035))/(0.075-0.035))/((1+0.075)^5)+SUM(DCF!E92:DCF!I92)+DCF!D19-DCF!D20)/DCF!D48 | I9: =(((DCF!I84*(1+0.04))/(0.075-0.04))/((1+0.075)^5)+SUM(DCF!E92:DCF!I92)+DCF!D19-DCF!D20)/DCF!D48 | J9: =(((DCF!I84*(1+0.045))/(0.075-0.045))/((1+0.075)^5)+SUM(DCF!E92:DCF!I92)+DCF!D19-DCF!D20)/DCF!D48
C10: 0.08 | D10: =(((DCF!I84*(1+0.015))/(0.08-0.015))/((1+0.08)^5)+SUM(DCF!E92:DCF!I92)+DCF!D19-DCF!D20)/DCF!D48 | E10: =(((DCF!I84*(1+0.02))/(0.08-0.02))/((1+0.08)^5)+SUM(DCF!E92:DCF!I92)+DCF!D19-DCF!D20)/DCF!D48 | F10: =(((DCF!I84*(1+0.025))/(0.08-0.025))/((1+0.08)^5)+SUM(DCF!E92:DCF!I92)+DCF!D19-DCF!D20)/DCF!D48 | G10: =(((DCF!I84*(1+0.03))/(0.08-0.03))/((1+0.08)^5)+SUM(DCF!E92:DCF!I92)+DCF!D19-DCF!D20)/DCF!D48 | H10: =(((DCF!I84*(1+0.035))/(0.08-0.035))/((1+0.08)^5)+SUM(DCF!E92:DCF!I92)+DCF!D19-DCF!D20)/DCF!D48 | I10: =(((DCF!I84*(1+0.04))/(0.08-0.04))/((1+0.08)^5)+SUM(DCF!E92:DCF!I92)+DCF!D19-DCF!D20)/DCF!D48 | J10: =(((DCF!I84*(1+0.045))/(0.08-0.045))/((1+0.08)^5)+SUM(DCF!E92:DCF!I92)+DCF!D19-DCF!D20)/DCF!D48
C11: 0.085 | D11: =(((DCF!I84*(1+0.015))/(0.085-0.015))/((1+0.085)^5)+SUM(DCF!E92:DCF!I92)+DCF!D19-DCF!D20)/DCF!D48 | E11: =(((DCF!I84*(1+0.02))/(0.085-0.02))/((1+0.085)^5)+SUM(DCF!E92:DCF!I92)+DCF!D19-DCF!D20)/DCF!D48 | F11: =(((DCF!I84*(1+0.025))/(0.085-0.025))/((1+0.085)^5)+SUM(DCF!E92:DCF!I92)+DCF!D19-DCF!D20)/DCF!D48 | G11: =(((DCF!I84*(1+0.03))/(0.085-0.03))/((1+0.085)^5)+SUM(DCF!E92:DCF!I92)+DCF!D19-DCF!D20)/DCF!D48 | H11: =(((DCF!I84*(1+0.035))/(0.085-0.035))/((1+0.085)^5)+SUM(DCF!E92:DCF!I92)+DCF!D19-DCF!D20)/DCF!D48 | I11: =(((DCF!I84*(1+0.04))/(0.085-0.04))/((1+0.085)^5)+SUM(DCF!E92:DCF!I92)+DCF!D19-DCF!D20)/DCF!D48 | J11: =(((DCF!I84*(1+0.045))/(0.085-0.045))/((1+0.085)^5)+SUM(DCF!E92:DCF!I92)+DCF!D19-DCF!D20)/DCF!D48
C12: 0.09 | D12: =(((DCF!I84*(1+0.015))/(0.09-0.015))/((1+0.09)^5)+SUM(DCF!E92:DCF!I92)+DCF!D19-DCF!D20)/DCF!D48 | E12: =(((DCF!I84*(1+0.02))/(0.09-0.02))/((1+0.09)^5)+SUM(DCF!E92:DCF!I92)+DCF!D19-DCF!D20)/DCF!D48 | F12: =(((DCF!I84*(1+0.025))/(0.09-0.025))/((1+0.09)^5)+SUM(DCF!E92:DCF!I92)+DCF!D19-DCF!D20)/DCF!D48 | G12: =(((DCF!I84*(1+0.03))/(0.09-0.03))/((1+0.09)^5)+SUM(DCF!E92:DCF!I92)+DCF!D19-DCF!D20)/DCF!D48 | H12: =(((DCF!I84*(1+0.035))/(0.09-0.035))/((1+0.09)^5)+SUM(DCF!E92:DCF!I92)+DCF!D19-DCF!D20)/DCF!D48 | I12: =(((DCF!I84*(1+0.04))/(0.09-0.04))/((1+0.09)^5)+SUM(DCF!E92:DCF!I92)+DCF!D19-DCF!D20)/DCF!D48 | J12: =(((DCF!I84*(1+0.045))/(0.09-0.045))/((1+0.09)^5)+SUM(DCF!E92:DCF!I92)+DCF!D19-DCF!D20)/DCF!D48
C13: 0.095 | D13: =(((DCF!I84*(1+0.015))/(0.095-0.015))/((1+0.095)^5)+SUM(DCF!E92:DCF!I92)+DCF!D19-DCF!D20)/DCF!D48 | E13: =(((DCF!I84*(1+0.02))/(0.095-0.02))/((1+0.095)^5)+SUM(DCF!E92:DCF!I92)+DCF!D19-DCF!D20)/DCF!D48 | F13: =(((DCF!I84*(1+0.025))/(0.095-0.025))/((1+0.095)^5)+SUM(DCF!E92:DCF!I92)+DCF!D19-DCF!D20)/DCF!D48 | G13: =(((DCF!I84*(1+0.03))/(0.095-0.03))/((1+0.095)^5)+SUM(DCF!E92:DCF!I92)+DCF!D19-DCF!D20)/DCF!D48 | H13: =(((DCF!I84*(1+0.035))/(0.095-0.035))/((1+0.095)^5)+SUM(DCF!E92:DCF!I92)+DCF!D19-DCF!D20)/DCF!D48 | I13: =(((DCF!I84*(1+0.04))/(0.095-0.04))/((1+0.095)^5)+SUM(DCF!E92:DCF!I92)+DCF!D19-DCF!D20)/DCF!D48 | J13: =(((DCF!I84*(1+0.045))/(0.095-0.045))/((1+0.095)^5)+SUM(DCF!E92:DCF!I92)+DCF!D19-DCF!D20)/DCF!D48
C14: 0.1 | D14: =(((DCF!I84*(1+0.015))/(0.1-0.015))/((1+0.1)^5)+SUM(DCF!E92:DCF!I92)+DCF!D19-DCF!D20)/DCF!D48 | E14: =(((DCF!I84*(1+0.02))/(0.1-0.02))/((1+0.1)^5)+SUM(DCF!E92:DCF!I92)+DCF!D19-DCF!D20)/DCF!D48 | F14: =(((DCF!I84*(1+0.025))/(0.1-0.025))/((1+0.1)^5)+SUM(DCF!E92:DCF!I92)+DCF!D19-DCF!D20)/DCF!D48 | G14: =(((DCF!I84*(1+0.03))/(0.1-0.03))/((1+0.1)^5)+SUM(DCF!E92:DCF!I92)+DCF!D19-DCF!D20)/DCF!D48 | H14: =(((DCF!I84*(1+0.035))/(0.1-0.035))/((1+0.1)^5)+SUM(DCF!E92:DCF!I92)+DCF!D19-DCF!D20)/DCF!D48 | I14: =(((DCF!I84*(1+0.04))/(0.1-0.04))/((1+0.1)^5)+SUM(DCF!E92:DCF!I92)+DCF!D19-DCF!D20)/DCF!D48 | J14: =(((DCF!I84*(1+0.045))/(0.1-0.045))/((1+0.1)^5)+SUM(DCF!E92:DCF!I92)+DCF!D19-DCF!D20)/DCF!D48
C17: SENSITIVITY TABLE 2: WACC vs Terminal EBITDA Multiple
C18: Implied Share Price
D19: 8 | E19: 9 | F19: 10 | G19: 11 | H19: 12 | I19: 13 | J19: 14
C20: 0.07 | D20: =(((DCF!I67*8.0)/((1+0.07)^5))+SUM(DCF!E92:DCF!I92)+DCF!D19-DCF!D20)/DCF!D48 | E20: =(((DCF!I67*9.0)/((1+0.07)^5))+SUM(DCF!E92:DCF!I92)+DCF!D19-DCF!D20)/DCF!D48 | F20: =(((DCF!I67*10.0)/((1+0.07)^5))+SUM(DCF!E92:DCF!I92)+DCF!D19-DCF!D20)/DCF!D48 | G20: =(((DCF!I67*11.0)/((1+0.07)^5))+SUM(DCF!E92:DCF!I92)+DCF!D19-DCF!D20)/DCF!D48 | H20: =(((DCF!I67*12.0)/((1+0.07)^5))+SUM(DCF!E92:DCF!I92)+DCF!D19-DCF!D20)/DCF!D48 | I20: =(((DCF!I67*13.0)/((1+0.07)^5))+SUM(DCF!E92:DCF!I92)+DCF!D19-DCF!D20)/DCF!D48 | J20: =(((DCF!I67*14.0)/((1+0.07)^5))+SUM(DCF!E92:DCF!I92)+DCF!D19-DCF!D20)/DCF!D48
C21: 0.075 | D21: =(((DCF!I67*8.0)/((1+0.075)^5))+SUM(DCF!E92:DCF!I92)+DCF!D19-DCF!D20)/DCF!D48 | E21: =(((DCF!I67*9.0)/((1+0.075)^5))+SUM(DCF!E92:DCF!I92)+DCF!D19-DCF!D20)/DCF!D48 | F21: =(((DCF!I67*10.0)/((1+0.075)^5))+SUM(DCF!E92:DCF!I92)+DCF!D19-DCF!D20)/DCF!D48 | G21: =(((DCF!I67*11.0)/((1+0.075)^5))+SUM(DCF!E92:DCF!I92)+DCF!D19-DCF!D20)/DCF!D48 | H21: =(((DCF!I67*12.0)/((1+0.075)^5))+SUM(DCF!E92:DCF!I92)+DCF!D19-DCF!D20)/DCF!D48 | I21: =(((DCF!I67*13.0)/((1+0.075)^5))+SUM(DCF!E92:DCF!I92)+DCF!D19-DCF!D20)/DCF!D48 | J21: =(((DCF!I67*14.0)/((1+0.075)^5))+SUM(DCF!E92:DCF!I92)+DCF!D19-DCF!D20)/DCF!D48
C22: 0.08 | D22: =(((DCF!I67*8.0)/((1+0.08)^5))+SUM(DCF!E92:DCF!I92)+DCF!D19-DCF!D20)/DCF!D48 | E22: =(((DCF!I67*9.0)/((1+0.08)^5))+SUM(DCF!E92:DCF!I92)+DCF!D19-DCF!D20)/DCF!D48 | F22: =(((DCF!I67*10.0)/((1+0.08)^5))+SUM(DCF!E92:DCF!I92)+DCF!D19-DCF!D20)/DCF!D48 | G22: =(((DCF!I67*11.0)/((1+0.08)^5))+SUM(DCF!E92:DCF!I92)+DCF!D19-DCF!D20)/DCF!D48 | H22: =(((DCF!I67*12.0)/((1+0.08)^5))+SUM(DCF!E92:DCF!I92)+DCF!D19-DCF!D20)/DCF!D48 | I22: =(((DCF!I67*13.0)/((1+0.08)^5))+SUM(DCF!E92:DCF!I92)+DCF!D19-DCF!D20)/DCF!D48 | J22: =(((DCF!I67*14.0)/((1+0.08)^5))+SUM(DCF!E92:DCF!I92)+DCF!D19-DCF!D20)/DCF!D48
C23: 0.085 | D23: =(((DCF!I67*8.0)/((1+0.085)^5))+SUM(DCF!E92:DCF!I92)+DCF!D19-DCF!D20)/DCF!D48 | E23: =(((DCF!I67*9.0)/((1+0.085)^5))+SUM(DCF!E92:DCF!I92)+DCF!D19-DCF!D20)/DCF!D48 | F23: =(((DCF!I67*10.0)/((1+0.085)^5))+SUM(DCF!E92:DCF!I92)+DCF!D19-DCF!D20)/DCF!D48 | G23: =(((DCF!I67*11.0)/((1+0.085)^5))+SUM(DCF!E92:DCF!I92)+DCF!D19-DCF!D20)/DCF!D48 | H23: =(((DCF!I67*12.0)/((1+0.085)^5))+SUM(DCF!E92:DCF!I92)+DCF!D19-DCF!D20)/DCF!D48 | I23: =(((DCF!I67*13.0)/((1+0.085)^5))+SUM(DCF!E92:DCF!I92)+DCF!D19-DCF!D20)/DCF!D48 | J23: =(((DCF!I67*14.0)/((1+0.085)^5))+SUM(DCF!E92:DCF!I92)+DCF!D19-DCF!D20)/DCF!D48
C24: 0.09 | D24: =(((DCF!I67*8.0)/((1+0.09)^5))+SUM(DCF!E92:DCF!I92)+DCF!D19-DCF!D20)/DCF!D48 | E24: =(((DCF!I67*9.0)/((1+0.09)^5))+SUM(DCF!E92:DCF!I92)+DCF!D19-DCF!D20)/DCF!D48 | F24: =(((DCF!I67*10.0)/((1+0.09)^5))+SUM(DCF!E92:DCF!I92)+DCF!D19-DCF!D20)/DCF!D48 | G24: =(((DCF!I67*11.0)/((1+0.09)^5))+SUM(DCF!E92:DCF!I92)+DCF!D19-DCF!D20)/DCF!D48 | H24: =(((DCF!I67*12.0)/((1+0.09)^5))+SUM(DCF!E92:DCF!I92)+DCF!D19-DCF!D20)/DCF!D48 | I24: =(((DCF!I67*13.0)/((1+0.09)^5))+SUM(DCF!E92:DCF!I92)+DCF!D19-DCF!D20)/DCF!D48 | J24: =(((DCF!I67*14.0)/((1+0.09)^5))+SUM(DCF!E92:DCF!I92)+DCF!D19-DCF!D20)/DCF!D48
C25: 0.095 | D25: =(((DCF!I67*8.0)/((1+0.095)^5))+SUM(DCF!E92:DCF!I92)+DCF!D19-DCF!D20)/DCF!D48 | E25: =(((DCF!I67*9.0)/((1+0.095)^5))+SUM(DCF!E92:DCF!I92)+DCF!D19-DCF!D20)/DCF!D48 | F25: =(((DCF!I67*10.0)/((1+0.095)^5))+SUM(DCF!E92:DCF!I92)+DCF!D19-DCF!D20)/DCF!D48 | G25: =(((DCF!I67*11.0)/((1+0.095)^5))+SUM(DCF!E92:DCF!I92)+DCF!D19-DCF!D20)/DCF!D48 | H25: =(((DCF!I67*12.0)/((1+0.095)^5))+SUM(DCF!E92:DCF!I92)+DCF!D19-DCF!D20)/DCF!D48 | I25: =(((DCF!I67*13.0)/((1+0.095)^5))+SUM(DCF!E92:DCF!I92)+DCF!D19-DCF!D20)/DCF!D48 | J25: =(((DCF!I67*14.0)/((1+0.095)^5))+SUM(DCF!E92:DCF!I92)+DCF!D19-DCF!D20)/DCF!D48
C26: 0.1 | D26: =(((DCF!I67*8.0)/((1+0.1)^5))+SUM(DCF!E92:DCF!I92)+DCF!D19-DCF!D20)/DCF!D48 | E26: =(((DCF!I67*9.0)/((1+0.1)^5))+SUM(DCF!E92:DCF!I92)+DCF!D19-DCF!D20)/DCF!D48 | F26: =(((DCF!I67*10.0)/((1+0.1)^5))+SUM(DCF!E92:DCF!I92)+DCF!D19-DCF!D20)/DCF!D48 | G26: =(((DCF!I67*11.0)/((1+0.1)^5))+SUM(DCF!E92:DCF!I92)+DCF!D19-DCF!D20)/DCF!D48 | H26: =(((DCF!I67*12.0)/((1+0.1)^5))+SUM(DCF!E92:DCF!I92)+DCF!D19-DCF!D20)/DCF!D48 | I26: =(((DCF!I67*13.0)/((1+0.1)^5))+SUM(DCF!E92:DCF!I92)+DCF!D19-DCF!D20)/DCF!D48 | J26: =(((DCF!I67*14.0)/((1+0.1)^5))+SUM(DCF!E92:DCF!I92)+DCF!D19-DCF!D20)/DCF!D48

Sheet TradingComps
B2: TRADING COMPARABLES ANALYSIS
B5: Company | C5: Market Cap | D5: Enterprise Value | E5: Revenue | F5: EBITDA | G5: EV/Revenue | H5: EV/EBITDA | I5: Rev Growth
B6: Comp 1 | C6: 10000 | D6: 11000 | E6: 5000 | F6: 1000 | G6: =IFERROR(D6/E6,"") | H6: =IFERROR(D6/F6,"") | I6: 0.08
B7: Comp 2 | C7: 10000 | D7: 11000 | E7: 5000 | F7: 1000 | G7: =IFERROR(D7/E7,"") | H7: =IFERROR(D7/F7,"") | I7: 0.08
B8: Comp 3 | C8: 10000 | D8: 11000 | E8: 5000 | F8: 1000 | G8: =IFERROR(D8/E8,"") | H8: =IFERROR(D8/F8,"") | I8: 0.08
B9: Comp 4 | C9: 10000 | D9: 11000 | E9: 5000 | F9: 1000 | G9: =IFERROR(D9/E9,"") | H9: =IFERROR(D9/F9,"") | I9: 0.08
B10: Comp 5 | C10: 10000 | D10: 11000 | E10: 5000 | F10: 1000 | G10: =IFERROR(D10/E10,"") | H10: =IFERROR(D10/F10,"") | I10: 0.08
B11: Comp 6 | C11: 10000 | D11: 11000 | E11: 5000 | F11: 1000 | G11: =IFERROR(D11/E11,"") | H11: =IFERROR(D11/F11,"") | I11: 0.08
B12: Comp 7 | C12: 10000 | D12: 11000 | E12: 5000 | F12: 1000 | G12: =IFERROR(D12/E12,"") | H12: =IFERROR(D12/F12,"") | I12: 0.08
B13: Comp 8 | C13: 10000 | D13: 11000 | E13: 5000 | F13: 1000 | G13: =IFERROR(D13/E13,"") | H13: =IFERROR(D13/F13,"") | I13: 0.08
B15: SUMMARY STATISTICS
B16: Mean | G16: =AVERAGE(G6:G13) | H16: =AVERAGE(H6:H13)
B17: Median | G17: =MEDIAN(G6:G13) | H17: =MEDIAN(H6:H13)
B18: 25th Percentile | G18: =QUARTILE(G6:G13,1) | H18: =QUARTILE(H6:H13,1)
B19: 75th Percentile | G19: =QUARTILE(G6:G13,3) | H19: =QUARTILE(H6:H13,3)
B21: IMPLIED VALUATION OF TARGET
B22: Target Revenue (LTM): | C22: =DCF!D63
B23: Target EBITDA (LTM): | C23: =DCF!D67
B24: Implied EV (Median EV/EBITDA): | C24: =C27*H17
B25: (+) Cash | C25: =DCF!D19
B26: (-) Debt | C26: =-DCF!D20
B27: Equity Value: | C27: =SUM(C28:C30)
B28: Implied Price per Share: | C28: =C31/DCF!D48

Sheet PrecedentTxns
B2: PRECEDENT TRANSACTIONS ANALYSIS
B5: Date | C5: Target | D5: Acquirer | E5: Deal Value | F5: Revenue | G5: EBITDA | H5: EV/Revenue | I5: EV/EBITDA
B6: 12/31/2024 | C6: Target 1 | D6: Acquirer 1 | E6: 5000 | F6: 4000 | G6: 800 | H6: =IFERROR(E6/F6,"") | I6: =IFERROR(E6/G6,"")
B7: 12/31/2024 | C7: Target 2 | D7: Acquirer 2 | E7: 5000 | F7: 4000 | G7: 800 | H7: =IFERROR(E7/F7,"") | I7: =IFERROR(E7/G7,"")
B8: 12/31/2024 | C8: Target 3 | D8: Acquirer 3 | E8: 5000 | F8: 4000 | G8: 800 | H8: =IFERROR(E8/F8,"") | I8: =IFERROR(E8/G8,"")
B9: 12/31/2024 | C9: Target 4 | D9: Acquirer 4 | E9: 5000 | F9: 4000 | G9: 800 | H9: =IFERROR(E9/F9,"") | I9: =IFERROR(E9/G9,"")
B10: 12/31/2024 | C10: Target 5 | D10: Acquirer 5 | E10: 5000 | F10: 4000 | G10: 800 | H10: =IFERROR(E10/F10,"") | I10: =IFERROR(E10/G10,"")
B11: 12/31/2024 | C11: Target 6 | D11: Acquirer 6 | E11: 5000 | F11: 4000 | G11: 800 | H11: =IFERROR(E11/F11,"") | I11: =IFERROR(E11/G11,"")
B12: 12/31/2024 | C12: Target 7 | D12: Acquirer 7 | E12: 5000 | F12: 4000 | G12: 800 | H12: =IFERROR(E12/F12,"") | I12: =IFERROR(E12/G12,"")
B13: 12/31/2024 | C13: Target 8 | D13: Acquirer 8 | E13: 5000 | F13: 4000 | G13: 800 | H13: =IFERROR(E13/F13,"") | I13: =IFERROR(E13/G13,"")
B15: SUMMARY STATISTICS
B16: Mean | H16: =AVERAGE(H6:H13) | I16: =AVERAGE(I6:I13)
B17: Median | H17: =MEDIAN(H6:H13) | I17: =MEDIAN(I6:I13)
B18: 25th Percentile | H18: =QUARTILE(H6:H13,1) | I18: =QUARTILE(I6:I13,1)
B19: 75th Percentile | H19: =QUARTILE(H6:H13,3) | I19: =QUARTILE(I6:I13,3)
B21: IMPLIED VALUATION OF TARGET
B22: Target EBITDA (LTM): | C22: =DCF!D67
B23: Implied EV (Median): | C23: =C26*I17
B24: (+) Cash: | C24: =DCF!D19
B25: (-) Debt: | C25: =-DCF!D20
B26: Equity Value: | C26: =SUM(C27:C29)
B27: Implied Price per Share: | C27: =C30/DCF!D48

Sheet CreditAnalysis
C2: CREDIT ANALYSIS & LEVERAGE RATIOS
C5: Metric | D5: LTM | E5: Year 1 | F5: Year 2 | G5: Year 3 | H5: Year 4 | I5: Year 5
C7: LEVERAGE RATIOS
C8: Total Debt / EBITDA | D8: =DCF!D20/DCF!D67 | E8: =DCF!D20/DCF!E67 | F8: =DCF!D20/DCF!F67 | G8: =DCF!D20/DCF!G67 | H8: =DCF!D20/DCF!H67 | I8: =DCF!D20/DCF!I67
C9: Net Debt / EBITDA | D9: =(DCF!D20-DCF!D19)/DCF!D67 | E9: =(DCF!D20-DCF!D19)/DCF!E67 | F9: =(DCF!D20-DCF!D19)/DCF!F67 | G9: =(DCF!D20-DCF!D19)/DCF!G67 | H9: =(DCF!D20-DCF!D19)/DCF!H67 | I9: =(DCF!D20-DCF!D19)/DCF!I67
C11: COVERAGE RATIOS
C12: EBITDA / Interest | D12: =DCF!D67/(DCF!D20*WACC!F15) | E12: =DCF!E67/(DCF!D20*WACC!F15) | F12: =DCF!F67/(DCF!D20*WACC!F15) | G12: =DCF!G67/(DCF!D20*WACC!F15) | H12: =DCF!H67/(DCF!D20*WACC!F15) | I12: =DCF!I67/(DCF!D20*WACC!F15)
C13: EBIT / Interest | D13: =DCF!D70/(DCF!D20*WACC!F15) | E13: =DCF!E70/(DCF!D20*WACC!F15) | F13: =DCF!F70/(DCF!D20*WACC!F15) | G13: =DCF!G70/(DCF!D20*WACC!F15) | H13: =DCF!H70/(DCF!D20*WACC!F15) | I13: =DCF!I70/(DCF!D20*WACC!F15)
C14: FCF / Interest | D14: =DCF!D84/(DCF!D20*WACC!F15) | E14: =DCF!E84/(DCF!D20*WACC!F15) | F14: =DCF!F84/(DCF!D20*WACC!F15) | G14: =DCF!G84/(DCF!D20*WACC!F15) | H14: =DCF!H84/(DCF!D20*WACC!F15) | I14: =DCF!I84/(DCF!D20*WACC!F15)
C16: IMPLIED CREDIT RATING
C17: S&P Equivalent Rating | D17: =IF(D10<2,"AAA",IF(D10<3,"AA",IF(D10<4,"A",IF(D10<5,"BBB",IF(D10<6,"BB","B")))))

Sheet Scenarios
C2: SCENARIO ANALYSIS
C5: Key Assumptions | D5: Bear Case | E5: Base Case | F5: Bull Case
C6: Revenue CAGR (Y1-5) | D6: 0.05 | E6: 0.08 | F6: 0.12
C7: EBITDA Margin (Year 5) | D7: 0.2 | E7: 0.25 | F7: 0.3
C8: Terminal Growth Rate | D8: 0.02 | E8: 0.025 | F8: 0.03
C9: WACC | D9: 0.095 | E9: 0.085 | F9: 0.075
C12: VALUATION OUTPUTS
C13: Implied Share Price | D13: =DCF!D32*0.70 | E13: =DCF!D32 | F13: =DCF!D32*1.30
C14: Upside / (Downside) | D14: =D13/DCF!D10-1 | E14: =E13/DCF!D10-1 | F14: =F13/DCF!D10-1
C17: PROBABILITY WEIGHTING
C18: Probability | D18: 0.25 | E18: 0.5 | F18: 0.25
C19: Weighted Price | D19: =D13*D18 | E19: =E13*E18 | F19: =F13*F18
C21: Probability-Weighted Price: | D21: =SUM(D19:F19)

Sheet Historicals
C2: HISTORICAL FINANCIAL STATEMENTS
C5: Item | D5: Year -4 | E5: Year -3 | F5: Year -2 | G5: Year -1 | H5: LTM
C7: INCOME STATEMENT
C8: Revenue | D8: 4000 | E8: 4000 | F8: 4000 | G8: 4000 | H8: 4000
C9: Revenue Growth % | E9: =E8/D8-1 | F9: =F8/E8-1 | G9: =G8/F8-1 | H9: =H8/G8-1
C11: EBITDA | D11: 800 | E11: 800 | F11: 800 | G11: 800 | H11: 800
C12: EBITDA Margin % | D12: =D11/D8 | E12: =E11/E8 | F12: =F11/F8 | G12: =G11/G8 | H12: =H11/H8
C14: Net Income | D14: 500 | E14: 500 | F14: 500 | G14: 500 | H14: 500
C15: Net Margin % | D15: =D14/D8 | E15: =E14/E8 | F15: =F14/F8 | G15: =G14/G8 | H15: =H14/H8
C18: BALANCE SHEET
C19: Total Assets | D19: 6000 | E19: 6000 | F19: 6000 | G19: 6000 | H19: 6000
C20: Total Liabilities | D20: 3000 | E20: 3000 | F20: 3000 | G20: 3000 | H20: 3000
C21: Shareholders Equity | D21: =D19-D20 | E21: =E19-E20 | F21: =F19-F20 | G21: =G19-G20 | H21: =H19-H20
C24: CASH FLOW STATEMENT
C25: Operating Cash Flow | D25: 900 | E25: 900 | F25: 900 | G25: 900 | H25: 900
C26: Capital Expenditures | D26: -200 | E26: -200 | F26: -200 | G26: -200 | H26: -200
C27: Free Cash Flow | D27: =D25+D26 | E27: =E25+E26 | F27: =F25+F26 | G27: =G25+G26 | H27: =H25+H26
