Workbook

Sheet Executive Summary
A1: HOUSE FLIPPING MODEL
A2: Executive Summary Dashboard
A4: PROPERTY INFORMATION | D4: KEY DEAL METRICS | G4: RETURN METRICS
A5: Property Address: | B5: =Inputs!B5 -> 123 Main Street, Anytown, USA | D5: Purchase Price: | E5: =Inputs!B13 -> 150000 | G5: Gross Profit: | H5: ='Deal Analysis'!E15 -> 0
A6: Property Type: | B6: =Inputs!B6 -> Single Family Home | D6: After Repair Value (ARV): | E6: ='Deal Analysis'!E6 -> From Inputs sheet | G6: ROI: | H6: ='Deal Analysis'!E16 -> 0
A7: Square Footage: | B7: =Inputs!B7 -> 1800 | D7: Total Renovation Cost: | E7: ='Renovation Budget'!C50 -> 800 | G7: 70% Rule Check: | H7: ='Deal Analysis'!E21 -> 0
A8: Bedrooms / Baths: | B8: =Inputs!B8&" / "&Inputs!B9 -> 3 / 2 | D8: All-In Cost: | E8: ='Deal Analysis'!E10 -> 0 | G8: Deal Quality: | H8: ='Deal Analysis'!E22 -> 0
A13: PROJECT TIMELINE
A14: Acquisition Period: | B14: =Inputs!B34 -> 200 | C14: days | D14: Renovation Period: | E14: =Inputs!B35 -> 0 | F14: days | G14: Marketing Period: | H14: =Inputs!B36 -> 0 | I14: days
A15: Total Hold Period: | B15: =Inputs!B34+Inputs!B35+Inputs!B36 -> 200 | C15: days

Sheet Inputs
A1: INPUTS & ASSUMPTIONS
A2: All BLUE cells are inputs - Change these to match your deal
A4: PROPERTY INFORMATION
A5: Property Address | B5: 123 Main Street, Anytown, USA
A6: Property Type | B6: Single Family Home
A7: Square Footage | B7: 1800
A8: Bedrooms | B8: 3
A9: Bathrooms | B9: 2
A10: Year Built | B10: 1975
A12: ACQUISITION COSTS
A13: Purchase Price | B13: 150000
A14: Closing Costs (% of Purchase) | B14: 0.025 | C14: =B13*B14 -> 3750
A15: Inspection Cost | B15: 500
A16: Due Diligence Costs | B16: 1000
A18: RENOVATION BUDGET ASSUMPTIONS
A19: Renovation Type | B19: Full Renovation | C19: Cosmetic / Full / Gut
A20: Estimated Total Renovation Cost | B20: 45000
A21: Contingency Reserve (% of Reno) | B21: 0.1
A23: AFTER REPAIR VALUE (ARV)
A24: Comp #1 Sale Price | B24: 285000
A25: Comp #2 Sale Price | B25: 295000
A26: Comp #3 Sale Price | B26: 290000
A27: Average Comp Value | B27: =AVERAGE(B23:B25) -> 290000
A28: Conservative Discount | B28: 0.02 | C28: Safety margin
A29: Your ARV Estimate | B29: =B26*(1-B27) -> -84099710000
A31: HOLDING COSTS
A32: Property Insurance (monthly) | B32: 150
A33: Property Taxes (monthly) | B33: 250
A34: Utilities (monthly) | B34: 200
A35: HOA Dues (if applicable, monthly) | B35: 0
A37: PROJECT TIMELINE
A38: Acquisition Period (days) | B38: 30 | C38: =B37/30 -> 0
A39: Renovation Period (days) | B39: 90
A40: Marketing & Sale Period (days) | B40: 60
A41: Total Hold Period (days) | B41: =B34+B35+B36 -> 200 | C41: =B37/30&" months" -> 0 months
A43: SELLING COSTS
A44: Real Estate Commission (%) | B44: 0.06
A45: Closing Costs (% of Sale Price) | B45: 0.015
A46: Staging & Photography | B46: 2000
A48: FINANCING ASSUMPTIONS
...

Sheet Deal Analysis
A1: DEAL ANALYSIS
A2: 70% Rule, MAO Calculation & Profitability Analysis
A4: AFTER REPAIR VALUE (ARV) ANALYSIS
D5: Value | E5: Note
A6: After Repair Value (ARV) | D6: =Inputs!B28 -> 0.02 | E6: From Inputs sheet
A8: TOTAL PROJECT COSTS
A9: Purchase Price | D9: =Inputs!B13 -> 150000
A10: Acquisition Closing Costs | D10: =Inputs!C14+Inputs!B15+Inputs!B16 -> 5250
A11: Renovation Costs (with contingency) | D11: =IF(D10=0,0,D10) -> 5250 | E11: Base + reserve
A12: Holding Costs (monthly × months) | D12: =(Inputs!B30+Inputs!B31+Inputs!B32+Inputs!B33)*(Inputs!B37/30) -> 0 | E12: Insurance, taxes, utilities
A13: All-In Cost | D13: =SUM(D7:D9) -> 150000
A14: Cash/Equity Required | D14: =D10 -> 5250 | E14: For cash deal
A16: SELLING ANALYSIS
A17: Total Selling Costs | D17: =D6*(Inputs!B40+Inputs!B41)+Inputs!B42 -> 5.2 | E17: Commission + closing + staging
A18: Net Sales Proceeds | D18: =D6-D13 -> -149999.98
A19: Gross Profit | D19: =D14-D10 -> 0
A20: Return on Investment (ROI) | D20: =Inputs!B13 -> 150000 | E20: Profit / Equity
A22: 70% RULE CHECK
A23: Maximum Allowable Offer (MAO) Formula: | D23: ARV × 70% - Repair Costs
A24: MAO Calculation | D24: =D6*Inputs!B52-D9 -> -150000 | E24: Max you should pay
A25: Your Purchase Price | D25: =D7 -> 0
A26: 70% Rule Result | D26: =IF(Inputs!B7=0,0,D9/Inputs!B7) -> 83.333333 | E26: Pass if under MAO
A27: Deal Quality Rating | D27: =IF(D16>=0.25,"EXCELLENT",IF(D16>=0.2,"GOOD",IF(D16>=0.15,"ACCEPTABLE","WEAK"))) -> WEAK | E27: Based on ROI
A29: DETAILED METRICS
A30: Purchase Price per SF | D30: =D7/Inputs!B7 -> 0
A31: ARV per SF | D31: =D6/Inputs!B7 -> 1.1111111e-05
A32: Renovation Cost per SF | D32: =D9/Inputs!B7 -> 83.333333
A33: Profit per SF | D33: =D15/Inputs!B7 -> 0
A34: Profit Margin (% of ARV) | D34: =D15/D6 -> 0
A35: Profit per Day Held | B35: =IF(D16="",0,D16) -> 0 | D35: =IFERROR(D16,0) -> 0
A36: Total Hold Period | D36: =Inputs!B37 -> 0 | E36: days
A38: PROFITABILITY BENCHMARKS
A39: Metric | B39: Your Deal | C39: Market Avg | D39: Status
A40: Gross Profit | B40: =D15 -> 0 | C40: 50000 | D40: =IF(B34>=C34,"Above ✓","Below ⚠") -> Above ✓
A41: ROI | B41: =D16 -> 0 | C41: 0.2 | D41: =IF(B35>=C35,"Above ✓","Below ⚠") -> Above ✓
A42: Profit Margin | B42: =D28 -> 0 | C42: 0.15 | D42: =IF(B36>=C36,"Above ✓","Below ⚠") -> Above ✓
A44: DEAL RECOMMENDATION
A45: =IF(AND(D21="PASS ✓",D16>=Inputs!B51),"PROCEED WITH DEAL - Meets 70% rule and ROI targets","CAUTION - Review assumptions carefully") -> CAUTION - Review assumptions carefully

Sheet Renovation Budget
A1: RENOVATION BUDGET
A2: Detailed Line-Item Breakdown by Category
A4: Category | B4: Item Description | C4: Cost | D4: Notes
A5: KITCHEN
B6: Cabinets (paint or replace) | C6: 4500 | D6: Paint: $2k, Replace: $5-10k
B7: Countertops | C7: 2500 | D7: Granite/Quartz
B8: Appliances (stove, fridge, dishwasher, microwave) | C8: 2800 | D8: Mid-grade stainless
B9: Sink & Faucet | C9: 600
B10: Backsplash | C10: 800 | D10: Tile/subway tile
B11: Lighting Fixtures | C11: 400
B12: Kitchen Subtotal | C12: =SUM(C6:C11) -> 11600
A14: BATHROOMS
B15: Vanity & Sink | C15: 1200 | D15: Per bathroom
B16: Toilet | C16: 400 | D16: Per bathroom
B17: Tub/Shower | C17: 1800 | D17: Refinish or replace
B18: Tile (floor & shower) | C18: 2000
B19: Fixtures & Faucets | C19: 600
B20: Lighting & Ventilation | C20: 500
B21: Bathrooms Subtotal | C21: =SUM(C15:C20) -> 6500
A23: FLOORING
B24: Hardwood/LVP Main Living Areas | C24: 4500 | D24: $4-6/SF installed
B25: Carpet Bedrooms | C25: 2000 | D25: $2-3/SF installed
B26: Tile (baths/entry) | C26: 1500
B27: Flooring Subtotal | C27: =SUM(C24:C26) -> 8000
A29: PAINT & FINISHES
B30: Interior Paint (entire house) | C30: 3500 | D30: $1.50-2.50/SF
B31: Exterior Paint | C31: 2500
B32: Trim & Baseboards | C32: 1200
B33: Paint Subtotal | C33: =SUM(C30:C32) -> 7200
A35: SYSTEMS & MECHANICALS
B36: HVAC (repair or replace) | C36: 3000 | D36: Replace: $5-8k
B37: Plumbing Repairs | C37: 1500
B38: Electrical Updates | C38: 2000
B39: Water Heater | C39: 1200
B40: Systems Subtotal | C40: =SUM(C36:C39) -> 7700
A42: EXTERIOR & LANDSCAPING
B43: Roof Repairs/Replacement | C43: 2000 | D43: Full replace: $8-12k
B44: Landscaping & Yard Cleanup | C44: 1500
B45: Driveway/Walkway | C45: 800
B46: Fence (if needed) | C46: 0
...

Sheet ProForma
A1: MONTHLY CASH FLOW PROFORMA
A2: Month-by-Month Cash Flow from Acquisition to Sale
A4: Month | B4: Phase | C4: Cash Out | D4: Cash In | E4: Net Cash Flow | F4: Cumulative | G4: Balance | H4: Notes
A5: 0 | B5: Acquisition | C5: =Inputs!B13+Inputs!C14+Inputs!B15+Inputs!B16 -> 155250 | D5: 0 | E5: =-C5 -> -155250 | F5: =E5 -> -155250 | G5: =F5 -> -155250 | H5: Purchase + closing costs
A6: 1 | B6: Renovation | C6: =('Renovation Budget'!C56/3)+(Inputs!B30+Inputs!B31+Inputs!B32+Inputs!B33) -> 400 | D6: 0 | E6: =-C6 -> -400 | F6: =F5+E6 -> -155650 | G6: =F6 -> -155650 | H6: 1/3 reno + holding costs
A7: 2 | B7: Renovation | C7: =('Renovation Budget'!C56/3)+(Inputs!B30+Inputs!B31+Inputs!B32+Inputs!B33) -> 400 | D7: 0 | E7: =-C7 -> -400 | F7: =F6+E7 -> -156050 | G7: =F7 -> -156050 | H7: 1/3 reno + holding costs
A8: 3 | B8: Renovation | C8: =('Renovation Budget'!C56/3)+(Inputs!B30+Inputs!B31+Inputs!B32+Inputs!B33) -> 400 | D8: 0 | E8: =-C8 -> -400 | F8: =F7+E8 -> -156450 | G8: =F8 -> -156450 | H8: Final 1/3 reno + holding
A9: 4 | B9: Marketing | C9: =(Inputs!B30+Inputs!B31+Inputs!B32+Inputs!B33)+Inputs!B42 -> 400 | D9: 0 | E9: =-C9 -> -400 | F9: =F8+E9 -> -156850 | G9: =F9 -> -156850 | H9: Staging + holding costs
A10: 5 | B10: Marketing | C10: =Inputs!B30+Inputs!B31+Inputs!B32+Inputs!B33 -> 400 | D10: 0 | E10: =-C10 -> -400 | F10: =F9+E10 -> -157250 | G10: =F10 -> -157250 | H10: Holding costs only
A11: 6 | B11: SALE | C11: ='Deal Analysis'!D13 -> 150000 | D11: =Inputs!B28 -> 0.02 | E11: =D11-C11 -> -149999.98 | F11: =F10+E11 -> -307249.98 | G11: =F11 -> -307249.98 | H11: ARV sale - selling costs
A14: CASH FLOW SUMMARY
A15: Total Cash Out | B15: =SUM(C5:C11) -> 307250
A16: Total Cash In | B16: =SUM(D5:D11) -> 0.02
A17: Net Profit (before financing) | B17: =B16-B15 -> -307249.98
A19: Maximum Capital Required | B19: =MIN(F5:F11) -> -307249.98 | C19: Peak negative cash
A20: Months to Break Even | B20: 6 | C20: At sale
A21: Annualized Return | B21: =(B17/ABS(B19))*(12/6) -> -2 | C21: If 6-month project
A24: COST BREAKDOWN BY PHASE
A25: Phase | B25: Duration | C25: Total Cost | D25: % of Total
A26: Acquisition | B26: 1 month | C26: =C5 -> 155250 | D26: =C26/B15 -> 0.50528885
A27: Renovation | B27: 3 months | C27: =SUM(C6:C8) -> 1200 | D27: =C27/B15 -> 0.0039056143
A28: Marketing | B28: 2 months | C28: =SUM(C9:C10) -> 800 | D28: =C28/B15 -> 0.0026037429
A29: Selling Costs | B29: At close | C29: =C11 -> 150000 | D29: =C28/B15 -> 0.0026037429
A30: TOTAL | C30: =SUM(C25:C28) -> 157250 | D30: =SUM(D25:D28) -> 0.51179821

Sheet Financing Comparison
A1: FINANCING STRATEGY COMPARISON
A2: Compare Cash, Hard Money, Private Money & BRRRR Strategies
A4: Metric | B4: All Cash | C4: Hard Money | D4: Private Money | E4: BRRRR
A5: PROJECT COSTS
A6: Purchase Price | B6: =Inputs!B13 -> 150000 | C6: =Inputs!B13 -> 150000 | D6: =Inputs!B13 -> 150000 | E6: =Inputs!B13 -> 150000
A7: Closing Costs | B7: =Inputs!C14 -> 3750 | C7: =Inputs!C14 -> 3750 | D7: =Inputs!C14 -> 3750 | E7: =Inputs!C14 -> 3750
A8: Renovation Cost | B8: ='Renovation Budget'!C56 -> 0 | C8: ='Renovation Budget'!C56 -> 0 | D8: ='Renovation Budget'!C56 -> 0 | E8: ='Renovation Budget'!C56 -> 0
A9: Total Project Cost | B9: =SUM(B6:B8) -> 153750 | C9: =SUM(C6:C8) -> 153750 | D9: =SUM(D6:D8) -> 153750 | E9: =SUM(E6:E8) -> 153750
A11: FINANCING STRUCTURE
A12: Loan Amount | B12: 0 | C12: =B9*Inputs!B44 -> 9225 | D12: =B9*0.7 -> 107625 | E12: =B9*0.75 -> 115312.5
A13: Loan-to-Cost (LTC) | B13: 0 | C13: =C12/C9 -> 0.06 | D13: =D12/D9 -> 0.7 | E13: =E12/E9 -> 0.75
A14: Cash/Equity Required | B14: =B9-B12 -> 153750 | C14: =C9-C12 -> 144525 | D14: =D9-D12 -> 46125 | E14: =E9-E12 -> 38437.5
A16: FINANCING COSTS
A17: Interest Rate (Annual) | B17: 0 | C17: =Inputs!B45 -> 0.015 | D17: =Inputs!B47 -> 0 | E17: =Inputs!B47 -> 0
A18: Points/Origination Fee | B18: 0 | C18: =C12*Inputs!B46 -> 18450000 | D18: 0 | E18: 0
A19: Interest Cost (6 months) | B19: 0 | C19: =C12*C17*(6/12) -> 69.1875 | D19: =D12*D17*(6/12) -> 0 | E19: =E12*E17*(6/12) -> 0
A20: Total Financing Cost | B20: =B18+B19 -> 0 | C20: =C18+C19 -> 18450069 | D20: =D18+D19 -> 0 | E20: =E18+E19 -> 0
A22: EXIT & RETURNS
A23: Sale Price (ARV) | B23: =Inputs!B28 -> 0.02 | C23: =Inputs!B28 -> 0.02 | D23: =Inputs!B28 -> 0.02 | E23: =Inputs!B28*0.75 -> 0.015
A24: Selling Costs | B24: ='Deal Analysis'!D13 -> 150000 | C24: ='Deal Analysis'!D13 -> 150000 | D24: ='Deal Analysis'!D13 -> 150000 | E24: 0
A25: Loan Payoff | B25: 0 | C25: =C12 -> 9225 | D25: =D12 -> 107625 | E25: =E12 -> 115312.5
A26: Net Proceeds | B26: =B23-B24-B25 -> -149999.98 | C26: =C23-C24-C25 -> -159224.98 | D26: =D23-D24-D25 -> -257624.98 | E26: =E23-E24-E25 -> -115312.49
A27: Total Cash Invested | B27: =B9+'Deal Analysis'!D9 -> 303750 | C27: =C14+'Deal Analysis'!D9+C20 -> 18744594 | D27: =D14+'Deal Analysis'!D9+D20 -> 196125 | E27: =E14+'Deal Analysis'!D9+E20 -> 188437.5
A28: Net Profit | B28: =B26-B27 -> -453749.98 | C28: =C26-C27 -> -18903819 | D28: =D26-D27 -> -453749.98 | E28: =E26-E27 -> -303749.98
A29: ROI (Return on Investment) | B29: =B28/B27 -> -1.4938271 | C29: =C28/C27 -> -1.0084944 | D29: =D28/D27 -> -2.3135754 | E29: =E28/E27 -> -1.6119402
A30: Annualized Return | B30: =B29*2 -> -2.9876542 | C30: =C29*2 -> -2.0169889 | D30: =D29*2 -> -4.6271508 | E30: =E29*2 -> -3.2238804
A33: STRATEGY COMPARISON
A34: Best For:
B35: Maximum profit per deal | C35: Fast close, limited capital | D35: Lower cost capital | E35: Build rental portfolio
A36: Pros:
B37: • No interest costs | C37: • Quick approval | D37: • Lower rates | E37: • Keep property
B38: • Highest ROI | C38: • 75% LTC typical | D38: • Relationship-based | E38: • Cash-out equity
B39: • Simple structure | C39: • No income docs | D39: • Flexible terms | E39: • Monthly income
A40: Cons:
B41: • Ties up capital | C41: • High interest (10%+) | D41: • Requires network | E41: • Landlord duties
B42: • Limits deal flow | C42: • Points upfront (3%) | D42: • Takes longer | E42: • Not quick cash
B43: • Opportunity cost | C43: • Short-term (6-12mo) | D43: • May be limited | E43: • Market risk
A45: RECOMMENDED STRATEGY
A46: =IF(B29>C29,IF(B29>D29,"ALL CASH - Highest ROI","PRIVATE MONEY"),IF(C29>D29,"HARD MONEY - Leverage advantage","PRIVATE MONEY")) -> HARD MONEY - Leverage advantage

Sheet Sensitivity Analysis
A1: SENSITIVITY ANALYSIS
A2: Test Best Case, Base Case & Worst Case Scenarios
A4: SCENARIO ASSUMPTIONS
A5: Variable | B5: Worst Case | C5: % Change | D5: Base Case | E5: % Change | F5: Best Case | G5: Notes
A6: After Repair Value (ARV) | B6: =Inputs!B28*0.9 -> 0.018 | C6: -10% | D6: =Inputs!B28 -> 0.02 | E6: 0% | F6: =Inputs!B28*1.05 -> 0.021 | G6: ARV lower/higher than expected
A7: Renovation Cost | B7: ='Renovation Budget'!C56*1.2 -> 0 | C7: +20% | D7: ='Renovation Budget'!C56 -> 0 | E7: 0% | F7: ='Renovation Budget'!C56*0.95 -> 0 | G7: Overruns vs under budget
A8: Hold Period (months) | B8: 9 | C8: +50% | D8: 6 | E8: 0% | F8: 4 | G8: Time to sell (affects holding costs)
A9: Purchase Price | B9: =Inputs!B13 -> 150000 | C9: 0% | D9: =Inputs!B13 -> 150000 | E9: 0% | F9: =Inputs!B13 -> 150000 | G9: Fixed - already purchased
A11: SCENARIO RESULTS
A12: Metric | B12: Worst Case | C12: vs Base | D12: Base Case | E12: vs Base | F12: Best Case | G12: Analysis
A13: All-In Cost | B13: =B9+Inputs!C14+B7+((Inputs!B30+Inputs!B31+Inputs!B32+Inputs!B33)*B8) -> 157350 | C13: =(B13-D13)/D13 -> 28.971429 | D13: ='Deal Analysis'!D10 -> 5250 | E13: =(F13-D13)/D13 -> 28.590476 | F13: =F9+Inputs!C14+F7+((Inputs!B30+Inputs!B31+Inputs!B32+Inputs!B33)*F8) -> 155350
A14: Selling Costs | B14: =B6*(Inputs!B40+Inputs!B41)+Inputs!B42 -> 4.68 | C14: =(B14-D14)/D14 -> -0.9999688 | D14: ='Deal Analysis'!D13 -> 150000 | E14: =(F14-D14)/D14 -> -0.9999636 | F14: =F6*(Inputs!B40+Inputs!B41)+Inputs!B42 -> 5.46
A15: Net Sales Proceeds | B15: =B6-B14 -> -4.662 | C15: =(B15-D15)/D15 -> -1.000888 | D15: ='Deal Analysis'!D14 -> 5250 | E15: =(F15-D15)/D15 -> -1.001036 | F15: =F6-F14 -> -5.439
A16: Gross Profit | B16: =B15-B13 -> -157354.66 | C16: =IFERROR((B16-D16)/D16,0) -> 0 | D16: ='Deal Analysis'!D15 -> 0 | E16: =IFERROR((F16-D16)/D16,0) -> 0 | F16: =F15-F13 -> -155355.44
A17: ROI | B17: =B16/B13 -> -1.0000296 | C17: =B17-D17 -> -1.0000296 | D17: ='Deal Analysis'!D16 -> 0 | E17: =F17-D17 -> -1.000035 | F17: =F16/F13 -> -1.000035
A18: Profit Margin | B18: =B16/B6 -> -8741925.7 | C18: =B18-D18 -> -8741925.7 | D18: ='Deal Analysis'!D28 -> 0 | E18: =F18-D18 -> -7397878 | F18: =F16/F6 -> -7397878
A21: RISK ASSESSMENT
A22: Can you afford worst case? | B22: =IF(B16>0,"YES - Still profitable","NO - Would lose money") -> NO - Would lose money
A23: Minimum acceptable profit? | B23: =IF(B16>=Inputs!B50,"YES - Exceeds minimum","NO - Below minimum") -> NO - Below minimum
A24: Deal quality in worst case? | B24: =IF(B17>=0.15,"ACCEPTABLE",IF(B17>=0.1,"MARGINAL","RISKY")) -> RISKY
A25: Upside potential? | B25: =F16-D16 -> -155355.44 | C25: Additional profit in best case
A26: Downside risk? | B26: =D16-B16 -> 157354.66 | C26: Profit reduction in worst case
A29: BREAKEVEN ANALYSIS
A30: Breakeven ARV | B30: =(B13+B14)/(1-(Inputs!B40+Inputs!B41)) -> -607.54703 | C30: Min ARV to break even
A31: Margin of Safety (ARV) | B31: =(D6-B26)/D6 -> -7867732.1 | C31: % ARV can drop before losing money
A32: Max Renovation Overrun | B32: =D16/0.8 -> 0 | C32: Max budget before unprofitable
A33: Renovation Safety Margin | B33: =IFERROR((B28-D7)/D7,0) -> 0 | C33: % budget can overrun
A36: OVERALL ASSESSMENT
A37: =IF(AND(B16>0,B17>=0.1),"DEAL HAS ACCEPTABLE RISK - Even worst case is profitable","HIGH RISK - Worst case results in loss or minimal profit") -> HIGH RISK - Worst case results in loss or minimal profit
A38: =IF(B27>0.15,"STRONG MARGIN OF SAFETY on ARV","THIN MARGINS - Small ARV drop = loss") -> THIN MARGINS - Small ARV drop = loss

Sheet Exit Strategies
A1: EXIT STRATEGY COMPARISON
A4: Strategy | B4: Flip | C4: BRRRR | D4: Rental | E4: Seller Finance
A5: Cash Out | B5: ='Deal Analysis'!D15 -> 0 | C5: =Inputs!B28*0.75*0.25 -> 0.00375 | D5: 0 | E5: =Inputs!B28*0.1 -> 0.002
A6: Monthly Income | B6: 0 | C6: =Inputs!B28*0.0075 -> 0.00015 | D6: =Inputs!B28*0.0075 -> 0.00015 | E6: =Inputs!B28*0.005 -> 0.0001
A7: ROI Year 1 | B7: ='Deal Analysis'!D16 -> 0 | C7: =IFERROR((C6*12)/'Deal Analysis'!D10,0) -> 3.4285714e-07 | D7: =IFERROR((D6*12)/'Deal Analysis'!D10,0) -> 3.4285714e-07 | E7: =(E6*12)/E5 -> 0.6
A9: Best For:
B10: Quick profit | C10: Scale portfolio | D10: Passive income | E10: Slow market
