Workbook

Sheet Executive Summary
B2: LEVERAGED BUYOUT MODEL
B3: Executive Summary & Investment Returns
B6: COMPANY INFORMATION | E6: RETURNS TO EQUITY
B7: Company Name: | C7: ='Transaction Assumptions'!C7
B8: Industry: | C8: ='Transaction Assumptions'!C8 | E8: Exit Enterprise Value | F8: ='Returns Analysis'!C35
B9: Transaction Date: | C9: ='Transaction Assumptions'!C9 | E9: Less: Net Debt at Exit | F9: ='Returns Analysis'!C36
B10: Exit Date (Assumed): | C10: ='Transaction Assumptions'!C10 | E10: Exit Equity Value | F10: ='Returns Analysis'!C37
E12: Initial Equity Investment | F12: ='Returns Analysis'!C15
B13: INVESTMENT SUMMARY | E13: Ending Equity Value | F13: ='Returns Analysis'!C37
B15: Purchase Price (Enterprise Value) | C15: ='Sources & Uses'!C21 | E15: Equity IRR to Sponsor | F15: ='Returns Analysis'!C42
B16: Total Debt | C16: ='Sources & Uses'!C15 | E16: Equity Multiple (MOIC) | F16: ='Returns Analysis'!C43
B17: Sponsor Equity | C17: ='Sources & Uses'!C17 | E17: Total Equity Cash Return | F17: ='Returns Analysis'!C44
B18: Management Rollover | C18: ='Sources & Uses'!C18 | E18: Total % Return | F18: ='Returns Analysis'!C45
B20: Entry EV / EBITDA Multiple | C20: ='Transaction Assumptions'!C13 | E20: KEY CREDIT METRICS
B21: Entry Leverage (Debt / EBITDA) | C21: ='Transaction Assumptions'!C24
B22: Equity % of Purchase Price | C22: =C17/C15 | E22: Leverage at Entry (Debt/EBITDA) | F22: ='Transaction Assumptions'!C24
E23: Leverage at Exit (Debt/EBITDA) | F23: ='Financial Statements'!K56
E25: Interest Coverage at Entry | F25: ='Transaction Assumptions'!C25
E26: Min. Interest Coverage (Y1-Y5) | F26: =MIN('Financial Statements'!G57:K57)
E28: Total Debt Paydown | F28: ='Returns Analysis'!C25

Sheet Transaction Assumptions
B2: TRANSACTION ASSUMPTIONS
B3: Entry Valuation & Deal Structure
B5: COMPANY INFORMATION
B7: Company Name: | C7: Target Company Inc.
B8: Industry: | C8: Consumer Products
B9: Transaction Date: | C9: 45658
B10: Holding Period (Years): | C10: 5
B11: Exit Date: | C11: =DATE(YEAR(C9)+C10,MONTH(C9),DAY(C9))
B14: ENTRY VALUATION
B16: LTM Revenue ($M) | C16: 500
B17: LTM EBITDA ($M) | C17: 100
B18: EBITDA Margin % | C18: =C17/C16
B20: Entry EV / Revenue Multiple | C20: 2
B21: Entry EV / EBITDA Multiple | C21: 10
B23: Purchase Price (Enterprise Value) | C23: =C17*C21
B26: FINANCING ASSUMPTIONS
B28: Total Leverage (Debt / EBITDA) | C28: 5
B29: Senior Leverage (Senior / EBITDA) | C29: 4
B31: Total Debt at Entry | C31: =C17*C28
B32: Interest Coverage (EBITDA / Interest) | C32: =C17/'Debt Schedule'!C32
B35: TRANSACTION COSTS
B37: M&A Advisory Fees (% of EV) | C37: 0.015
B38: Legal & Other Fees ($ M) | C38: 3
B39: Financing Fees (% of Debt) | C39: 0.02
B41: Total M&A Advisory Fees | C41: =C23*C37
B42: Total Financing Fees | C42: =C31*C39
B43: Total Transaction Costs | C43: =C41+C38+C42
B46: EXIT ASSUMPTIONS
B48: Exit EV / EBITDA Multiple | C48: 10
B49: Exit Year EBITDA ($ M) | C49: ='Financial Statements'!K31
B50: Exit Enterprise Value | C50: =C49*C48

Sheet Sources & Uses
B2: SOURCES & USES OF FUNDS
B3: Transaction Financing Structure
B6: SOURCES | E6: USES
B8: Debt Financing: | E8: Purchase Price:
B9: Revolving Credit Facility | C9: 0 | E9: Enterprise Value | F9: ='Transaction Assumptions'!C23
B10: Term Loan A | C10: 200 | E10: Less: Existing Cash | F10: 0
B11: Term Loan B | C11: 200 | E11: Plus: Existing Debt Payoff | F11: 0
B12: Subordinated Debt | C12: 100
E13: Purchase of Equity | F13: =F9-F10+F11
B14: Total Debt | C14: =SUM(C9:C12)
E15: Transaction Costs:
B16: Equity Financing: | E16: M&A Advisory Fees | F16: ='Transaction Assumptions'!C41
B17: Sponsor Equity | C17: 450 | E17: Legal & Other Fees | F17: ='Transaction Assumptions'!C38
B18: Management Rollover | C18: 50 | E18: Financing Fees | F18: ='Transaction Assumptions'!C42
B20: Total Equity | C20: =SUM(C17:C18) | E20: Total Transaction Costs | F20: =SUM(F16:F18)
B22: TOTAL SOURCES | C22: =C14+C20 | E22: TOTAL USES | F22: =F13+F20
E25: Check (Should = 0): | F25: =C22-F22
B27: CAPITAL STRUCTURE ANALYSIS
B29: Debt as % of Total Capitalization | C29: =C14/C22
B30: Equity as % of Total Capitalization | C30: =C20/C22
B31: Sponsor Equity as % of Total Equity | C31: =C17/C20
B32: Management as % of Total Equity | C32: =C18/C20

Sheet Debt Schedule
B2: DEBT SCHEDULE & CASH SWEEP
C6: Year 0 | D6: Year 1 | E6: Year 2 | F6: Year 3 | G6: Year 4 | H6: Year 5 | I6: Year 6 | J6: Year 7 | K6: Year 8
B8: DEBT ASSUMPTIONS
B10: Revolving Credit Facility
B11: Commitment Amount | C11: ='Sources & Uses'!C9
B12: Interest Rate (% p.a.) | C12: 0.05
B16: Term Loan A
B17: Principal Amount | C17: ='Sources & Uses'!C10
B18: Interest Rate (% p.a.) | C18: 0.06
B19: Mandatory Amortization (%) | C19: 0.05
B20: Cash Sweep (%) | C20: 1
B22: Term Loan B
B23: Principal Amount | C23: ='Sources & Uses'!C11
B24: Interest Rate (% p.a.) | C24: 0.075
B25: Mandatory Amortization (%) | C25: 0.01
B26: Cash Sweep (%) | C26: 0.5
B28: Subordinated Debt
B29: Principal Amount | C29: ='Sources & Uses'!C12
B30: Interest Rate (% p.a.) | C30: 0.1
B32: Total Year 1 Interest Expense | C32: =D63
B35: DEBT BALANCES
B37: Revolver | C37: =C11 | D37: =MAX(0,C37+D63) | E37: =MAX(0,D37+E63) | F37: =MAX(0,E37+F63) | G37: =MAX(0,F37+G63) | H37: =MAX(0,G37+H63) | I37: =MAX(0,H37+I63) | J37: =MAX(0,I37+J63) | K37: =MAX(0,J37+K63)
B38: Term Loan A | C38: =C17 | D38: =MAX(0,C38-D46-D47) | E38: =MAX(0,D38-E46-E47) | F38: =MAX(0,E38-F46-F47) | G38: =MAX(0,F38-G46-G47) | H38: =MAX(0,G38-H46-H47) | I38: =MAX(0,H38-I46-I47) | J38: =MAX(0,I38-J46-J47) | K38: =MAX(0,J38-K46-K47)
B39: Term Loan B | C39: =C23 | D39: =MAX(0,C39-D50-D51) | E39: =MAX(0,D39-E50-E51) | F39: =MAX(0,E39-F50-F51) | G39: =MAX(0,F39-G50-G51) | H39: =MAX(0,G39-H50-H51) | I39: =MAX(0,H39-I50-I51) | J39: =MAX(0,I39-J50-J51) | K39: =MAX(0,J39-K50-K51)
B40: Subordinated Debt | C40: =C29 | D40: =C40 | E40: =D40 | F40: =E40 | G40: =F40 | H40: =G40 | I40: =H40 | J40: =I40 | K40: =J40
B42: Total Debt | C42: =SUM(C37:C40) | D42: =SUM(D37:D40) | E42: =SUM(E37:E40) | F42: =SUM(F37:F40) | G42: =SUM(G37:G40) | H42: =SUM(H37:H40) | I42: =SUM(I37:I40) | J42: =SUM(J37:J40) | K42: =SUM(K37:K40)
B44: MANDATORY AMORTIZATION
B46: Term Loan A - Mandatory | D46: =MIN(C38,C17*C19) | E46: =MIN(D38,C17*C19) | F46: =MIN(E38,C17*C19) | G46: =MIN(F38,C17*C19) | H46: =MIN(G38,C17*C19) | I46: =MIN(H38,C17*C19) | J46: =MIN(I38,C17*C19) | K46: =MIN(J38,C17*C19)
B47: Term Loan A - Cash Sweep | D47: =D74 | E47: =E74 | F47: =F74 | G47: =G74 | H47: =H74 | I47: =I74 | J47: =J74 | K47: =K74
B50: Term Loan B - Mandatory | D50: =MIN(C39,C23*C25) | E50: =MIN(D39,C23*C25) | F50: =MIN(E39,C23*C25) | G50: =MIN(F39,C23*C25) | H50: =MIN(G39,C23*C25) | I50: =MIN(H39,C23*C25) | J50: =MIN(I39,C23*C25) | K50: =MIN(J39,C23*C25)
B51: Term Loan B - Cash Sweep | D51: =D76 | E51: =E76 | F51: =F76 | G51: =G76 | H51: =H76 | I51: =I76 | J51: =J76 | K51: =K76
B54: INTEREST EXPENSE
B56: Revolver | D56: =C37*C12 | E56: =D37*C12 | F56: =E37*C12 | G56: =F37*C12 | H56: =G37*C12 | I56: =H37*C12 | J56: =I37*C12 | K56: =J37*C12
B58: Term Loan A | D58: =C38*C18 | E58: =D38*C18 | F58: =E38*C18 | G58: =F38*C18 | H58: =G38*C18 | I58: =H38*C18 | J58: =I38*C18 | K58: =J38*C18
B59: Term Loan B | D59: =C39*C24 | E59: =D39*C24 | F59: =E39*C24 | G59: =F39*C24 | H59: =G39*C24 | I59: =H39*C24 | J59: =I39*C24 | K59: =J39*C24
B60: Subordinated Debt | D60: =C40*C30 | E60: =D40*C30 | F60: =E40*C30 | G60: =F40*C30 | H60: =G40*C30 | I60: =H40*C30 | J60: =I40*C30 | K60: =J40*C30
B63: Total Interest | D63: =SUM(D56:D60) | E63: =SUM(E56:E60) | F63: =SUM(F56:F60) | G63: =SUM(G56:G60) | H63: =SUM(H56:H60) | I63: =SUM(I56:I60) | J63: =SUM(J56:J60) | K63: =SUM(K56:K60)
B66: CASH SWEEP
B68: FCF (from Operations) | D68: ='Financial Statements'!D51 | E68: ='Financial Statements'!E51 | F68: ='Financial Statements'!F51 | G68: ='Financial Statements'!G51 | H68: ='Financial Statements'!H51 | I68: ='Financial Statements'!I51 | J68: ='Financial Statements'!J51 | K68: ='Financial Statements'!K51
B69: Less: Mandatory Amort | D69: =-D46-D50 | E69: =-E46-E50 | F69: =-F46-F50 | G69: =-G46-G50 | H69: =-H46-H50 | I69: =-I46-I50 | J69: =-J46-J50 | K69: =-K46-K50
...

Sheet Financial Statements
B2: FINANCIAL STATEMENTS
C6: Year 0 | D6: Year 1 | E6: Year 2 | F6: Year 3 | G6: Year 4 | H6: Year 5 | I6: Year 6 | J6: Year 7 | K6: Year 8
B8: INCOME STATEMENT
B10: Revenue | C10: ='Transaction Assumptions'!C16 | D10: =C10*(1+D11) | E10: =D10*(1+E11) | F10: =E10*(1+F11) | G10: =F10*(1+G11) | H10: =G10*(1+H11) | I10: =H10*(1+I11) | J10: =I10*(1+J11) | K10: =J10*(1+K11)
B11: Revenue Growth % | C11: 0 | D11: 0.05 | E11: 0.05 | F11: 0.05 | G11: 0.05 | H11: 0.05 | I11: 0.05 | J11: 0.05 | K11: 0.05
B13: EBITDA | C13: =C10*C14 | D13: =D10*D14 | E13: =E10*E14 | F13: =F10*F14 | G13: =G10*G14 | H13: =H10*H14 | I13: =I10*I14 | J13: =J10*J14 | K13: =K10*K14
B14: EBITDA Margin % | C14: ='Transaction Assumptions'!C18 | D14: 0.22 | E14: 0.22 | F14: 0.22 | G14: 0.22 | H14: 0.22 | I14: 0.22 | J14: 0.22 | K14: 0.22
B16: Less: D&A | C16: 15 | D16: 15 | E16: 15 | F16: 15 | G16: 15 | H16: 15 | I16: 15 | J16: 15 | K16: 15
B18: EBIT | C18: =C13-C16 | D18: =D13-D16 | E18: =E13-E16 | F18: =F13-F16 | G18: =G13-G16 | H18: =H13-H16 | I18: =I13-I16 | J18: =J13-J16 | K18: =K13-K16
B20: Less: Interest Expense | C20: ='Debt Schedule'!C63 | D20: ='Debt Schedule'!D63 | E20: ='Debt Schedule'!E63 | F20: ='Debt Schedule'!F63 | G20: ='Debt Schedule'!G63 | H20: ='Debt Schedule'!H63 | I20: ='Debt Schedule'!I63 | J20: ='Debt Schedule'!J63 | K20: ='Debt Schedule'!K63
B22: EBT | C22: =C18-C20 | D22: =D18-D20 | E22: =E18-E20 | F22: =F18-F20 | G22: =G18-G20 | H22: =H18-H20 | I22: =I18-I20 | J22: =J18-J20 | K22: =K18-K20
B24: Less: Taxes | C24: =C22*C25 | D24: =D22*D25 | E24: =E22*E25 | F24: =F22*F25 | G24: =G22*G25 | H24: =H22*H25 | I24: =I22*I25 | J24: =J22*J25 | K24: =K22*K25
B25: Tax Rate % | C25: 0.25 | D25: =$C$25 | E25: =$C$25 | F25: =$C$25 | G25: =$C$25 | H25: =$C$25 | I25: =$C$25 | J25: =$C$25 | K25: =$C$25
B27: Net Income | C27: =C22-C24 | D27: =D22-D24 | E27: =E22-E24 | F27: =F22-F24 | G27: =G22-G24 | H27: =H22-H24 | I27: =I22-I24 | J27: =J22-J24 | K27: =K22-K24
B30: CASH FLOW
B32: EBITDA | C32: =C13 | D32: =D13 | E32: =E13 | F32: =F13 | G32: =G13 | H32: =H13 | I32: =I13 | J32: =J13 | K32: =K13
B33: Less: Cash Taxes | C33: =-C24 | D33: =-D24 | E33: =-E24 | F33: =-F24 | G33: =-G24 | H33: =-H24 | I33: =-I24 | J33: =-J24 | K33: =-K24
B34: Less: Interest | C34: =-C20 | D34: =-D20 | E34: =-E20 | F34: =-F20 | G34: =-G20 | H34: =-H20 | I34: =-I20 | J34: =-J20 | K34: =-K20
B35: Less: CapEx | C35: =-C10*C36 | D35: =-D10*D36 | E35: =-E10*E36 | F35: =-F10*F36 | G35: =-G10*G36 | H35: =-H10*H36 | I35: =-I10*I36 | J35: =-J10*J36 | K35: =-K10*K36
B36: CapEx % of Revenue | C36: 0.03 | D36: 0.03 | E36: 0.03 | F36: 0.03 | G36: 0.03 | H36: 0.03 | I36: 0.03 | J36: 0.03 | K36: 0.03
B38: Less: Change in NWC | C38: =0 | D38: =-(D10*D39-C10*C39) | E38: =-(E10*E39-D10*D39) | F38: =-(F10*F39-E10*E39) | G38: =-(G10*G39-F10*F39) | H38: =-(H10*H39-G10*G39) | I38: =-(I10*I39-H10*H39) | J38: =-(J10*J39-I10*I39) | K38: =-(K10*K39-J10*J39)
B39: NWC % of Revenue | C39: 0.1 | D39: 0.1 | E39: 0.1 | F39: 0.1 | G39: 0.1 | H39: 0.1 | I39: 0.1 | J39: 0.1 | K39: 0.1
B41: Free Cash Flow | C41: =SUM(C32:C38) | D41: =SUM(D32:D38) | E41: =SUM(E32:E38) | F41: =SUM(F32:F38) | G41: =SUM(G32:G38) | H41: =SUM(H32:H38) | I41: =SUM(I32:I38) | J41: =SUM(J32:J38) | K41: =SUM(K32:K38)
B51: FCF to Debt Schedule | C51: =C41 | D51: =D41 | E51: =E41 | F51: =F41 | G51: =G41 | H51: =H41 | I51: =I41 | J51: =J41 | K51: =K41
B54: CREDIT METRICS
B56: Total Debt / EBITDA | C56: ='Debt Schedule'!C42/C13 | D56: ='Debt Schedule'!D42/D13 | E56: ='Debt Schedule'!E42/E13 | F56: ='Debt Schedule'!F42/F13 | G56: ='Debt Schedule'!G42/G13 | H56: ='Debt Schedule'!H42/H13 | I56: ='Debt Schedule'!I42/I13 | J56: ='Debt Schedule'!J42/J13 | K56: ='Debt Schedule'!K42/K13
B57: EBITDA / Interest | C57: =IF(C20>0,C13/C20,0) | D57: =IF(D20>0,D13/D20,0) | E57: =IF(E20>0,E13/E20,0) | F57: =IF(F20>0,F13/F20,0) | G57: =IF(G20>0,G13/G20,0) | H57: =IF(H20>0,H13/H20,0) | I57: =IF(I20>0,I13/I20,0) | J57: =IF(J20>0,J13/J20,0) | K57: =IF(K20>0,K13/K20,0)
B58: EBIT / Interest | C58: =IF(C20>0,C18/C20,0) | D58: =IF(D20>0,D18/D20,0) | E58: =IF(E20>0,E18/E20,0) | F58: =IF(F20>0,F18/F20,0) | G58: =IF(G20>0,G18/G20,0) | H58: =IF(H20>0,H18/H20,0) | I58: =IF(I20>0,I18/I20,0) | J58: =IF(J20>0,J18/J20,0) | K58: =IF(K20>0,K18/K20,0)

Sheet Returns Analysis
B2: RETURNS ANALYSIS
B3: IRR, MOIC & Exit Valuation
B6: INVESTMENT SUMMARY | E6: DEBT PAYDOWN
B8: Transaction Date | C8: ='Transaction Assumptions'!C9 | E8: Initial Debt | F8: ='Debt Schedule'!C42
B9: Exit Date | C9: ='Transaction Assumptions'!C11 | E9: Ending Debt | F9: ='Debt Schedule'!K42
B10: Holding Period (Years) | C10: ='Transaction Assumptions'!C10 | E10: Total Debt Paydown | F10: =F8-F9
E11: % of Initial Debt Paid | F11: =F10/F8
B12: Initial Equity Investment
B13: Sponsor Equity | C13: ='Sources & Uses'!C17
B14: Management Rollover | C14: ='Sources & Uses'!C18
B15: Total Equity Investment | C15: =C13+C14
B18: EXIT VALUATION
B20: Exit Year EBITDA | C20: ='Financial Statements'!K13
B21: Exit EV / EBITDA Multiple | C21: ='Transaction Assumptions'!C48
B23: Exit Enterprise Value | C23: =C20*C21
B25: Less: Net Debt at Exit | C25: ='Debt Schedule'!K42 | E25: Debt Paydown (for Exec) | F25: =F10
B26: Exit Equity Value | C26: =C23-C25
B29: RETURNS TO EQUITY
B31: Equity IRR | C31: =IRR({-C15,0,0,0,0,C26})
B32: Equity Multiple (MOIC) | C32: =C26/C15
B33: Total Cash Return ($) | C33: =C26-C15
B34: Total % Return | C34: =(C26-C15)/C15
B35: Exit Enterprise Value (Link) | C35: =C23
B36: Net Debt at Exit (Link) | C36: =C25
B37: Exit Equity Value (Link) | C37: =C26
B42: IRR (for Exec Summary) | C42: =C31
B43: MOIC (for Exec Summary) | C43: =C32
B44: Cash Return (for Exec Summary) | C44: =C33
B45: % Return (for Exec Summary) | C45: =C34

Sheet Sensitivity Analysis
B2: SENSITIVITY ANALYSIS
B5: EXIT MULTIPLE vs ENTRY MULTIPLE SENSITIVITY
B7: Entry Multiple → | E7: =8.0 | F7: =9.0 | G7: =10.0 | H7: =11.0 | I7: =12.0
B8: =8.0 | C8: IRR values will be calculated with data tables
B9: =9.0
B10: =10.0
B11: =11.0
B12: =12.0
B14: EBITDA GROWTH vs EXIT MULTIPLE SENSITIVITY
B16: EBITDA CAGR →
B17: Exit Multiple ↓

Sheet Distribution Waterfall
B2: DISTRIBUTION WATERFALL
B3: European-Style Waterfall with Preferred Return
B6: WATERFALL ASSUMPTIONS
B8: Preferred Return (IRR Hurdle) | C8: 0.08
B9: GP Catch-Up % | C9: 1
B10: Carried Interest % | C10: 0.2
B11: LP Share (after catch-up) | C11: =1-C10
B14: DISTRIBUTION CALCULATION
B16: Total Distributions Available | C16: ='Returns Analysis'!C26
B18: 1. Return of Capital to LPs | C18: ='Returns Analysis'!C15
B19: Remaining for Distribution | C19: =C16-C18
B21: 2. Preferred Return to LPs (8%) | C21: =C18*((1+C8)^'Returns Analysis'!C10-1)
B22: Remaining after Pref Return | C22: =C19-C21
B24: 3. GP Catch-Up (100%) | C24: =MIN(C22,(C18+C21)*C10/(1-C10))
B25: Remaining after Catch-Up | C25: =C22-C24
B27: 4. Carried Interest Split:
B28: To GP (20%) | C28: =C25*C10
B29: To LPs (80%) | C29: =C25*C11
B32: FINAL DISTRIBUTION SUMMARY
B34: Total to LPs | C34: =C18+C21+C29
B35: Total to GP | C35: =C24+C28
B37: LP % of Total | C37: =C34/C16
B38: GP % of Total (Carry) | C38: =C35/C16
B40: Check (should = 0) | C40: =C16-C34-C35
