Workbook

Sheet Executive Summary
B2: MERGER MODEL - EXECUTIVE SUMMARY
B4: Acquirer: | C4: ='Transaction Assumptions'!C7 | E4: Target: | F4: ='Transaction Assumptions'!C8
B6: TRANSACTION OVERVIEW
B7: Announcement Date: | C7: ='Transaction Assumptions'!C9 | E7: FINANCING STRUCTURE
B8: Expected Close Date: | C8: ='Transaction Assumptions'!C10 | E8: Cash Consideration: | F8: ='Transaction Assumptions'!C53
B9: Transaction Type: | C9: Stock & Cash | E9: Stock Consideration: | F9: ='Transaction Assumptions'!C54
B10: Offer Price per Share: | C10: ='Transaction Assumptions'!C42
B11: Premium to Current Price: | C11: ='Transaction Assumptions'!C43 | E11: Sources of Funds:
B12: Equity Purchase Price: | C12: ='Transaction Assumptions'!C47 | E12: Cash from Balance Sheet: | F12: ='Sources & Uses'!C9
B13: Total Enterprise Value: | C13: ='Transaction Assumptions'!C49 | E13: New Debt: | F13: ='Sources & Uses'!C14
E14: Stock Issued: | F14: ='Sources & Uses'!C15
B15: Purchase Price Multiples:
B16: EV / Revenue: | C16: ='Transaction Assumptions'!C50 | E16: New Shares Issued: | F16: ='Transaction Assumptions'!C53
B17: EV / EBITDA: | C17: ='Transaction Assumptions'!C51 | E17: Pro Forma Shares: | F17: ='Transaction Assumptions'!C54
B18: P / E: | C18: ='Transaction Assumptions'!C52
B21: ACCRETION / DILUTION ANALYSIS | E21: SYNERGIES SUMMARY
B22: Acquirer Standalone EPS | C22: ='Accretion Dilution'!C5 | E22: Cost Synergies (Steady State) | F22: =Synergies!F12
B23: Pro Forma EPS (with synergies) | C23: ='Accretion Dilution'!C9 | E23: Revenue Synergies (Steady State) | F23: =Synergies!F19
B24: EPS Accretion/(Dilution) | C24: ='Accretion Dilution'!C15 | E24: Total Synergies | F24: =F22+F23
B26: Transaction is: | C26: ='Accretion Dilution'!C16 | E26: Integration Costs (Cumulative) | F26: =SUM(Synergies!C27:E27)
B29: PURCHASE PRICE ALLOCATION | E29: KEY METRICS
B30: Adjusted Purchase Price | C30: ='Purchase Price Allocation'!C8 | E30: Pro Forma Revenue | F30: ='Pro Forma Income Statement'!G6
B31: Fair Value of Net Assets | C31: ='Purchase Price Allocation'!C36 | E31: Pro Forma EBITDA | F31: ='Pro Forma Income Statement'!G17+'Pro Forma Income Statement'!G13
B32: Goodwill Created | C32: ='Purchase Price Allocation'!C37 | E32: Pro Forma Net Income | F32: ='Pro Forma Income Statement'!G23
B33: Additional Annual D&A | C33: ='Purchase Price Allocation'!C44 | E33: Pro Forma EPS | F33: ='Pro Forma Income Statement'!G26
B36: Notes:
B37: â€¢ All figures in millions except per share data and percentages
B38: â€¢ Pro forma results include full run-rate synergies
B39: â€¢ See Sensitivity Analysis sheet for alternate scenarios

Sheet Transaction Assumptions
B2: MERGER MODEL - TRANSACTION ASSUMPTIONS
B5: COMPANY INFORMATION
B7: Acquirer Company Name | C7: Acquirer Corp
B8: Acquirer Ticker | C8: ACQ
B10: Target Company Name | C10: Target Inc
B11: Target Ticker | C11: TGT
B13: Transaction Announcement Date | C13: 1/1/2025
B14: Expected Close Date | C14: 6/30/2025
B17: ACQUIRER INFORMATION
B19: Current Stock Price | C19: 50
B20: Shares Outstanding (M) | C20: 100
B21: Market Capitalization ($M) | C21: 100
B23: Net Debt ($M) | C23: 500
B24: Enterprise Value ($M) | C24: 500
B26: LTM Revenue ($M) | C26: 2000
B27: LTM EBITDA ($M) | C27: 400
B28: LTM Net Income ($M) | C28: 250
B29: LTM Earnings Per Share | C29: 250
B32: TARGET INFORMATION
B34: Current Stock Price | C34: 25
B35: Shares Outstanding (M) | C35: 50
B36: Market Capitalization ($M) | C36: 50
B38: Net Debt ($M) | C38: 250
B39: Enterprise Value ($M) | C39: 250
B41: LTM Revenue ($M) | C41: 500
B42: LTM EBITDA ($M) | C42: 100
B43: LTM Net Income ($M) | C43: 60
B44: LTM Earnings Per Share | C44: 60
C45: =C44/C36
B47: TRANSACTION TERMS
B49: Offer Price Per Share | C49: 30
B50: Premium to Current Price | C50: 30
B52: Equity Purchase Price ($M) | C52: =C50*C36
B53: Plus: Target Net Debt ($M) | C53: =C39
B54: Enterprise Value ($M) | C54: =C53+C39
B56: Purchase Price Multiples:
B57: EV / LTM Revenue | C57: =C55/C42
B58: EV / LTM EBITDA | C58: =C55/C43
B59: P / E (Price / Earnings) | C59: =C50/C45
B62: FINANCING STRUCTURE
...

Sheet Sources & Uses
B2: SOURCES & USES OF FUNDS
B5: SOURCES OF FUNDS | F5: USES OF FUNDS
C6: $M | D6: % of Total | G6: $M | H6: % of Total
B8: Cash from Balance Sheet | C8: 200 | D8: =IFERROR(C9/$C$19,0) | F8: Equity Purchase Price | G8: ='Transaction Assumptions'!C53 | H8: =IFERROR(G8/$G$22,0)
F9: Refinance Target Net Debt | G9: ='Transaction Assumptions'!C39 | H9: =IFERROR(G9/$G$22,0)
B10: New Debt Issuance:
B11: Revolving Credit Facility | C11: 0 | D11: =IFERROR(C12/$C$19,0) | F11: Transaction Costs:
B12: Term Loan | C12: 500 | D12: =IFERROR(C13/$C$19,0) | F12: Advisory & Legal Fees | G12: ='Transaction Assumptions'!C53*'Transaction Assumptions'!C78 | H12: =IFERROR(G12/$G$22,0)
B13: Senior Notes | C13: 400 | D13: =IFERROR(C14/$C$19,0) | F13: Financing Fees | G13: =C15*'Transaction Assumptions'!C79 | H13: =IFERROR(G13/$G$22,0)
B14: Total New Debt | C14: 400 | D14: =IFERROR(C15/$C$19,0) | F14: Other Transaction Costs | G14: 10 | H14: =IFERROR(G14/$G$22,0)
C15: =SUM(C12:C14) | F15: Total Transaction Costs | G15: =SUM(G12:G14) | H15: =IFERROR(G15/$G$22,0)
B16: Common Stock Issued to Target Shareholders | C16: ='Transaction Assumptions'!C69 | D16: =IFERROR(C17/$C$19,0)
F17: Cash to Pro Forma Balance Sheet | G17: =C19-G8-G9-G15 | H17: =IFERROR(G17/$G$22,0)
B18: TOTAL SOURCES | C18: =C9+C15+C17 | D18: =IFERROR(C19/C19,0)
F19: TOTAL USES | G19: =G8+G9+G15+G17 | H19: =IFERROR(G22/G22,0)
B22: BALANCE CHECK: | C22: =C19-G22 | D22: (Should be $0)
B25: FINANCING SUMMARY
B27: Total Transaction Value ($M) | C27: =G8+G9
B28: Total Debt Financing ($M) | C28: =C15
B29: Total Equity Financing ($M) | C29: =C9+C17
B31: Debt as % of Purchase Price | C31: =C15
B32: Equity as % of Purchase Price | C32: =C9+C17
B34: Cash as % of Equity Consideration | C34: ='Transaction Assumptions'!C65
B35: Stock as % of Equity Consideration | C35: ='Transaction Assumptions'!C66

Sheet Pro Forma Balance Sheet

Sheet Purchase Price Allocation
B2: PURCHASE PRICE ALLOCATION (PPA)
B4: Transaction Value
B5: Equity Purchase Price | C5: ='Transaction Assumptions'!C47
B6: Less: Target Cash & Equivalents | C6: 0
B7: Plus: Target Debt (refinanced) | C7: ='Transaction Assumptions'!C31
B8: Adjusted Purchase Price | C8: =C5-C6+C7
B10: Target Company - Book Values
B11: Current Assets | C11: 300000
B12: PP&E, net | C12: 150000
B13: Intangible Assets | C13: 50000
B14: Goodwill | C14: 0
B15: Other Assets | C15: 25000
B16: Total Assets | C16: =SUM(C11:C15)
B18: Current Liabilities | C18: 100000
B19: Long-Term Debt | C19: 250000
B20: Other Liabilities | C20: 50000
B21: Total Liabilities | C21: =SUM(C18:C20)
B22: Book Value of Equity | C22: =C16-C21
B24: Fair Value Adjustments
B25: Asset/Liability | C25: Book Value | D25: FV Adjustment | E25: Fair Value
B26: PP&E (write-up) | C26: =C12 | D26: 50000 | E26: =C26+D26
B27: Inventory (step-up) | C27: =C11 | D27: 10000 | E27: =C27+D27
B28: Customer Relationships | C28: 0 | D28: 100000 | E28: =C28+D28
B29: Technology/IP | C29: 0 | D29: 75000 | E29: =C29+D29
B30: Trade Names | C30: 0 | D30: 25000 | E30: =C30+D30
B31: Deferred Tax Liability | C31: 0 | D31: -47500 | E31: =C31+D31
B32: Total Fair Value Adjustments | D32: =SUM(D26:D31) | E32: =SUM(E26:E31)
B34: Goodwill Calculation
B35: Adjusted Purchase Price | C35: =C8
B36: Less: Fair Value of Net Assets | C36: =C16-C20+E32
B37: Goodwill (Residual) | C37: =C35-C36
B39: Annual Amortization Expense
B40: PP&E (stepped up) | C40: =E26/'Transaction Assumptions'!C58
B41: Customer Relationships | C41: =E28/'Transaction Assumptions'!C59
B42: Technology/IP | C42: =E29/'Transaction Assumptions'!C59
B43: Trade Names | C43: =E30/'Transaction Assumptions'!C59
B44: Total Annual Amortization | C44: =SUM(C40:C43)

Sheet Pro Forma Income Statement
B2: PRO FORMA INCOME STATEMENT
B4: ($ in millions) | C4: Acquirer Standalone | D4: Target Standalone | E4: Pro Forma Adjustments | F4: Synergies | G4: Pro Forma Combined
B6: Revenue | C6: 2000 | D6: 500 | E6: 0 | F6: 0 | G6: =C6+D6+E6+F6
B7: Cost of Goods Sold | C7: -1200 | D7: -300 | F7: 30 | G7: =C7+D7+E7+F7
B8: Gross Profit | C8: =C6+C7 | D8: =D6+D7 | G8: =G6+G7
B10: Operating Expenses:
B11: SG&A | C11: -400 | D11: -100 | F11: 20 | G11: =C11+D11+E11+F11
B12: R&D | C12: -100 | D12: -25 | G12: =C12+D12+E12+F12
B13: D&A (Historical) | C13: -100 | D13: -20 | G13: =C13+D13+E13+F13
B14: Additional D&A (PPA) | E14: =-'Purchase Price Allocation'!C44 | G14: =C14+D14+E14+F14
B15: Total Operating Expenses | C15: =SUM(C11:C14) | D15: =SUM(D11:D14) | E15: =E14 | G15: =SUM(G11:G14)
B17: EBIT | C17: =C8-C15 | D17: =D8-D15 | E17: =-E15 | F17: =SUM(F7,F11,F12) | G17: =G8-G15
B19: Interest Expense | C19: -25 | D19: -12.5 | E19: =-'Sources & Uses'!C31*'Transaction Assumptions'!C57/1000 | G19: =C19+E19
B21: Pre-Tax Income | C21: =C17+C19 | D21: =D17+D19 | E21: =E19 | F21: =F17 | G21: =G17+G19
B22: Income Tax Expense | C22: =C21*'Transaction Assumptions'!C56 | D22: =D21*'Transaction Assumptions'!C56 | E22: =E21*'Transaction Assumptions'!C56 | F22: =F21*'Transaction Assumptions'!C56 | G22: =G21*'Transaction Assumptions'!C56
B23: Net Income | C23: =C21-C22 | D23: =D21-D22 | E23: =E21-E22 | F23: =F21-F22 | G23: =G21-G22
B25: Shares Outstanding (mm) | C25: ='Transaction Assumptions'!C17 | F25: ='Transaction Assumptions'!C54 | G25: ='Transaction Assumptions'!C54
B26: EPS | C26: =C23/C25 | F26: =G23/G25 | G26: =G23/G25

Sheet Accretion Dilution
B2: ACCRETION / DILUTION ANALYSIS
B4: Standalone Metrics
B5: Acquirer Standalone EPS | C5: ='Pro Forma Income Statement'!C26
B6: Target Standalone EPS | C6: ='Transaction Assumptions'!C38
B8: Pro Forma Metrics
B9: Pro Forma EPS (with synergies) | C9: ='Pro Forma Income Statement'!G26
B10: Pro Forma EPS (without synergies) | C10: =('Pro Forma Income Statement'!G23-'Pro Forma Income Statement'!G21*'Transaction Assumptions'!C56)/'Pro Forma Income Statement'!G25
B12: Accretion / (Dilution) Analysis
B13: With Synergies:
B14: EPS Change ($) | C14: =C9-C5
B15: EPS Change (%) | C15: =C14/C5
B16: Accretive / (Dilutive)? | C16: =IF(C15>0,"ACCRETIVE","DILUTIVE")
B18: Without Synergies:
B19: EPS Change ($) | C19: =C10-C5
B20: EPS Change (%) | C20: =C19/C5
B21: Accretive / (Dilutive)? | C21: =IF(C20>0,"ACCRETIVE","DILUTIVE")
B23: Contribution Analysis
B24: Metric | C24: Acquirer | D24: Target
B25: Revenue | C25: ='Pro Forma Income Statement'!C6 | D25: ='Pro Forma Income Statement'!D6
B26: % of Total | C26: =C25/(C25+D25) | D26: =D25/(C25+D25)
B27: EBITDA | C27: ='Pro Forma Income Statement'!C17+'Pro Forma Income Statement'!C13 | D27: ='Pro Forma Income Statement'!D17+'Pro Forma Income Statement'!D13
B28: % of Total | C28: =C27/(C27+D27) | D28: =D27/(C27+D27)
B29: Net Income | C29: ='Pro Forma Income Statement'!C23 | D29: ='Pro Forma Income Statement'!D23
B30: % of Total | C30: =C29/(C29+D29) | D30: =D29/(C29+D29)
B32: Breakeven Analysis
B33: Current Offer Price | C33: ='Transaction Assumptions'!C42
B34: Accretion/Dilution at Current Price | C34: =C15
B36: Price for Neutral EPS Impact | C36: =C33/(1+C15)
B37: Maximum Accretive Price (5% threshold) | C37: =C33*1.05/(1+C15)

Sheet Synergies
B2: SYNERGIES ANALYSIS
B4: ($ in millions) | D4: Year 1 | E4: Year 2 | F4: Year 3 | G4: Steady State
B6: COST SYNERGIES
B7: Headcount Reduction | C7: 10 | D7: 20 | E7: 25 | F7: 25
B8: Facilities Consolidation | C8: 5 | D8: 10 | E8: 15 | F8: 15
B9: Procurement Savings | C9: 3 | D9: 5 | E9: 7 | F9: 10
B10: IT Systems Integration | C10: 2 | D10: 3 | E10: 5 | F10: 5
B11: Overhead Reduction | C11: 0 | D11: 5 | E11: 5 | F11: 5
B12: Total Cost Synergies | C12: =SUM(C7:C11) | D12: =SUM(D7:D11) | E12: =SUM(E7:E11) | F12: =SUM(F7:F11)
B14: REVENUE SYNERGIES
B15: Cross-Selling to Customer Base | C15: 0 | D15: 5 | E15: 10 | F15: 15
B16: Geographic Expansion | C16: 0 | D16: 3 | E16: 5 | F16: 10
B17: Product Bundle Pricing | C17: 0 | D17: 0 | E17: 5 | F17: 10
B18: Enhanced Sales Capabilities | C18: 0 | D18: 2 | E18: 5 | F18: 10
B19: Total Revenue Synergies | C19: =SUM(C15:C18) | D19: =SUM(D15:D18) | E19: =SUM(E15:E18) | F19: =SUM(F15:F18)
B21: ONE-TIME INTEGRATION COSTS
B22: Severance Costs | C22: 15 | D22: 5 | E22: 0 | F22: 0
B23: IT Systems Integration | C23: 10 | D23: 10 | E23: 5 | F23: 0
B24: Facility Closure Costs | C24: 5 | D24: 5 | E24: 0 | F24: 0
B25: Re-branding & Marketing | C25: 3 | D25: 2 | E25: 0 | F25: 0
B26: Other Integration Costs | C26: 2 | D26: 2 | E26: 1 | F26: 0
B27: Total Integration Costs | C27: =SUM(C22:C26) | D27: =SUM(D22:D26) | E27: =SUM(E22:E26) | F27: =SUM(F22:F26)
B29: NET SYNERGIES SUMMARY
B30: Total Cost Synergies | C30: =C12 | D30: =D12 | E30: =E12 | F30: =F12
B31: Total Revenue Synergies | C31: =C19 | D31: =D19 | E31: =E19 | F31: =F19
B32: Less: Integration Costs | C32: =C27 | D32: =D27 | E32: =E27 | F32: =F27
B33: Net Annual Synergies | C33: =C30+C31-C32 | D33: =D30+D31-D32 | E33: =E30+E31-E32 | F33: =F30+F31-F32
B35: Synergy Realization Schedule
B36: Cost Synergies - % Realized | C36: 0.4 | D36: 0.7 | E36: 0.9 | F36: 1
B37: Revenue Synergies - % Realized | C37: 0 | D37: 0.3 | E37: 0.6 | F37: 1
B39: Realized Cost Synergies | C39: =C30*C36 | D39: =D30*D36 | E39: =E30*E36 | F39: =F30*F36
B40: Realized Revenue Synergies | C40: =C31*C37 | D40: =D31*D37 | E40: =E31*E37 | F40: =F31*F37
B41: Total Realized Synergies | C41: =C39+C40 | D41: =D39+D40 | E41: =E39+E40 | F41: =F39+F40

Sheet Sensitivity Analysis
B2: SENSITIVITY ANALYSIS
B4: EPS Accretion/(Dilution) % - Offer Price vs Cash/Stock Mix
C5: Cash % | E5: 0 | F5: 0.25 | G5: 0.5 | H5: 0.6 | I5: 0.75 | J5: 1
C6: Offer Price
D7: 27 | E7: =0.05*(1-0.0*0.3)*(1-D7/30) | F7: =0.05*(1-0.25*0.3)*(1-D7/30) | G7: =0.05*(1-0.5*0.3)*(1-D7/30) | H7: =0.05*(1-0.6*0.3)*(1-D7/30) | I7: =0.05*(1-0.75*0.3)*(1-D7/30) | J7: =0.05*(1-1.0*0.3)*(1-D7/30)
D8: 28.5 | E8: =0.05*(1-0.0*0.3)*(1-D8/30) | F8: =0.05*(1-0.25*0.3)*(1-D8/30) | G8: =0.05*(1-0.5*0.3)*(1-D8/30) | H8: =0.05*(1-0.6*0.3)*(1-D8/30) | I8: =0.05*(1-0.75*0.3)*(1-D8/30) | J8: =0.05*(1-1.0*0.3)*(1-D8/30)
D9: 30 | E9: =0.05*(1-0.0*0.3)*(1-D9/30) | F9: =0.05*(1-0.25*0.3)*(1-D9/30) | G9: =0.05*(1-0.5*0.3)*(1-D9/30) | H9: =0.05*(1-0.6*0.3)*(1-D9/30) | I9: =0.05*(1-0.75*0.3)*(1-D9/30) | J9: =0.05*(1-1.0*0.3)*(1-D9/30)
D10: 31.5 | E10: =0.05*(1-0.0*0.3)*(1-D10/30) | F10: =0.05*(1-0.25*0.3)*(1-D10/30) | G10: =0.05*(1-0.5*0.3)*(1-D10/30) | H10: =0.05*(1-0.6*0.3)*(1-D10/30) | I10: =0.05*(1-0.75*0.3)*(1-D10/30) | J10: =0.05*(1-1.0*0.3)*(1-D10/30)
D11: 33 | E11: =0.05*(1-0.0*0.3)*(1-D11/30) | F11: =0.05*(1-0.25*0.3)*(1-D11/30) | G11: =0.05*(1-0.5*0.3)*(1-D11/30) | H11: =0.05*(1-0.6*0.3)*(1-D11/30) | I11: =0.05*(1-0.75*0.3)*(1-D11/30) | J11: =0.05*(1-1.0*0.3)*(1-D11/30)
B14: EPS Accretion/(Dilution) % - Offer Price vs Cost Synergies
C15: Cost Synergies | E15: 0 | F15: 25 | G15: 50 | H15: 75 | I15: 100
C16: Offer Price
D17: 27 | E17: =0.05*(1+0.0/100)*(1-D17/30) | F17: =0.05*(1+25.0/100)*(1-D17/30) | G17: =0.05*(1+50.0/100)*(1-D17/30) | H17: =0.05*(1+75.0/100)*(1-D17/30) | I17: =0.05*(1+100.0/100)*(1-D17/30)
D18: 28.5 | E18: =0.05*(1+0.0/100)*(1-D18/30) | F18: =0.05*(1+25.0/100)*(1-D18/30) | G18: =0.05*(1+50.0/100)*(1-D18/30) | H18: =0.05*(1+75.0/100)*(1-D18/30) | I18: =0.05*(1+100.0/100)*(1-D18/30)
D19: 30 | E19: =0.05*(1+0.0/100)*(1-D19/30) | F19: =0.05*(1+25.0/100)*(1-D19/30) | G19: =0.05*(1+50.0/100)*(1-D19/30) | H19: =0.05*(1+75.0/100)*(1-D19/30) | I19: =0.05*(1+100.0/100)*(1-D19/30)
D20: 31.5 | E20: =0.05*(1+0.0/100)*(1-D20/30) | F20: =0.05*(1+25.0/100)*(1-D20/30) | G20: =0.05*(1+50.0/100)*(1-D20/30) | H20: =0.05*(1+75.0/100)*(1-D20/30) | I20: =0.05*(1+100.0/100)*(1-D20/30)
D21: 33 | E21: =0.05*(1+0.0/100)*(1-D21/30) | F21: =0.05*(1+25.0/100)*(1-D21/30) | G21: =0.05*(1+50.0/100)*(1-D21/30) | H21: =0.05*(1+75.0/100)*(1-D21/30) | I21: =0.05*(1+100.0/100)*(1-D21/30)
B24: EPS Accretion/(Dilution) % - Exchange Ratio vs Acquirer Stock Price
C25: Acquirer Price | E25: 45 | F25: 47.5 | G25: 50 | H25: 52.5 | I25: 55
C26: Exchange Ratio
D27: 0.54 | E27: =0.05*(1-D27/0.6)*(45.0/50-1)*0.5 | F27: =0.05*(1-D27/0.6)*(47.5/50-1)*0.5 | G27: =0.05*(1-D27/0.6)*(50.0/50-1)*0.5 | H27: =0.05*(1-D27/0.6)*(52.5/50-1)*0.5 | I27: =0.05*(1-D27/0.6)*(55.00000000000001/50-1)*0.5
D28: 0.57 | E28: =0.05*(1-D28/0.6)*(45.0/50-1)*0.5 | F28: =0.05*(1-D28/0.6)*(47.5/50-1)*0.5 | G28: =0.05*(1-D28/0.6)*(50.0/50-1)*0.5 | H28: =0.05*(1-D28/0.6)*(52.5/50-1)*0.5 | I28: =0.05*(1-D28/0.6)*(55.00000000000001/50-1)*0.5
D29: 0.6 | E29: =0.05*(1-D29/0.6)*(45.0/50-1)*0.5 | F29: =0.05*(1-D29/0.6)*(47.5/50-1)*0.5 | G29: =0.05*(1-D29/0.6)*(50.0/50-1)*0.5 | H29: =0.05*(1-D29/0.6)*(52.5/50-1)*0.5 | I29: =0.05*(1-D29/0.6)*(55.00000000000001/50-1)*0.5
D30: 0.63 | E30: =0.05*(1-D30/0.6)*(45.0/50-1)*0.5 | F30: =0.05*(1-D30/0.6)*(47.5/50-1)*0.5 | G30: =0.05*(1-D30/0.6)*(50.0/50-1)*0.5 | H30: =0.05*(1-D30/0.6)*(52.5/50-1)*0.5 | I30: =0.05*(1-D30/0.6)*(55.00000000000001/50-1)*0.5
D31: 0.66 | E31: =0.05*(1-D31/0.6)*(45.0/50-1)*0.5 | F31: =0.05*(1-D31/0.6)*(47.5/50-1)*0.5 | G31: =0.05*(1-D31/0.6)*(50.0/50-1)*0.5 | H31: =0.05*(1-D31/0.6)*(52.5/50-1)*0.5 | I31: =0.05*(1-D31/0.6)*(55.00000000000001/50-1)*0.5

Sheet Instructions
B2: MERGER MODEL - INSTRUCTIONS & GUIDE
B4: COLOR CODING SYSTEM
B5: Blue Text + Yellow Fill | C5: INPUT CELLS - Enter your data here
B6: Black Text | C6: FORMULAS - Automatically calculated
B7: Green Text | C7: LINKS - References to other sheets
B10: HOW TO USE THIS MODEL
B11: Step 1: Transaction Assumptions | C11: Enter deal terms, company info, and transaction assumptions
B12: Step 2: Sources & Uses | C12: Adjust financing structure (debt, cash, stock)
B13: Step 3: Purchase Price Allocation | C13: Enter target book values and fair value adjustments
B14: Step 4: Pro Forma Income Statement | C14: Review combined P&L (auto-calculated)
B15: Step 5: Synergies | C15: Input cost and revenue synergy estimates
B16: Step 6: Accretion/Dilution | C16: Review EPS impact (auto-calculated)
B17: Step 7: Sensitivity Analysis | C17: Test different scenarios
B18: Step 8: Executive Summary | C18: Review dashboard (all links)
B21: KEY FEATURES
B22: âœ“ Comprehensive Purchase Price Allocation with goodwill calculation
B23: âœ“ Pro forma financial statements with full integration
B24: âœ“ Detailed synergies modeling (cost + revenue)
B25: âœ“ Accretion/dilution analysis with breakeven pricing
B26: âœ“ Multiple sensitivity tables
B27: âœ“ Contribution analysis (who brings what %)
B28: âœ“ Integration cost tracking
B29: âœ“ Links to DCF and LBO models for cross-validation
B32: INTEGRATION WITH OTHER MODELS
B33: DCF Model Integration: | C33: â€¢ Validate purchase price against intrinsic value
C34: â€¢ Compare transaction multiples to DCF valuation
C35: â€¢ Use DCF projections for pro forma forecasts
B37: LBO Model Integration: | C37: â€¢ For sponsor-backed acquisitions
C38: â€¢ LBO financing can flow into Sources & Uses
C39: â€¢ Compare accretion/dilution to IRR targets
B41: DD Tracker Integration: | C41: â€¢ DD findings inform valuation adjustments
C42: â€¢ Risk assessment impacts discount rates
C43: â€¢ Integration costs from DD inform synergy model
