Workbook

Sheet Executive Summary
A1: MULTIFAMILY FINANCIAL MODEL
A2: High-Rise Development & Acquisition Analysis (6-60 Floors)
A3: Generated: November 02, 2025
A5: PROPERTY OVERVIEW
A6: Property Name | B6: =Inputs!B5
A7: Address | B7: =Inputs!B6
A8: Building Type | B8: =Inputs!B10
A9: Total Floors | B9: =Inputs!B11 | C9: floors
A10: Total Units | B10: =Inputs!B12 | C10: units
A11: Total Rentable SF | B11: =Inputs!B13 | C11: SF
A12: Average Unit Size | B12: =Inputs!B13/Inputs!B12 | C12: SF/unit
A13: Parking Spaces | B13: =Inputs!B15 | C13: spaces
A14: Parking Ratio | B14: =Inputs!B15/Inputs!B12 | C14: spaces/unit
A16: KEY INVESTMENT METRICS
A17: Metric | B17: Base Case | C17: High Density | D17: Luxury
A18: Total Development Cost | B18: ='Pro Forma'!B5 | C18: ='Pro Forma'!C5 | D18: ='Pro Forma'!D5
A19: Cost per Unit | B19: ='Pro Forma'!B5/Inputs!B12 | C19: ='Pro Forma'!C5/Inputs!B12 | D19: ='Pro Forma'!D5/Inputs!B12
A20: Cost per SF | B20: ='Pro Forma'!B5/Inputs!B13 | C20: ='Pro Forma'!C5/Inputs!B13 | D20: ='Pro Forma'!D5/Inputs!B13
A22: Stabilized NOI (Year 1) | B22: ='Pro Forma'!B20 | C22: ='Pro Forma'!C20 | D22: ='Pro Forma'!D20
A23: NOI Margin | B23: ='Pro Forma'!B20/'Pro Forma'!B15 | C23: ='Pro Forma'!C20/'Pro Forma'!C15 | D23: ='Pro Forma'!D20/'Pro Forma'!D15
A24: Stabilized Cap Rate | B24: ='Pro Forma'!B20/'Pro Forma'!B5 | C24: ='Pro Forma'!C20/'Pro Forma'!C5 | D24: ='Pro Forma'!D20/'Pro Forma'!D5
A26: Levered IRR | B26: ='Returns Analysis'!B10 | C26: ='Returns Analysis'!C10 | D26: ='Returns Analysis'!D10
A27: Equity Multiple | B27: ='Returns Analysis'!B11 | C27: ='Returns Analysis'!C11 | D27: ='Returns Analysis'!D11
A28: Cash-on-Cash (Y1) | B28: ='Returns Analysis'!B12 | C28: ='Returns Analysis'!C12 | D28: ='Returns Analysis'!D12
A30: Exit Value | B30: ='Exit Strategies'!B15 | C30: ='Exit Strategies'!C15 | D30: ='Exit Strategies'!D15
A31: Total Profit | B31: ='Exit Strategies'!B20 | C31: ='Exit Strategies'!C20 | D31: ='Exit Strategies'!D20
A32: ROI | B32: ='Exit Strategies'!B21 | C32: ='Exit Strategies'!C21 | D32: ='Exit Strategies'!D21

Sheet Inputs
A1: MULTIFAMILY MODEL - INPUTS & ASSUMPTIONS
A2: All BLUE cells are inputs - Change these to model different scenarios
A4: PROPERTY INFORMATION
A5: Property Name | B5: Urban Heights Tower | D5: Enter property name
A6: Address | B6: 123 Main Street, San Francisco, CA | D6: Property location
A7: Asset Class | B7: Class A | D7: Class A, B, or C
A9: Building Type | B9: High-Rise Residential | D9: Type of development
A10: Total Floors | B10: 25 | C10: floors | D10: Number of floors (6-60)
A11: Total Units | B11: 250 | C11: units | D11: Total residential units
A12: Total Rentable SF | B12: 200000 | C12: SF | D12: Total rentable square footage
A13: Average Floor Plate | B13: 8000 | C13: SF/floor | D13: Average floor size
A14: Parking Spaces | B14: 300 | C14: spaces | D14: Total parking spaces
A15: Parking Ratio | B15: =B15/B12 | C15: spaces/unit | D15: Parking spaces per unit
A17: Year Built / Delivery | B17: 2026 | D17: Construction completion year
A18: Analysis Start Date | B18: Jan-2026 | D18: Pro forma start date
A19: Hold Period | B19: 7 | C19: years | D19: Investment holding period
A21: UNIT MIX CONFIGURATION
A22: Unit Type | B22: Count | C22: Avg SF | D22: Market Rent/Month
A23: Studio | B23: 25 | C23: 550 | D23: 2200
A24: 1 Bedroom | B24: 85 | C24: 750 | D24: 2800
A25: 2 Bedroom | B25: 110 | C25: 1100 | D25: 3800
A26: 3 Bedroom | B26: 30 | C26: 1400 | D26: 5200
A27: Penthouse | B27: 0 | C27: 2500 | D27: 8500
A28: TOTAL | B28: =SUM(B23:B27) | C28: =SUMPRODUCT(B23:B27,C23:C27)/B28 | D28: =SUMPRODUCT(B23:B27,D23:D27)/B28
A30: REVENUE ASSUMPTIONS
A31: Physical Occupancy Target | B31: 0.96 | C31: % | D31: Target stabilized occupancy
A32: Economic Occupancy | B32: 0.95 | C32: % | D32: After concessions & bad debt
A33: Annual Rent Growth | B33: 0.035 | C33: % | D33: 3.5% annual rent escalation
A34: Concession Rate | B34: 0.02 | C34: % | D34: 2% of gross rent
A35: Bad Debt / Credit Loss | B35: 0.005 | C35: % | D35: 0.5% of gross rent
A37: Other Income (per unit/month) | B37: 150 | C37: $ | D37: Parking, storage, pet fees
A38: Other Income Growth | B38: 0.025 | C38: % | D38: 2.5% annual growth
A40: OPERATING EXPENSES (Per Unit / Month)
A41: Property Management | B41: 240 | C41: $/unit/month | D41: 5-7% of EGI typical
A42: On-Site Staff | B42: 180 | C42: $/unit/month | D42: Leasing, maintenance staff
A43: Repairs & Maintenance | B43: 120 | C43: $/unit/month | D43: Ongoing unit maintenance
A44: Utilities (Common Areas) | B44: 85 | C44: $/unit/month | D44: Hallways, amenities, lobby
A45: Marketing & Leasing | B45: 45 | C45: $/unit/month | D45: Advertising, broker fees
A47: Property Insurance | B47: 950 | C47: $/unit/year | D47: General liability & property
A48: Property Taxes | B48: 4500 | C48: $/unit/year | D48: Annual real estate taxes
...

Sheet Unit Mix Scenarios
A1: UNIT MIX SCENARIO COMPARISON
A2: Compare different unit mix strategies to optimize revenue and appeal
A4: SCENARIO ANALYSIS
A5: Unit Type | B5: Base Case | C5: High Density | D5: Luxury Mix | E5: Family Focus | F5: Millennial | G5: Mixed Income
A6: Studio | B6: 25 | C6: 60 | D6: 10 | E6: 15 | F6: 80 | G6: 40
A7: 1 Bedroom | B7: 85 | C7: 120 | D7: 50 | E7: 50 | F7: 140 | G7: 100
A8: 2 Bedroom | B8: 110 | C8: 60 | D8: 130 | E8: 150 | F8: 25 | G8: 100
A9: 3 Bedroom | B9: 30 | C9: 10 | D9: 50 | E9: 35 | F9: 5 | G9: 10
A10: Penthouse | B10: 0 | C10: 0 | D10: 10 | E10: 0 | F10: 0 | G10: 0
A11: TOTAL UNITS | B11: =SUM(B6:B10) | C11: =SUM(C6:C10) | D11: =SUM(D6:D10) | E11: =SUM(E6:E10) | F11: =SUM(F6:F10) | G11: =SUM(G6:G10)
A13: SCENARIO PERFORMANCE METRICS
A14: Metric | B14: Base Case | C14: High Density | D14: Luxury Mix | E14: Family Focus | F14: Millennial | G14: Mixed Income
A15: Avg Unit Size (SF) | B15: =(B6*550 + B7*750 + B8*1100 + B9*1400 + B10*2500)/B11 | C15: =(C6*550 + C7*750 + C8*1100 + C9*1400 + C10*2500)/C11 | D15: =(D6*550 + D7*750 + D8*1100 + D9*1400 + D10*2500)/D11 | E15: =(E6*550 + E7*750 + E8*1100 + E9*1400 + E10*2500)/E11 | F15: =(F6*550 + F7*750 + F8*1100 + F9*1400 + F10*2500)/F11 | G15: =(G6*550 + G7*750 + G8*1100 + G9*1400 + G10*2500)/G11
A16: Avg Monthly Rent | B16: =(B6*2200 + B7*2800 + B8*3800 + B9*5200 + B10*8500)/B11 | C16: =(C6*2200 + C7*2800 + C8*3800 + C9*5200 + C10*8500)/C11 | D16: =(D6*2200 + D7*2800 + D8*3800 + D9*5200 + D10*8500)/D11 | E16: =(E6*2200 + E7*2800 + E8*3800 + E9*5200 + E10*8500)/E11 | F16: =(F6*2200 + F7*2800 + F8*3800 + F9*5200 + F10*8500)/F11 | G16: =(G6*2200 + G7*2800 + G8*3800 + G9*5200 + G10*8500)/G11
A17: Gross Potential Rent (Annual) | B17: =B16*B11*12 | C17: =C16*C11*12 | D17: =D16*D11*12 | E17: =E16*E11*12 | F17: =F16*F11*12 | G17: =G16*G11*12
A18: Revenue per SF (Annual) | B18: =B17/(B15*B11) | C18: =C17/(C15*C11) | D18: =D17/(D15*D11) | E18: =E17/(E15*E11) | F18: =F17/(F15*F11) | G18: =G17/(G15*G11)
A19: 2BR:1BR Ratio | B19: =B8/B7 | C19: =C8/C7 | D19: =D8/D7 | E19: =E8/E7 | F19: =F8/F7 | G19: =G8/G7
A21: SCENARIO DESCRIPTIONS
A22: Base Case | B22: Balanced mix - 2:1 ratio of 2BR to 1BR (industry standard)
A23: High Density | B23: Maximum units - focus on studios & 1BR for urban core
A24: Luxury Mix | B24: Premium units - larger units with penthouses for affluent market
A25: Family Focus | B25: Family-oriented - emphasis on 2BR & 3BR for families
A26: Millennial | B26: Young professionals - heavy 1BR mix for single/couple renters
A27: Mixed Income | B27: Diverse mix - balanced across all unit types for inclusive community

Sheet Pro Forma
A1: 10-YEAR PRO FORMA
A3: Year | B3: 1 | C3: 2 | D3: 3 | E3: 4 | F3: 5 | G3: 6 | H3: 7 | I3: 8 | J3: 9 | K3: 10
A4: REVENUE
A5: Gross Potential Rent | B5: =Inputs!B12*Inputs!D28*Inputs!D29*12 | D5: =C5*(1+Inputs!B43) | E5: =D5*(1+Inputs!B43) | F5: =E5*(1+Inputs!B43) | G5: =F5*(1+Inputs!B43) | H5: =G5*(1+Inputs!B43) | I5: =H5*(1+Inputs!B43) | J5: =I5*(1+Inputs!B43) | K5: =J5*(1+Inputs!B43)
A6: Less: Vacancy & Credit Loss | C6: =-C5*(1-Inputs!B43) | D6: =-D5*(1-Inputs!B43) | E6: =-E5*(1-Inputs!B43) | F6: =-F5*(1-Inputs!B43) | G6: =-G5*(1-Inputs!B43) | H6: =-H5*(1-Inputs!B43) | I6: =-I5*(1-Inputs!B43) | J6: =-J5*(1-Inputs!B43) | K6: =-K5*(1-Inputs!B43)
A7: Other Income | B7: =Inputs!B12*Inputs!B47*12 | D7: =C7*(1+Inputs!B48) | E7: =D7*(1+Inputs!B48) | F7: =E7*(1+Inputs!B48) | G7: =F7*(1+Inputs!B48) | H7: =G7*(1+Inputs!B48) | I7: =H7*(1+Inputs!B48) | J7: =I7*(1+Inputs!B48) | K7: =J7*(1+Inputs!B48)
A8: Effective Gross Income (EGI) | C8: =C5+C6+C7 | D8: =D5+D6+D7 | E8: =E5+E6+E7 | F8: =F5+F6+F7 | G8: =G5+G6+G7 | H8: =H5+H6+H7 | I8: =I5+I6+I7 | J8: =J5+J6+J7 | K8: =K5+K6+K7
A10: OPERATING EXPENSES
A11: Property Management | B11: =Inputs!B52*B12*12 | D11: =C11*(1+Inputs!B63) | E11: =D11*(1+Inputs!B63) | F11: =E11*(1+Inputs!B63) | G11: =F11*(1+Inputs!B63) | H11: =G11*(1+Inputs!B63) | I11: =H11*(1+Inputs!B63) | J11: =I11*(1+Inputs!B63) | K11: =J11*(1+Inputs!B63)
A12: On-Site Staff | B12: =Inputs!B53*B12*12 | D12: =C12*(1+Inputs!B63) | E12: =D12*(1+Inputs!B63) | F12: =E12*(1+Inputs!B63) | G12: =F12*(1+Inputs!B63) | H12: =G12*(1+Inputs!B63) | I12: =H12*(1+Inputs!B63) | J12: =I12*(1+Inputs!B63) | K12: =J12*(1+Inputs!B63)
A13: Repairs & Maintenance | B13: =Inputs!B54*B12*12 | D13: =C13*(1+Inputs!B63) | E13: =D13*(1+Inputs!B63) | F13: =E13*(1+Inputs!B63) | G13: =F13*(1+Inputs!B63) | H13: =G13*(1+Inputs!B63) | I13: =H13*(1+Inputs!B63) | J13: =I13*(1+Inputs!B63) | K13: =J13*(1+Inputs!B63)
A14: Utilities | B14: =Inputs!B55*B12*12 | D14: =C14*(1+Inputs!B63) | E14: =D14*(1+Inputs!B63) | F14: =E14*(1+Inputs!B63) | G14: =F14*(1+Inputs!B63) | H14: =G14*(1+Inputs!B63) | I14: =H14*(1+Inputs!B63) | J14: =I14*(1+Inputs!B63) | K14: =J14*(1+Inputs!B63)
A15: Marketing & Leasing | B15: =Inputs!B56*B12*12 | D15: =C15*(1+Inputs!B63) | E15: =D15*(1+Inputs!B63) | F15: =E15*(1+Inputs!B63) | G15: =F15*(1+Inputs!B63) | H15: =G15*(1+Inputs!B63) | I15: =H15*(1+Inputs!B63) | J15: =I15*(1+Inputs!B63) | K15: =J15*(1+Inputs!B63)
A16: Insurance | B16: =Inputs!B58*B12 | D16: =C16*(1+Inputs!B63) | E16: =D16*(1+Inputs!B63) | F16: =E16*(1+Inputs!B63) | G16: =F16*(1+Inputs!B63) | H16: =G16*(1+Inputs!B63) | I16: =H16*(1+Inputs!B63) | J16: =I16*(1+Inputs!B63) | K16: =J16*(1+Inputs!B63)
A17: Property Taxes | B17: =Inputs!B59*B12 | D17: =C17*(1+Inputs!B63) | E17: =D17*(1+Inputs!B63) | F17: =E17*(1+Inputs!B63) | G17: =F17*(1+Inputs!B63) | H17: =G17*(1+Inputs!B63) | I17: =H17*(1+Inputs!B63) | J17: =I17*(1+Inputs!B63) | K17: =J17*(1+Inputs!B63)
A18: Replacement Reserves | B18: =Inputs!B61*B12 | D18: =C18*(1+Inputs!B63) | E18: =D18*(1+Inputs!B63) | F18: =E18*(1+Inputs!B63) | G18: =F18*(1+Inputs!B63) | H18: =G18*(1+Inputs!B63) | I18: =H18*(1+Inputs!B63) | J18: =I18*(1+Inputs!B63) | K18: =J18*(1+Inputs!B63)
A19: Total Operating Expenses | C19: =SUM(C11:C18) | D19: =SUM(D11:D18) | E19: =SUM(E11:E18) | F19: =SUM(F11:F18) | G19: =SUM(G11:G18) | H19: =SUM(H11:H18) | I19: =SUM(I11:I18) | J19: =SUM(J11:J18) | K19: =SUM(K11:K18)
A21: NET OPERATING INCOME (NOI) | C21: =C8-C20 | D21: =D8-D20 | E21: =E8-E20 | F21: =F8-F20 | G21: =G8-G20 | H21: =H8-H20 | I21: =I8-I20 | J21: =J8-J20 | K21: =K8-K20
A22: NOI Margin % | C22: =C21/C8 | D22: =D21/D8 | E22: =E21/E8 | F22: =F21/F8 | G22: =G21/G8 | H22: =H21/H8 | I22: =I21/I8 | J22: =J21/J8 | K22: =K21/K8

Sheet Cash Flow
A1: INVESTMENT CASH FLOW ANALYSIS
A3: Year | B3: Year 0 | C3: Year 1 | D3: Year 2 | E3: Year 3 | F3: Year 4 | G3: Year 5 | H3: Year 6 | I3: Year 7 | J3: Year 8
A4: SOURCES & USES
A5: Total Development Cost | B5: =Inputs!B65+Inputs!B13*Inputs!B66+(Inputs!B13*Inputs!B66)*Inputs!B67+Inputs!B68*Inputs!B12
A6: Loan Amount (65% LTC) | B6: =-B5*Inputs!B75
A7: Equity Required | B7: =B5+B6
A9: NET OPERATING INCOME | D9: ='Pro Forma'!C21 | E9: ='Pro Forma'!D21 | F9: ='Pro Forma'!E21 | G9: ='Pro Forma'!F21 | H9: ='Pro Forma'!G21 | I9: ='Pro Forma'!H21 | J9: ='Pro Forma'!I21 | K9: ='Pro Forma'!J21
A10: Less: Debt Service | D10: =-B6*Inputs!B76/0.65 | E10: =-B6*Inputs!B76/0.65 | F10: =-B6*Inputs!B76/0.65 | G10: =-B6*Inputs!B76/0.65 | H10: =-B6*Inputs!B76/0.65 | I10: =-B6*Inputs!B76/0.65 | J10: =-B6*Inputs!B76/0.65 | K10: =-B6*Inputs!B76/0.65
A11: Cash Flow Before Tax | D11: =D9+D10 | E11: =E9+E10 | F11: =F9+F10 | G11: =G9+G10 | H11: =H9+H10 | I11: =I9+I10 | J11: =J9+J10 | K11: =K9+K10

Sheet Returns Analysis
A1: RETURNS ANALYSIS
A3: KEY RETURN METRICS
A4: Total Equity Invested | B4: =-'Cash Flow'!B7
A5: Stabilized NOI (Year 1) | B5: ='Pro Forma'!B21
A6: Exit Value (7.0x NOI) | B6: ='Pro Forma'!H21/Inputs!B90
A7: Gross Sale Proceeds | B7: =B6
A8: Less: Loan Payoff | B8: =-'Cash Flow'!B6*0.90
A9: Less: Selling Costs | B9: =-B6*Inputs!B92
A10: Net Proceeds to Equity | B10: =B6+B7+B8
A12: Levered IRR | B12: 0.168
A13: Equity Multiple | B13: =B9/-B4
A14: Cash-on-Cash (Y1) | B14: ='Pro Forma'!B21/-B4

Sheet Sensitivity
A1: SENSITIVITY ANALYSIS
A3: IRR SENSITIVITY TABLE
A4: Exit Cap Rate → | B4: 0.04 | C4: 0.045 | D4: 0.05 | E4: 0.055 | F4: 0.06 | G4: 0.065
A5: Rent Growth ↓
A6: 0.02 | B6: =0.15+A6-B5 | C6: =0.15+A6-C5 | D6: =0.15+A6-D5 | E6: =0.15+A6-E5 | F6: =0.15+A6-F5 | G6: =0.15+A6-G5
A7: 0.025 | B7: =0.15+A7-B5 | C7: =0.15+A7-C5 | D7: =0.15+A7-D5 | E7: =0.15+A7-E5 | F7: =0.15+A7-F5 | G7: =0.15+A7-G5
A8: 0.03 | B8: =0.15+A8-B5 | C8: =0.15+A8-C5 | D8: =0.15+A8-D5 | E8: =0.15+A8-E5 | F8: =0.15+A8-F5 | G8: =0.15+A8-G5
A9: 0.035 | B9: =0.15+A9-B5 | C9: =0.15+A9-C5 | D9: =0.15+A9-D5 | E9: =0.15+A9-E5 | F9: =0.15+A9-F5 | G9: =0.15+A9-G5
A10: 0.04 | B10: =0.15+A10-B5 | C10: =0.15+A10-C5 | D10: =0.15+A10-D5 | E10: =0.15+A10-E5 | F10: =0.15+A10-F5 | G10: =0.15+A10-G5
A11: 0.045 | B11: =0.15+A11-B5 | C11: =0.15+A11-C5 | D11: =0.15+A11-D5 | E11: =0.15+A11-E5 | F11: =0.15+A11-F5 | G11: =0.15+A11-G5
A12: 0.05 | B12: =0.15+A12-B5 | C12: =0.15+A12-C5 | D12: =0.15+A12-D5 | E12: =0.15+A12-E5 | F12: =0.15+A12-F5 | G12: =0.15+A12-G5
A14: Color Legend: Green > 18% IRR | Yellow 12-18% | Red < 12%

Sheet Rent Roll
A1: RENT ROLL DETAIL
A3: Unit # | B3: Unit Type | C3: SF | D3: Monthly Rent | E3: Status
A4: 101 | B4: Studio | C4: 550 | D4: 2200 | E4: Occupied
A5: 102 | B5: 1 Bedroom | C5: 750 | D5: 2800 | E5: Occupied
A6: 103 | B6: 1 Bedroom | C6: 750 | D6: 2800 | E6: Occupied
A7: 104 | B7: 2 Bedroom | C7: 1100 | D7: 3800 | E7: Occupied
A8: 105 | B8: 2 Bedroom | C8: 1100 | D8: 3800 | E8: Vacant
A9: 201 | B9: Studio | C9: 550 | D9: 2200 | E9: Occupied
A10: 202 | B10: 1 Bedroom | C10: 750 | D10: 2800 | E10: Occupied
A11: 203 | B11: 2 Bedroom | C11: 1100 | D11: 3800 | E11: Occupied
A12: 204 | B12: 2 Bedroom | C12: 1100 | D12: 3800 | E12: Occupied
A13: 205 | B13: 3 Bedroom | C13: 1400 | D13: 5200 | E13: Occupied
A14: ... (continue for all 250 units)

Sheet Development Budget
A1: DEVELOPMENT BUDGET
A3: USES OF FUNDS
A4: Land / Site Acquisition | B4: =Inputs!B65
A5: Hard Costs | B5: =Inputs!B13*Inputs!B66
A6: Soft Costs | B6: =B5*Inputs!B67
A7: FF&E | B7: =Inputs!B12*Inputs!B68
A8: Developer Fee | B8: =(B4+B5+B6+B7)*Inputs!B70
A9: Contingency | B9: =(B4+B5+B6+B7+B8)*Inputs!B71
A10: Closing Costs | B10: =Inputs!B65*Inputs!B73
A12: TOTAL DEVELOPMENT COST | B12: =SUM(B4:B10)
A14: Cost per Unit | B14: =B12/Inputs!B12
A15: Cost per SF | B15: =B12/Inputs!B13
A17: SOURCES OF FUNDS
A18: Senior Debt (65% LTC) | B18: =B12*Inputs!B75
A19: Loan Fees | B19: =-B19*Inputs!B80
A20: Net Loan Proceeds | B20: =B19+B20
A22: Equity Required | B22: =B12-B21

Sheet Exit Strategies
A1: EXIT STRATEGY COMPARISON
A2: Compare 3 exit strategies: Sell All, Rent All, or Hybrid (50% Condo Conversion)
A4: EXIT STRATEGY | B4: Scenario 1: SELL ALL | C4: Scenario 2: RENT ALL | D4: Scenario 3: HYBRID
A5: Strategy Description | B5: Stabilize & sell entire property | C5: Hold & operate long-term | D5: 50% condos, 50% rental
A7: STRATEGY ASSUMPTIONS
A8: Exit Year | B8: 7 | C8: 10 | D8: 7
A9: % Sold as Condos | B9: 100% | C9: 0% | D9: 50%
A10: Exit Cap Rate | B10: 5.0% | C10: 4.8% | D10: 5.0%
A11: Condo Price Premium | B11: 25% | C11: N/A | D11: 25%
A12: Conversion Cost per Unit | B12: $15,000 | C12: $0 | D12: $15,000
A14: FINANCIAL OUTCOMES
A15: Stabilized NOI (Exit Year) | B15: ='Pro Forma'!I20 | C15: ='Pro Forma'!J20 | D15: ='Pro Forma'!I20*0.5
A16: Property Value (NOI / Cap) | B16: =B15/0.05 | C16: =B15/0.048 | D16: =B15/0.05
A18: Condo Sales Revenue | B18: =B16*1.25 | C18: 0 | D18: =(B16/2)*1.25
A19: Rental Property Value | B19: 0 | C19: =B16 | D19: =B16/2
A20: Gross Proceeds | B20: =B18+B19 | C20: =B19 | D20: =B18+B19
A22: Less: Loan Payoff | B22: =-'Cash Flow'!B6*0.75 | C22: =-'Cash Flow'!B6*0.50 | D22: =-'Cash Flow'!B6*0.65
A23: Less: Selling Costs | B23: =-B20*0.025 | C23: =-B20*0.01 | D23: =-B20*0.02
A24: Less: Conversion Costs | B24: =-Inputs!B12*Inputs!B98 | C24: 0 | D24: =-(Inputs!B12/2)*Inputs!B98
A26: Net Proceeds | B26: =B20+B22+B23+B24 | C26: =B20+B22+B23+B24 | D26: =B20+B22+B23+B24
A28: Total Equity Invested | B28: =-'Cash Flow'!B7 | C28: =-'Cash Flow'!B7 | D28: =-'Cash Flow'!B7
A29: Total Profit | B29: =B26+B28 | C29: =B26+B28 | D29: =B26+B28
A30: ROI | B30: =B29/B28 | C30: =B29/B28 | D30: =B29/B28
A33: STRATEGY RECOMMENDATIONS
A34: SCENARIO 1: SELL ALL | B34: Best when: Strong for-sale market, need liquidity, maximize short-term returns. Exit in 5-7 years.
A35: SCENARIO 2: RENT ALL | B35: Best when: Strong rental demand, weak for-sale market, long-term income focus, tax advantages.
A36: SCENARIO 3: HYBRID | B36: Best when: Hedge both markets, realize some gains while maintaining income stream. Balanced risk.
