Workbook

Sheet Executive Summary
A1: REAL ESTATE FINANCIAL MODEL - EXECUTIVE SUMMARY
A2: Generated: November 02, 2025
A4: PROPERTY OVERVIEW
A5: Property Name | B5: =Inputs!B5
A6: Property Type | B6: =Inputs!B6
A7: Address | B7: =Inputs!B7
A8: City/State | B8: =Inputs!B8
A9: Acquisition Date | B9: =Inputs!B9
A10: Hold Period (Years) | B10: =Inputs!B10
A13: KEY INVESTMENT METRICS
A14: Total Acquisition Cost | B14: =Summary!B5
A15: Purchase Price per Unit | B15: =Summary!B6
A16: Purchase Price per SF | B16: =Summary!B7
A17: Entry Cap Rate | B17: =Summary!B8
A18: Year 1 NOI | B18: =Summary!B9
A19: Year 1 Cash-on-Cash Return | B19: =Summary!B10
A20: Unlevered IRR | B20: =Summary!B11
A21: Levered IRR | B21: =Summary!B12
A22: Equity Multiple | B22: =Summary!B13
A23: Exit Value | B23: =Summary!B14
A24: Exit Cap Rate | B24: =Summary!B15
A25: Total Return | B25: =Summary!B16
A28: SENSITIVITY ANALYSIS
A29: IRR Sensitivity Matrix (Exit Cap Rate vs. Rent Growth)
A30: Exit Cap → | B30: 4.50% | C30: 5.00% | D30: 5.50% | E30: 6.00% | F30: 6.50%
A31: Rent Growth 2.0% | B31: =Sensitivity!B10 | C31: =Sensitivity!C10 | D31: =Sensitivity!D10 | E31: =Sensitivity!E10 | F31: =Sensitivity!F10
A32: Rent Growth 3.0% | B32: =Sensitivity!B11 | C32: =Sensitivity!C11 | D32: =Sensitivity!D11 | E32: =Sensitivity!E11 | F32: =Sensitivity!F11
A33: Rent Growth 4.0% | B33: =Sensitivity!B12 | C33: =Sensitivity!C12 | D33: =Sensitivity!D12 | E33: =Sensitivity!E12 | F33: =Sensitivity!F12
A34: Rent Growth 5.0% | B34: =Sensitivity!B13 | C34: =Sensitivity!C13 | D34: =Sensitivity!D13 | E34: =Sensitivity!E13 | F34: =Sensitivity!F13
A35: Rent Growth 6.0% | B35: =Sensitivity!B14 | C35: =Sensitivity!C14 | D35: =Sensitivity!D14 | E35: =Sensitivity!E14 | F35: =Sensitivity!F14

Sheet Inputs
A1: INPUT ASSUMPTIONS
A2: ⚠️ YELLOW CELLS = User Input Required
A4: PROPERTY INFORMATION
A5: Property Name | B5: Arcadia Gardens Apartments
A6: Property Type | B6: Multifamily
A7: Address | B7: 1234 Main Street
A8: City, State | B8: Phoenix, AZ
A9: Acquisition Date | B9: 1/1/2025
A10: Hold Period (Years) | B10: 5
A12: Number of Units | B12: 150
A13: Average Unit Size (SF) | B13: 950
A14: Total Rentable SF | B14: =B12*B13
A15: Gross Square Feet | B15: =B14/0.92
A16: Parking Spaces | B16: 200
A18: Current Occupancy % | B18: 0.93
A19: Stabilized Occupancy % | B19: 0.95
A21: UNIT MIX & RENTS
A22: Unit Type | B22: # Units | C22: Avg SF | D22: Total SF | E22: Market Rent/Month | F22: Market Rent/SF/Month
A23: Studio | B23: 20 | C23: 550 | D23: =B23*C23 | E23: 0 | F23: =E23/C23
A24: 1 Bed / 1 Bath | B24: 60 | C24: 750 | D24: =B24*C24 | E24: 0 | F24: =E24/C24
A25: 2 Bed / 2 Bath | B25: 50 | C25: 1100 | D25: =B25*C25 | E25: 0 | F25: =E25/C25
A26: 3 Bed / 2 Bath | B26: 20 | C26: 1400 | D26: =B26*C26 | E26: 0 | F26: =E26/C26
A28: Total Units | B28: =SUM(B24:B27)
A30: ACQUISITION COSTS
A31: Purchase Price | B31: 25000000
A32: Due Diligence & Inspection | B32: 50000
A33: Legal & Title | B33: 75000
A34: Brokerage Fee (% of Price) | B34: 0.015
A35: Loan Origination Fee (% of Loan) | B35: 0.01
A36: Other Closing Costs | B36: 50000
A38: Total Acquisition Cost | B38: =B31+B32+B33+B31*B34+B35+B36
A40: FINANCING ASSUMPTIONS
A41: Loan-to-Value (LTV) | B41: 0.7
A42: Interest Rate (Annual) | B42: 0.055
A43: Amortization Period (Years) | B43: 30
A44: IO Period (Years) | B44: 0
A45: Loan Term (Years) | B45: 10
A48: OPERATING ASSUMPTIONS
A49: Annual Rent Growth | B49: 0.04
A50: Annual Expense Growth | B50: 0.03
...

Sheet ProForma
A1: PROPERTY PRO FORMA
A3: Line Item | B3: Year 0 | C3: Year 1 | D3: Year 2 | E3: Year 3 | F3: Year 4 | G3: Year 5
A4: RENTAL INCOME
A5: Gross Potential Rent | B5: 0 | C5: =B5*(1+Inputs!B76) | D5: =C5*(1+Inputs!B76) | E5: =D5*(1+Inputs!B76) | F5: =E5*(1+Inputs!B76) | G5: =F5*(1+Inputs!B76)
A6: Other Income (parking, laundry, etc.) | B6: =B5*0.05 | C6: =B6*(1+Inputs!B76) | D6: =C6*(1+Inputs!B76) | E6: =D6*(1+Inputs!B76) | F6: =E6*(1+Inputs!B76) | G6: =F6*(1+Inputs!B76)
A7: Gross Potential Income | B7: =SUM(B5:B6) | C7: =SUM(C5:C6) | D7: =SUM(D5:D6) | E7: =SUM(E5:E6) | F7: =SUM(F5:F6) | G7: =SUM(G5:G6) | H7: =SUM(H5:H6)
A8: Less: Vacancy & Credit Loss | B8: =B7*(1-Inputs!B18) | C8: =C7*(1-Inputs!B19) | D8: =D7*(1-Inputs!B19) | E8: =E7*(1-Inputs!B19) | F8: =F7*(1-Inputs!B19) | G8: =G7*(1-Inputs!B19)
A9: Effective Gross Income (EGI) | B9: =B7+B8 | C9: =C7+C8 | D9: =D7+D8 | E9: =E7+E8 | F9: =F7+F8 | G9: =G7+G8 | H9: =H7+H8
A11: OPERATING EXPENSES
A12: Property Taxes | B12: 0 | C12: =B12*(1+Inputs!B76) | D12: =C12*(1+Inputs!B76) | E12: =D12*(1+Inputs!B76) | F12: =E12*(1+Inputs!B76) | G12: =F12*(1+Inputs!B76)
A13: Insurance | B13: 0 | C13: =B13*(1+Inputs!B76) | D13: =C13*(1+Inputs!B76) | E13: =D13*(1+Inputs!B76) | F13: =E13*(1+Inputs!B76) | G13: =F13*(1+Inputs!B76)
A14: Property Management | B14: 0 | C14: =B14*(1+Inputs!B77) | D14: =C14*(1+Inputs!B77) | E14: =D14*(1+Inputs!B77) | F14: =E14*(1+Inputs!B77) | G14: =F14*(1+Inputs!B77)
A15: Repairs & Maintenance | B15: 0 | C15: =B15*(1+Inputs!B77) | D15: =C15*(1+Inputs!B77) | E15: =D15*(1+Inputs!B77) | F15: =E15*(1+Inputs!B77) | G15: =F15*(1+Inputs!B77)
A16: Utilities | B16: 0 | C16: =B16*(1+Inputs!B77) | D16: =C16*(1+Inputs!B77) | E16: =D16*(1+Inputs!B77) | F16: =E16*(1+Inputs!B77) | G16: =F16*(1+Inputs!B77)
A17: Marketing & Leasing | B17: 0 | C17: =B17*(1+Inputs!B77) | D17: =C17*(1+Inputs!B77) | E17: =D17*(1+Inputs!B77) | F17: =E17*(1+Inputs!B77) | G17: =F17*(1+Inputs!B77)
A18: Administrative | B18: 0 | C18: =B18*(1+Inputs!B77) | D18: =C18*(1+Inputs!B77) | E18: =D18*(1+Inputs!B77) | F18: =E18*(1+Inputs!B77) | G18: =F18*(1+Inputs!B77)
A19: Total Operating Expenses | B19: =SUM(B12:B18) | C19: =SUM(C12:C18) | D19: =SUM(D12:D18) | E19: =SUM(E12:E18) | F19: =SUM(F12:F18) | G19: =SUM(G12:G18) | H19: =SUM(H12:H18)
A21: NET OPERATING INCOME (NOI) | B21: =B9-B20 | C21: =C9-C20 | D21: =D9-D20 | E21: =E9-E20 | F21: =F9-F20 | G21: =G9-G20 | H21: =H9-H20
A23: Capital Expenditures | B23: 0 | C23: =C9*Inputs!B86 | D23: =D9*Inputs!B86 | E23: =E9*Inputs!B86 | F23: =F9*Inputs!B86 | G23: =G9*Inputs!B86 | H23: =H9*Inputs!B86
A24: Leasing Costs | B24: 0 | C24: =C9*Inputs!B87 | D24: =D9*Inputs!B87 | E24: =E9*Inputs!B87 | F24: =F9*Inputs!B87 | G24: =G9*Inputs!B87 | H24: =H9*Inputs!B87
A25: Total Capital Items | B25: =SUM(B23:B24) | C25: =SUM(C23:C24) | D25: =SUM(D23:D24) | E25: =SUM(E23:E24) | F25: =SUM(F23:F24) | G25: =SUM(G23:G24) | H25: =SUM(H23:H24)
A27: CASH FLOW FROM OPERATIONS | B27: =B18-B26 | C27: =C18-C26 | D27: =D18-D26 | E27: =E18-E26 | F27: =F18-F26 | G27: =G18-G26 | H27: =H18-H26
A29: DEBT SERVICE
A30: Debt Service (P+I) | B30: 0 | C30: =CashFlow!C10 | D30: =CashFlow!C10 | E30: =CashFlow!C10 | F30: =CashFlow!C10 | G30: =CashFlow!C10 | H30: =CashFlow!C10
A32: CASH FLOW BEFORE TAX | B32: =B27-B31 | C32: =C27-C31 | D32: =D27-D31 | E32: =E27-E31 | F32: =F27-F31 | G32: =G27-G31 | H32: =H27-H31
A34: PERFORMANCE METRICS
A35: NOI Margin % | B35: 0 | C35: =C18/C9 | D35: =D18/D9 | E35: =E18/E9 | F35: =F18/F9 | G35: =G18/G9 | H35: =H18/H9
A36: Operating Expense Ratio | B36: 0 | C36: =C16/C9 | D36: =D16/D9 | E36: =E16/E9 | F36: =F16/F9 | G36: =G16/G9 | H36: =H16/H9
A37: Debt Service Coverage Ratio | B37: 0 | C37: =C18/C29 | D37: =D18/D29 | E37: =E18/E29 | F37: =F18/F29 | G37: =G18/G29 | H37: =H18/H29
A39: EXIT VALUE CALCULATION
A40: Exit Year NOI | G40: =G18
A41: Exit Cap Rate | G41: =Inputs!B93
A42: Gross Exit Value | G42: =G40/G41
A43: Less: Selling Costs | G43: =G42*Inputs!B94
A44: Net Exit Value | G44: =G42-G43

Sheet CashFlow
A1: CASH FLOW ANALYSIS
A3: Line Item | B3: Year 0 | C3: Year 1 | D3: Year 2 | E3: Year 3 | F3: Year 4 | G3: Year 5
A4: ACQUISITION / FINANCING
A5: Total Acquisition Cost | B5: 0 | C5: 0 | D5: 0 | E5: 0 | F5: 0 | G5: 0
A6: Loan Amount | B6: =Inputs!B54*Inputs!B65 | C6: 0 | D6: 0 | E6: 0 | F6: 0 | G6: 0
A7: Equity Investment | B7: =B5-B6 | C7: 0 | D7: 0 | E7: 0 | F7: 0 | G7: 0
A9: DEBT SERVICE
A10: Annual Debt Service | B10: 0 | C10: =-PMT(Inputs!B66/12,Inputs!B67*12,B6)*12 | D10: =-PMT(Inputs!B66/12,Inputs!B67*12,B6)*12 | E10: =-PMT(Inputs!B66/12,Inputs!B67*12,B6)*12 | F10: =-PMT(Inputs!B66/12,Inputs!B67*12,B6)*12 | G10: =-PMT(Inputs!B66/12,Inputs!B67*12,B6)*12
A12: OPERATING CASH FLOW
A13: Net Operating Income | B13: =ProForma!B18 | C13: =ProForma!C18 | D13: =ProForma!D18 | E13: =ProForma!E18 | F13: =ProForma!F18 | G13: =ProForma!G18 | H13: =ProForma!H18
A14: Less: Capital Items | B14: =ProForma!B22 | C14: =ProForma!C22 | D14: =ProForma!D22 | E14: =ProForma!E22 | F14: =ProForma!F22 | G14: =ProForma!G22 | H14: =ProForma!H22
A15: Less: Debt Service | B15: =B10 | C15: =C10 | D15: =D10 | E15: =E10 | F15: =F10 | G15: =G10 | H15: =H10
A16: Cash Flow Before Tax | B16: =B13+B14+B15 | C16: =C13+C14+C15 | D16: =D13+D14+D15 | E16: =E13+E14+E15 | F16: =F13+F14+F15 | G16: =G13+G14+G15 | H16: =H13+H14+H15
A18: EXIT PROCEEDS (Year 5 Only)
A19: Net Exit Value | B19: 0 | C19: 0 | D19: 0 | E19: 0 | F19: 0 | G19: =ProForma!G48
A20: Less: Loan Payoff | B20: 0 | C20: 0 | D20: 0 | E20: 0 | F20: 0 | G20: =-FV(Inputs!B66/12,Inputs!B10*12,-PMT(Inputs!B66/12,Inputs!B67*12,B6),B6)
A21: Net Sale Proceeds | B21: 0 | C21: 0 | D21: 0 | E21: 0 | F21: 0 | G21: =G19+G20
A23: TOTAL CASH FLOWS
A24: Unlevered Cash Flow | B24: =-Inputs!B54 | C24: =C13 | D24: =D13 | E24: =E13 | F24: =F13 | G24: =G20+G23
A25: Unlevered IRR | B25: =IRR(B24:G24)
A27: Levered Cash Flow | B27: =B8 | C27: =C16 | D27: =D16 | E27: =E16 | F27: =F16 | G27: =G16+G22
A28: Levered IRR | B28: =IRR(B27:G27)
A30: Equity Multiple | B30: =(SUM(C28:F28)+G28)/ABS(B28)

Sheet DCF Valuation
A1: DISCOUNTED CASH FLOW (DCF) VALUATION
A2: Enhanced valuation with multiple discount rates and terminal value methods
A4: DCF ASSUMPTIONS
A5: Discount Rate (WACC) | B5: 0.095
A6: Terminal Growth Rate | B6: 0.025
A7: Terminal Cap Rate | B7: 0.055
A8: Valuation Method | B8: Cap Rate
A11: CASH FLOW PROJECTION
A12: Year | B12: 1 | C12: 2 | D12: 3 | E12: 4 | F12: 5
A13: Unlevered Free Cash Flow | B13: =ProForma!B24 | C13: =ProForma!C24 | D13: =ProForma!D24 | E13: =ProForma!E24 | F13: =ProForma!F24
A14: Discount Factor | B14: =1/((1+$B$5)^1) | C14: =1/((1+$B$5)^2) | D14: =1/((1+$B$5)^3) | E14: =1/((1+$B$5)^4) | F14: =1/((1+$B$5)^5)
A15: Present Value of Cash Flow | B15: =B13*B14 | C15: =C13*C14 | D15: =D13*D14 | E15: =E13*E14 | F15: =F13*F14
A17: TERMINAL VALUE CALCULATION
A18: Year 5 NOI | B18: =ProForma!G18
A19: Terminal Cap Rate | B19: =B7
A20: Terminal Value | B20: =B18/B19
A21: PV of Terminal Value | B21: =B20*G14
A23: ENTERPRISE VALUE CALCULATION
A24: PV of Operating Cash Flows (Years 1-5) | B24: =SUM(B14:F14)
A25: PV of Terminal Value | B25: =B22
A26: Enterprise Value | B26: =B24+B25
A27: Less: Net Debt | B27: =CashFlow!B6
A28: Equity Value | B28: =B26+B27
A30: VALUATION METRICS
A31: Implied Value per Unit | B31: =B29/Inputs!B12
A32: Implied Value per SF | B32: =B29/Inputs!B14
A33: DCF vs. Purchase Price | B33: =B29/Inputs!B54-1

Sheet Summary
A1: INVESTMENT SUMMARY CALCULATIONS
A3: KEY METRICS
A4: Total Acquisition Cost | B4: =Inputs!B62
A5: Purchase Price per Unit | B5: =B5/Inputs!B12
A6: Purchase Price per SF | B6: =B5/Inputs!B14
A7: Entry Cap Rate | B7: =ProForma!C18/Inputs!B54
A8: Year 1 NOI | B8: =ProForma!C18
A9: Year 1 Cash-on-Cash Return | B9: =ProForma!C31/(B5-CashFlow!C8)
A10: Unlevered IRR | B10: =IRR(CashFlow!B28:G28)
A11: Levered IRR | B11: =IRR(CashFlow!B31:G31)
A12: Equity Multiple | B12: =(SUM(CashFlow!C31:F31)+CashFlow!G31)/(B5-CashFlow!C8)
A13: Exit Value | B13: =ProForma!G44
A14: Exit Cap Rate | B14: =Inputs!B93
A15: Total Return | B15: =B14-B5
A18: VALUATION METRICS
A19: Purchase Price | B19: =Inputs!B54
A20: Stabilized Year 1 NOI | B20: =ProForma!C18
A21: Implied Entry Cap Rate | B21: =B23/B22
A23: Exit Year NOI | B23: =ProForma!G18
A24: Exit Cap Rate | B24: =Inputs!B93
A25: Gross Exit Value | B25: =B26/B27
A26: Less: Selling Costs | B26: =B28*Inputs!B94
A27: Net Exit Value | B27: =B28-B29

Sheet Sensitivity
A1: SENSITIVITY ANALYSIS
A2: IRR Sensitivity: Exit Cap Rate vs. Annual Rent Growth
A4: Rent Growth → | B4: 0.02 | C4: 0.03 | D4: 0.04 | E4: 0.05 | F4: 0.06
A5: Exit Cap ↓
A6: 0.045 | B6: 0.15 | C6: 0.15 | D6: 0.15 | E6: 0.15 | F6: 0.15
A7: 0.05 | B7: 0.15 | C7: 0.15 | D7: 0.15 | E7: 0.15 | F7: 0.15
A8: 0.055 | B8: 0.15 | C8: 0.15 | D8: 0.15 | E8: 0.15 | F8: 0.15
A9: 0.06 | B9: 0.15 | C9: 0.15 | D9: 0.15 | E9: 0.15 | F9: 0.15
A10: 0.065 | B10: 0.15 | C10: 0.15 | D10: 0.15 | E10: 0.15 | F10: 0.15
A12: Note: To activate sensitivity analysis:
A13: 1. Select the range A5:F10
A14: 2. Go to Data > What-If Analysis > Data Table
A15: 3. Row input cell: Inputs!B76 (Rent Growth)
A16: 4. Column input cell: Inputs!B93 (Exit Cap Rate)
A19: NET PRESENT VALUE SENSITIVITY
A20: Discount Rate → | B20: 0.08 | C20: 0.1 | D20: 0.12 | E20: 0.14 | F20: 0.16
A21: Exit Cap ↓
A22: 0.045 | B22: 0 | C22: 0 | D22: 0 | E22: 0 | F22: 0
A23: 0.05 | B23: 0 | C23: 0 | D23: 0 | E23: 0 | F23: 0
A24: 0.055 | B24: 0 | C24: 0 | D24: 0 | E24: 0 | F24: 0
A25: 0.06 | B25: 0 | C25: 0 | D25: 0 | E25: 0 | F25: 0
A26: 0.065 | B26: 0 | C26: 0 | D26: 0 | E26: 0 | F26: 0

Sheet Market Analysis
A1: MARKET ANALYSIS & COMPARABLES
A2: 🤖 AI-POWERED: This section can be auto-populated using property valuation APIs
A4: COMPARABLE SALES
A5: Property Name | B5: Address | C5: Sale Date | D5: Sale Price | E5: Units | F5: $/Unit | G5: SF | H5: $/SF | I5: Cap Rate
A6: Sunset Apartments | B6: 456 Oak St | C6: 2024-06-15 | D6: 28500000 | E6: 155 | F6: =D7/E7 | G6: 142500 | H6: =D7/G7 | I6: 0.052
A7: Riverside Complex | B7: 789 River Rd | C7: 2024-08-20 | D7: 31200000 | E7: 165 | F7: =D8/E8 | G7: 156750 | H7: =D8/G8 | I7: 0.048
A8: Mountain View | B8: 321 Hill Ave | C8: 2024-10-05 | D8: 26800000 | E8: 145 | F8: =D9/E9 | G8: 137500 | H8: =D9/G9 | I8: 0.055
A9: Downtown Tower | B9: 654 Main St | C9: 2024-11-12 | D9: 42500000 | E9: 220 | F9: =D10/E10 | G9: 220000 | H9: =D10/G10 | I9: 0.051
A10: Park Plaza | B10: 987 Park Blvd | C10: 2024-12-01 | D10: 24600000 | E10: 130 | F10: =D11/E11 | G10: 123500 | H10: =D11/G11 | I10: 0.057
A12: MARKET AVERAGES | F12: =AVERAGE(F7:F11) | H12: =AVERAGE(H7:H11) | I12: =AVERAGE(I7:I11)
A15: SUBJECT PROPERTY vs. MARKET
A16: Subject Property $/Unit | B16: =Summary!B6 | C16: Market Average $/Unit | D16: =F13
A17: Subject Property $/SF | B17: =Summary!B7 | C17: Market Average $/SF | D17: =H13
A18: Subject Entry Cap Rate | B18: =Summary!B8 | C18: Market Average Cap Rate | D18: =I13
A20: $/Unit Premium/(Discount) | B20: =B18-D18 | C20: % Difference | D20: =B18/D18-1
A21: $/SF Premium/(Discount) | B21: =B19-D19 | C21: % Difference | D21: =B19/D19-1
A22: Cap Rate Difference | B22: =B20-D20 | C22: Basis Points | D22: =(B20-D20)*10000
A25: MARKET METRICS & TRENDS
A26: 🤖 AI DATA: Below metrics can be populated via HouseCanary, CoreLogic, or similar APIs
A27: Submarket Vacancy Rate | B27: 0.068
A28: Submarket Avg Rent Growth (3yr) | B28: 0.045
A29: Submarket Avg Cap Rate | B29: 0.053
A30: Population Growth (5yr forecast) | B30: 0.028
A31: Employment Growth (5yr forecast) | B31: 0.032
A32: Median Household Income | B32: 78500
A33: Crime Rate Index (vs. national avg) | B33: 95

Sheet Development Budget
A1: DEVELOPMENT / RENOVATION BUDGET
A2: Optional: Use for ground-up development or major renovation projects
A4: PROJECT INFORMATION
A5: Project Type | B5: Ground-Up / Renovation / Addition
A6: Total SF to Develop | B6: 145000
A7: Construction Start Date | B7: 2025-Q1
A8: Construction Duration (months) | B8: 18
A9: Total Development Budget | B9: 45000000
A12: DEVELOPMENT COSTS
A13: Category | B13: $/SF | C13: Total SF | D13: Subtotal | E13: % of Total | F13: Notes
A14: Land Acquisition | B14: 0 | C14: 0 | D14: 8500000 | F14: Existing site
A15: Site Work & Preparation | B15: 15 | C15: =B7 | D15: =B18*C18 | E15: =D18/$B$9 | F15: Grading, utilities
A16: Hard Costs - Shell | B16: 120 | C16: =B7 | D16: =B19*C19 | E16: =D19/$B$9 | F16: Structure, exterior
A17: Hard Costs - Interior | B17: 85 | C17: =B7 | D17: =B20*C20 | E17: =D20/$B$9 | F17: TI, finishes
A18: MEP Systems | B18: 45 | C18: =B7 | D18: =B21*C21 | E18: =D21/$B$9 | F18: Mechanical, electrical, plumbing
A19: Parking Structure | B19: 25 | C19: =B7 | D19: =B22*C22 | E19: =D22/$B$9 | F19: Surface + structured
A20: Landscaping & Amenities | B20: 12 | C20: =B7 | D20: =B23*C23 | E20: =D23/$B$9 | F20: Pool, fitness, courtyards
A21: Contingency (5%) | D21: =SUM(D18:D24)*0.05 | E21: =D25/$B$9 | F21: Construction contingency
A22: Total Hard Costs | D22: =SUM(D17:D25) | E22: =D26/$B$9
A24: Soft Costs:
A25: Architecture & Engineering | D25: 850000 | E25: =D29/$B$9 | F25: Design fees
A26: Legal & Permitting | D26: 425000 | E26: =D30/$B$9 | F26: Entitlements, permits
A27: Construction Management | D27: =D26*0.04 | E27: =D31/$B$9 | F27: 4% of hard costs
A28: Developer Fee | D28: =D26*0.05 | E28: =D32/$B$9 | F28: 5% of hard costs
A29: Marketing & Lease-Up | D29: 650000 | E29: =D33/$B$9 | F29: Pre-leasing
A30: Financing Costs | D30: 1250000 | E30: =D34/$B$9 | F30: Interest during construction
A31: Insurance & Taxes | D31: 425000 | E31: =D35/$B$9 | F31: During construction
A32: Total Soft Costs | D32: =SUM(D29:D35) | E32: =D36/$B$9
A34: TOTAL DEVELOPMENT COST | D34: =D26+D36 | E34: =D38/$B$9
A35: Cost per SF | B35: =D38/B7

Sheet AI Integration Guide
A1: 🤖 AI INTEGRATION & AUTOMATION GUIDE
A2: This model is designed for both manual use and platform integration
A4: OVERVIEW
A6: This Real Estate Financial Model combines Jake's Model structure with enhancements from:
A7: • Industrial Development Model - Construction budgeting and phased development
A8: • Multifamily Acquisition Model - Comprehensive property analysis
A9: • RE AI Technology Reference Guide - AI-powered automation capabilities
A11: The model works in TWO MODES:
A12: 1. STANDALONE: Manual Excel template for deal analysis
A13: 2. INTEGRATED: Automated via Portfolio Dashboard platform
A16: AI-POWERED FEATURES
A18: Feature | B18: API Provider | C18: Auto-Populates | D18: Manual Override
A19: Property Valuation | B19: HouseCanary / CoreLogic | C19: Market value, confidence score | D19: Inputs!B54
A20: Comparable Sales | B20: MLS / Zillow API | C20: Market Analysis sheet cells | D20: Market Analysis!D7:D11
A21: Market Metrics | B21: Census / BLS APIs | C21: Market Analysis!B31:B37 | D21: Market Analysis sheet
A22: Rent Predictions | B22: RentRange / Zillow | C22: Inputs!E25:E28 | D22: Unit Mix section
A23: Cap Rate Analysis | B23: CBRE / CoStar | C23: Inputs!B93, Market Analysis | D23: Exit Assumptions
A24: Document Extraction | B24: Claude AI / GPT-4 | C24: Rent rolls, financials | D24: Various inputs
A27: PLATFORM INTEGRATION WORKFLOW
A29: STEP 1: Property Onboarding
A30: → User uploads property address + basic info
A31: → API calls to HouseCanary for valuation + comparables
A32: → Auto-populate Inputs sheet (B5-B19)
A34: STEP 2: Financial Data Extraction
A35: → User uploads rent roll PDF, financial statements
A36: → Claude AI extracts: unit mix, rents, expenses
A37: → Auto-populate: Unit Mix (B25:E28), Operating Assumptions
A39: STEP 3: Model Generation
A40: → Python script (excel_model_generator.py) creates this Excel file
A41: → All formulas preserved, data injected into yellow input cells
... A55: DATABASE SCHEMA MAPPING
A57: Excel Cell | B57: Database Table | C57: Database Column | D57: Data Type
A58: Inputs!B5 | B58: properties | C58: property_name | D58: VARCHAR
A59: Inputs!B6 | B59: properties | C59: property_type | D59: VARCHAR
A60: Inputs!B7-B8 | B60: properties | C60: address | D60: TEXT
A61: Inputs!B9 | B61: properties | C61: acquisition_date | D61: DATE
A62: Inputs!B12 | B62: properties | C62: num_units | D62: INTEGER
A63: Inputs!B54 | B63: acquisitions | C63: purchase_price | D63: DECIMAL
A64: Inputs!B65-B69 | B64: financing | C64: ltv, rate, term | D64: DECIMAL
A65: ProForma!C18:G18 | B65: projections | C65: noi_year1-5 | D65: DECIMAL
...
